[2025-05-14 01:22:16,941] [INFO] Found 74 Python scripts to validate
[2025-05-14 01:22:16,941] [INFO] Validating script: cleanup.py
[2025-05-14 01:22:16,988] [INFO] Validation passed for /home/emilio/Documents/ai/pizza/scripts/cleanup.py
[2025-05-14 01:22:16,988] [INFO] Validating script: filter_dataset.py
[2025-05-14 01:22:16,996] [WARNING] Missing or incomplete docstring in /home/emilio/Documents/ai/pizza/scripts/filter_dataset.py
[2025-05-14 01:22:16,996] [WARNING] Validation passed with warnings for /home/emilio/Documents/ai/pizza/scripts/filter_dataset.py
[2025-05-14 01:22:16,996] [INFO] Validating script: label_tool.py
[2025-05-14 01:22:19,121] [INFO] Validation passed for /home/emilio/Documents/ai/pizza/scripts/label_tool.py
[2025-05-14 01:22:19,121] [INFO] Validating script: framebuffer_demo.py
[2025-05-14 01:22:19,223] [WARNING] Execution test issue in /home/emilio/Documents/ai/pizza/scripts/framebuffer_demo.py: Execution failed with error: 
[2025-05-14 01:22:19,224] [WARNING] Validation passed with warnings for /home/emilio/Documents/ai/pizza/scripts/framebuffer_demo.py
[2025-05-14 01:22:19,224] [INFO] Validating script: compare_inverted_residual.py
[2025-05-14 01:22:22,892] [INFO] Validation passed for /home/emilio/Documents/ai/pizza/scripts/compare_inverted_residual.py
[2025-05-14 01:22:22,892] [INFO] Validating script: test_temporal_smoothing.py
[2025-05-14 01:22:23,196] [INFO] Validation passed for /home/emilio/Documents/ai/pizza/scripts/test_temporal_smoothing.py
[2025-05-14 01:22:23,197] [INFO] Validating script: knowledge_distillation.py
[2025-05-14 01:22:25,175] [INFO] Validation passed for /home/emilio/Documents/ai/pizza/scripts/knowledge_distillation.py
[2025-05-14 01:22:25,175] [INFO] Validating script: visualize_gradcam.py
[2025-05-14 01:22:25,762] [WARNING] Missing dependencies in /home/emilio/Documents/ai/pizza/scripts/visualize_gradcam.py: scripts
[2025-05-14 01:22:28,224] [WARNING] Execution test issue in /home/emilio/Documents/ai/pizza/scripts/visualize_gradcam.py: Execution failed with error: Traceback (most recent call last):
  File "/home/emilio/Documents/ai/pizza/scripts/visualize_gradcam.py", line 52, in <module>
    from scripts.compare_tiny_cnns import MCUNet, MobilePizzaNet
  File "/home/emilio/Documents/ai/pizza/scripts/compare_tiny_cnns.py", line 52, in <module>
    from src.metrics import ModelMetrics
ImportError: cannot import name 'ModelMetrics' from 'src.metrics' (/home/emilio/Documents/ai/pizza/src/metrics.py)

[2025-05-14 01:22:28,228] [WARNING] Validation passed with warnings for /home/emilio/Documents/ai/pizza/scripts/visualize_gradcam.py
[2025-05-14 01:22:28,228] [INFO] Validating script: classify_images.py
[2025-05-14 01:22:28,236] [WARNING] Missing or incomplete docstring in /home/emilio/Documents/ai/pizza/scripts/classify_images.py
[2025-05-14 01:22:28,236] [WARNING] Validation passed with warnings for /home/emilio/Documents/ai/pizza/scripts/classify_images.py
[2025-05-14 01:22:28,237] [INFO] Validating script: visualize_pruning.py
[2025-05-14 01:22:30,660] [INFO] Validation passed for /home/emilio/Documents/ai/pizza/scripts/visualize_pruning.py
[2025-05-14 01:22:30,660] [INFO] Validating script: compare_tiny_cnns.py
[2025-05-14 01:22:30,691] [WARNING] Missing dependencies in /home/emilio/Documents/ai/pizza/scripts/compare_tiny_cnns.py: scripts
[2025-05-14 01:22:33,149] [WARNING] Execution test issue in /home/emilio/Documents/ai/pizza/scripts/compare_tiny_cnns.py: Execution failed with error: Traceback (most recent call last):
  File "/home/emilio/Documents/ai/pizza/scripts/compare_tiny_cnns.py", line 52, in <module>
    from src.metrics import ModelMetrics
ImportError: cannot import name 'ModelMetrics' from 'src.metrics' (/home/emilio/Documents/ai/pizza/src/metrics.py)

[2025-05-14 01:22:33,153] [WARNING] Validation passed with warnings for /home/emilio/Documents/ai/pizza/scripts/compare_tiny_cnns.py
[2025-05-14 01:22:33,153] [INFO] Validating script: compare_se_models.py
[2025-05-14 01:22:35,711] [INFO] Validation passed for /home/emilio/Documents/ai/pizza/scripts/compare_se_models.py
[2025-05-14 01:22:35,711] [INFO] Validating script: automated_test_suite.py
[2025-05-14 01:22:38,190] [WARNING] Execution test issue in /home/emilio/Documents/ai/pizza/scripts/automated_test_suite.py: Execution failed with error: Traceback (most recent call last):
  File "/home/emilio/Documents/ai/pizza/scripts/automated_test_suite.py", line 53, in <module>
    from src.pizza_detector import (
ImportError: cannot import name 'load_model' from 'src.pizza_detector' (/home/emilio/Documents/ai/pizza/src/pizza_detector.py)

[2025-05-14 01:22:38,194] [WARNING] Validation passed with warnings for /home/emilio/Documents/ai/pizza/scripts/automated_test_suite.py
[2025-05-14 01:22:38,194] [INFO] Validating script: compare_hard_swish.py
[2025-05-14 01:22:40,736] [INFO] Validation passed for /home/emilio/Documents/ai/pizza/scripts/compare_hard_swish.py
[2025-05-14 01:22:40,736] [INFO] Validating script: demo_status_display.py
[2025-05-14 01:22:40,770] [WARNING] Execution test issue in /home/emilio/Documents/ai/pizza/scripts/demo_status_display.py: Execution failed with error: Traceback (most recent call last):
  File "/home/emilio/Documents/ai/pizza/scripts/demo_status_display.py", line 38, in <module>
    from src.status_display import (
ModuleNotFoundError: No module named 'src.status_display'

[2025-05-14 01:22:40,772] [WARNING] Validation passed with warnings for /home/emilio/Documents/ai/pizza/scripts/demo_status_display.py
[2025-05-14 01:22:40,772] [INFO] Validating script: test_image_preprocessing.py
[2025-05-14 01:22:41,088] [WARNING] Execution test issue in /home/emilio/Documents/ai/pizza/scripts/test_image_preprocessing.py: Execution failed with error: Traceback (most recent call last):
  File "/home/emilio/Documents/ai/pizza/scripts/test_image_preprocessing.py", line 22, in <module>
    from src.constants import INPUT_SIZE
ImportError: cannot import name 'INPUT_SIZE' from 'src.constants' (/home/emilio/Documents/ai/pizza/src/constants.py)

[2025-05-14 01:22:41,089] [WARNING] Validation passed with warnings for /home/emilio/Documents/ai/pizza/scripts/test_image_preprocessing.py
[2025-05-14 01:22:41,089] [INFO] Validating script: test_pizza_detection.py
[2025-05-14 01:22:43,031] [WARNING] Execution test issue in /home/emilio/Documents/ai/pizza/scripts/test_pizza_detection.py: Execution failed with error: Traceback (most recent call last):
  File "/home/emilio/Documents/ai/pizza/scripts/test_pizza_detection.py", line 26, in <module>
    from src.constants import INPUT_SIZE, IMAGE_MEAN, IMAGE_STD
ImportError: cannot import name 'INPUT_SIZE' from 'src.constants' (/home/emilio/Documents/ai/pizza/src/constants.py)

[2025-05-14 01:22:43,032] [WARNING] Validation passed with warnings for /home/emilio/Documents/ai/pizza/scripts/test_pizza_detection.py
[2025-05-14 01:22:43,033] [INFO] Validating script: demo_power_management.py
[2025-05-14 01:22:43,338] [WARNING] Execution test issue in /home/emilio/Documents/ai/pizza/scripts/demo_power_management.py: Execution failed with error: Traceback (most recent call last):
  File "/home/emilio/Documents/ai/pizza/scripts/demo_power_management.py", line 19, in <module>
    from src.emulator import RP2040Emulator
ModuleNotFoundError: No module named 'src.emulator'

[2025-05-14 01:22:43,340] [WARNING] Validation passed with warnings for /home/emilio/Documents/ai/pizza/scripts/demo_power_management.py
[2025-05-14 01:22:43,340] [INFO] Validating script: analyze_performance_logs.py
[2025-05-14 01:22:44,056] [INFO] Validation passed for /home/emilio/Documents/ai/pizza/scripts/analyze_performance_logs.py
[2025-05-14 01:22:44,056] [INFO] Validating script: simulate_memory_constraints.py
[2025-05-14 01:22:44,356] [WARNING] Execution test issue in /home/emilio/Documents/ai/pizza/scripts/simulate_memory_constraints.py: Execution failed with error: Traceback (most recent call last):
  File "/home/emilio/Documents/ai/pizza/scripts/simulate_memory_constraints.py", line 17, in <module>
    from src.constants import (
ImportError: cannot import name 'RP2040_FLASH_SIZE_KB' from 'src.constants' (/home/emilio/Documents/ai/pizza/src/constants.py)

[2025-05-14 01:22:44,358] [WARNING] Validation passed with warnings for /home/emilio/Documents/ai/pizza/scripts/simulate_memory_constraints.py
[2025-05-14 01:22:44,358] [INFO] Validating script: simulate_clahe_resources.py
[2025-05-14 01:22:44,657] [WARNING] Execution test issue in /home/emilio/Documents/ai/pizza/scripts/simulate_clahe_resources.py: Execution failed with error: Traceback (most recent call last):
  File "/home/emilio/Documents/ai/pizza/scripts/simulate_clahe_resources.py", line 22, in <module>
    from src.constants import INPUT_SIZE
ImportError: cannot import name 'INPUT_SIZE' from 'src.constants' (/home/emilio/Documents/ai/pizza/src/constants.py)

[2025-05-14 01:22:44,659] [WARNING] Validation passed with warnings for /home/emilio/Documents/ai/pizza/scripts/simulate_clahe_resources.py
[2025-05-14 01:22:44,659] [INFO] Validating script: run_pizza_tests.py
[2025-05-14 01:22:44,684] [INFO] Validation passed for /home/emilio/Documents/ai/pizza/scripts/run_pizza_tests.py
[2025-05-14 01:22:44,684] [INFO] Validating script: run_pruning_clustering.py
[2025-05-14 01:22:44,686] [WARNING] Missing dependencies in /home/emilio/Documents/ai/pizza/scripts/run_pruning_clustering.py: config, scripts
[2025-05-14 01:22:46,639] [WARNING] Validation passed with warnings for /home/emilio/Documents/ai/pizza/scripts/run_pruning_clustering.py
[2025-05-14 01:22:46,639] [INFO] Validating script: augment_dataset.py
[2025-05-14 01:22:46,746] [INFO] Validation passed for /home/emilio/Documents/ai/pizza/scripts/augment_dataset.py
[2025-05-14 01:22:46,747] [INFO] Validating script: train_pizza_model.py
[2025-05-14 01:22:48,696] [WARNING] Execution test issue in /home/emilio/Documents/ai/pizza/scripts/train_pizza_model.py: Execution failed with error: Traceback (most recent call last):
  File "/home/emilio/Documents/ai/pizza/scripts/train_pizza_model.py", line 28, in <module>
    from src.constants import INPUT_SIZE, IMAGE_MEAN, IMAGE_STD
ImportError: cannot import name 'INPUT_SIZE' from 'src.constants' (/home/emilio/Documents/ai/pizza/src/constants.py)

[2025-05-14 01:22:48,699] [WARNING] Validation passed with warnings for /home/emilio/Documents/ai/pizza/scripts/train_pizza_model.py
[2025-05-14 01:22:48,699] [INFO] Validating script: simulate_lighting_conditions.py
[2025-05-14 01:22:48,983] [WARNING] Execution test issue in /home/emilio/Documents/ai/pizza/scripts/simulate_lighting_conditions.py: Execution failed with error: Traceback (most recent call last):
  File "/home/emilio/Documents/ai/pizza/scripts/simulate_lighting_conditions.py", line 17, in <module>
    from src.emulator import RP2040Emulator
ModuleNotFoundError: No module named 'src.emulator'

[2025-05-14 01:22:48,984] [WARNING] Validation passed with warnings for /home/emilio/Documents/ai/pizza/scripts/simulate_lighting_conditions.py
[2025-05-14 01:22:48,984] [INFO] Validating script: quantization_aware_training.py
[2025-05-14 01:22:50,976] [INFO] Validation passed for /home/emilio/Documents/ai/pizza/scripts/quantization_aware_training.py
[2025-05-14 01:22:50,976] [INFO] Validating script: simulate_power_consumption.py
[2025-05-14 01:22:51,271] [WARNING] Execution test issue in /home/emilio/Documents/ai/pizza/scripts/simulate_power_consumption.py: Execution failed with error: Traceback (most recent call last):
  File "/home/emilio/Documents/ai/pizza/scripts/simulate_power_consumption.py", line 18, in <module>
    from src.constants import (
ImportError: cannot import name 'RP2040_FLASH_SIZE_KB' from 'src.constants' (/home/emilio/Documents/ai/pizza/src/constants.py)

[2025-05-14 01:22:51,272] [WARNING] Validation passed with warnings for /home/emilio/Documents/ai/pizza/scripts/simulate_power_consumption.py
[2025-05-14 01:22:51,272] [INFO] Validating script: generate_pizza_dataset.py
[2025-05-14 01:22:56,175] [WARNING] Execution test issue in /home/emilio/Documents/ai/pizza/scripts/generate_pizza_dataset.py: Execution failed with error: 2025-05-14 01:22:53.567583: I tensorflow/core/util/port.cc:153] oneDNN custom operations are on. You may see slightly different numerical results due to floating-point round-off errors from different computation orders. To turn them off, set the environment variable `TF_ENABLE_ONEDNN_OPTS=0`.
2025-05-14 01:22:53.576300: E external/local_xla/xla/stream_executor/cuda/cuda_fft.cc:467] Unable to register cuFFT factory: Attempting to register factory for plugin cuFFT when one has already been registered
WARNING: All log messages before absl::InitializeLog() is called are written to STDERR
E0000 00:00:1747178573.586556  159677 cuda_dnn.cc:8579] Unable to register cuDNN factory: Attempting to register factory for plugin cuDNN when one has already been registered
E0000 00:00:1747178573.589586  159677 cuda_blas.cc:1407] Unable to register cuBLAS factory: Attempting to register factory for plugin cuBLAS when one has already been registered
W0000 00:00:1747178573.597504  159677 computation_placer.cc:177] computation placer already registered. Please check linkage and avoid linking the same target more than once.
W0000 00:00:1747178573.597517  159677 computation_placer.cc:177] computation placer already registered. Please check linkage and avoid linking the same target more than once.
W0000 00:00:1747178573.597519  159677 computation_placer.cc:177] computation placer already registered. Please check linkage and avoid linking the same target more than once.
W0000 00:00:1747178573.597520  159677 computation_placer.cc:177] computation placer already registered. Please check linkage and avoid linking the same target more than once.
2025-05-14 01:22:53.600032: I tensorflow/core/platform/cpu_feature_guard.cc:210] This TensorFlow binary is optimized to use available CPU instructions in performance-critical operations.
To enable the following instructions: AVX2 AVX_VNNI FMA, in other operations, rebuild TensorFlow with the appropriate compiler flags.
Traceback (most recent call last):
  File "/home/emilio/Documents/ai/pizza/scripts/generate_pizza_dataset.py", line 28, in <module>
    from src.augmentation.advanced_pizza_diffusion_control import (
  File "/home/emilio/Documents/ai/pizza/src/augmentation/advanced_pizza_diffusion_control.py", line 293
    image_size=image_size,
    ^^^^^^^^^^^^^^^^^^^^^
SyntaxError: keyword argument repeated: image_size

[2025-05-14 01:22:56,176] [WARNING] Validation passed with warnings for /home/emilio/Documents/ai/pizza/scripts/generate_pizza_dataset.py
[2025-05-14 01:22:56,180] [INFO] Validating script: hyperparameter_search.py
[2025-05-14 01:22:58,715] [WARNING] Execution test issue in /home/emilio/Documents/ai/pizza/scripts/hyperparameter_search.py: Execution failed with error: Traceback (most recent call last):
  File "/home/emilio/Documents/ai/pizza/scripts/hyperparameter_search.py", line 45, in <module>
    from src.metrics import ModelMetrics
ImportError: cannot import name 'ModelMetrics' from 'src.metrics' (/home/emilio/Documents/ai/pizza/src/metrics.py)

[2025-05-14 01:22:58,718] [WARNING] Validation passed with warnings for /home/emilio/Documents/ai/pizza/scripts/hyperparameter_search.py
[2025-05-14 01:22:58,718] [INFO] Validating script: extract_frames.py
[2025-05-14 01:22:58,730] [WARNING] Missing or incomplete docstring in /home/emilio/Documents/ai/pizza/scripts/extract_frames.py
[2025-05-14 01:22:58,731] [WARNING] Validation passed with warnings for /home/emilio/Documents/ai/pizza/scripts/extract_frames.py
[2025-05-14 01:22:58,731] [INFO] Validating script: validate_integration.py
[2025-05-14 01:22:58,766] [INFO] Validation passed for /home/emilio/Documents/ai/pizza/scripts/ci/validate_integration.py
[2025-05-14 01:22:58,766] [INFO] Validating script: validate_scripts.py
[2025-05-14 01:22:58,852] [INFO] Validation passed for /home/emilio/Documents/ai/pizza/scripts/ci/validate_scripts.py
[2025-05-14 01:22:58,852] [INFO] Validating script: generate_pipeline_report.py
[2025-05-14 01:22:59,145] [INFO] Validation passed for /home/emilio/Documents/ai/pizza/scripts/ci/generate_pipeline_report.py
[2025-05-14 01:22:59,145] [INFO] Validating script: weight_pruning.py
[2025-05-14 01:22:59,154] [WARNING] Missing dependencies in /home/emilio/Documents/ai/pizza/scripts/model_optimization/weight_pruning.py: config
[2025-05-14 01:23:01,110] [WARNING] Validation passed with warnings for /home/emilio/Documents/ai/pizza/scripts/model_optimization/weight_pruning.py
[2025-05-14 01:23:01,110] [INFO] Validating script: micropizzanet_early_exit.py
[2025-05-14 01:23:03,066] [INFO] Validation passed for /home/emilio/Documents/ai/pizza/scripts/early_exit/micropizzanet_early_exit.py
[2025-05-14 01:23:03,066] [INFO] Validating script: verify_model.py
[2025-05-14 01:23:04,752] [WARNING] Missing or incomplete docstring in /home/emilio/Documents/ai/pizza/models/rp2040_export/verify_model.py
[2025-05-14 01:23:04,752] [WARNING] Validation passed with warnings for /home/emilio/Documents/ai/pizza/models/rp2040_export/verify_model.py
[2025-05-14 01:23:04,752] [INFO] Validating script: pizza-baking-detection-final.py
[2025-05-14 01:23:05,836] [WARNING] Missing dependencies in /home/emilio/Documents/ai/pizza/src/pizza-baking-detection-final.py: onnx_tf
[2025-05-14 01:23:07,720] [WARNING] Execution test issue in /home/emilio/Documents/ai/pizza/src/pizza-baking-detection-final.py: Execution failed with error: 2025-05-14 01:23:07,346 - INFO - ================================================================================
2025-05-14 01:23:07,346 - INFO - RP2040 PIZZA-ERKENNUNGSSYSTEM - DETAILLIERTE KONFIGURATION
2025-05-14 01:23:07,346 - INFO - ================================================================================
2025-05-14 01:23:07,346 - INFO - Hardware: RP2040 - 133MHz, 264KB RAM, 2048KB Flash
2025-05-14 01:23:07,346 - INFO - Kamera: OV2640 - 320x240, 7 FPS
2025-05-14 01:23:07,346 - INFO - Stromversorgung: CR123A - 1500mAh, 8.33h aktiv, 3000.00h standby
2025-05-14 01:23:07,346 - INFO - Modellparameter: 48x48 Eingabegröße, 8-Bit Quantisierung
2025-05-14 01:23:07,346 - INFO - Speicherbeschränkungen: Max. 180KB Modellgröße, 100KB Laufzeit-RAM
2025-05-14 01:23:07,346 - INFO - ================================================================================
2025-05-14 01:23:07,346 - ERROR - Fehler im Optimierungsprozess: [Errno 2] No such file or directory: 'augmented_pizza'
Traceback (most recent call last):
  File "/home/emilio/Documents/ai/pizza/src/pizza-baking-detection-final.py", line 2230, in main
    analyzer = PizzaDatasetAnalysis(config.DATA_DIR)
               ^^^^^^^^^^^^^^^^^^^^^^^^^^^^^^^^^^^^^
  File "/home/emilio/Documents/ai/pizza/src/pizza-baking-detection-final.py", line 107, in __init__
    self.class_dirs = [d for d in os.listdir(data_dir)
                                 ^^^^^^^^^^^^^^^^^^^^
FileNotFoundError: [Errno 2] No such file or directory: 'augmented_pizza'
Traceback (most recent call last):
  File "/home/emilio/Documents/ai/pizza/src/pizza-baking-detection-final.py", line 2302, in <module>
    main()
  File "/home/emilio/Documents/ai/pizza/src/pizza-baking-detection-final.py", line 2230, in main
    analyzer = PizzaDatasetAnalysis(config.DATA_DIR)
               ^^^^^^^^^^^^^^^^^^^^^^^^^^^^^^^^^^^^^
  File "/home/emilio/Documents/ai/pizza/src/pizza-baking-detection-final.py", line 107, in __init__
    self.class_dirs = [d for d in os.listdir(data_dir) 
                                  ^^^^^^^^^^^^^^^^^^^^
FileNotFoundError: [Errno 2] No such file or directory: 'augmented_pizza'

[2025-05-14 01:23:07,730] [WARNING] Missing or incomplete docstring in /home/emilio/Documents/ai/pizza/src/pizza-baking-detection-final.py
[2025-05-14 01:23:07,730] [WARNING] Validation passed with warnings for /home/emilio/Documents/ai/pizza/src/pizza-baking-detection-final.py
[2025-05-14 01:23:07,730] [INFO] Validating script: metrics.py
[2025-05-14 01:23:07,744] [WARNING] Missing or incomplete docstring in /home/emilio/Documents/ai/pizza/src/metrics.py
[2025-05-14 01:23:07,744] [WARNING] Validation passed with warnings for /home/emilio/Documents/ai/pizza/src/metrics.py
[2025-05-14 01:23:07,744] [INFO] Validating script: __init__.py
[2025-05-14 01:23:07,753] [WARNING] Missing or incomplete docstring in /home/emilio/Documents/ai/pizza/src/__init__.py
[2025-05-14 01:23:07,753] [WARNING] Validation passed with warnings for /home/emilio/Documents/ai/pizza/src/__init__.py
[2025-05-14 01:23:07,753] [INFO] Validating script: pizza_detector.py
[2025-05-14 01:23:07,778] [WARNING] Missing dependencies in /home/emilio/Documents/ai/pizza/src/pizza_detector.py: onnx_tf
[2025-05-14 01:23:09,720] [WARNING] Execution test issue in /home/emilio/Documents/ai/pizza/src/pizza_detector.py: Execution failed with error: 2025-05-14 01:23:09,350 - INFO - ================================================================================
2025-05-14 01:23:09,350 - INFO - RP2040 PIZZA-ERKENNUNGSSYSTEM - DETAILLIERTE KONFIGURATION
2025-05-14 01:23:09,350 - INFO - ================================================================================
2025-05-14 01:23:09,350 - INFO - Hardware: RP2040 - 133MHz, 264KB RAM, 2048KB Flash
2025-05-14 01:23:09,350 - INFO - Kamera: OV2640 - 320x240, 7 FPS
2025-05-14 01:23:09,350 - INFO - Stromversorgung: CR123A - 1500mAh, 8.33h aktiv, 3000.00h standby
2025-05-14 01:23:09,350 - INFO - Modellparameter: 48x48 Eingabegröße, 8-Bit Quantisierung
2025-05-14 01:23:09,350 - INFO - Speicherbeschränkungen: Max. 180KB Modellgröße, 100KB Laufzeit-RAM
2025-05-14 01:23:09,350 - INFO - ================================================================================
2025-05-14 01:23:09,350 - ERROR - Fehler im Optimierungsprozess: [Errno 2] No such file or directory: 'augmented_pizza'
Traceback (most recent call last):
  File "/home/emilio/Documents/ai/pizza/src/pizza_detector.py", line 2475, in main
    analyzer = PizzaDatasetAnalysis(config.DATA_DIR)
               ^^^^^^^^^^^^^^^^^^^^^^^^^^^^^^^^^^^^^
  File "/home/emilio/Documents/ai/pizza/src/pizza_detector.py", line 107, in __init__
    self.class_dirs = [d for d in os.listdir(data_dir)
                                 ^^^^^^^^^^^^^^^^^^^^
FileNotFoundError: [Errno 2] No such file or directory: 'augmented_pizza'
Traceback (most recent call last):
  File "/home/emilio/Documents/ai/pizza/src/pizza_detector.py", line 2547, in <module>
    main()
  File "/home/emilio/Documents/ai/pizza/src/pizza_detector.py", line 2475, in main
    analyzer = PizzaDatasetAnalysis(config.DATA_DIR)
               ^^^^^^^^^^^^^^^^^^^^^^^^^^^^^^^^^^^^^
  File "/home/emilio/Documents/ai/pizza/src/pizza_detector.py", line 107, in __init__
    self.class_dirs = [d for d in os.listdir(data_dir) 
                                  ^^^^^^^^^^^^^^^^^^^^
FileNotFoundError: [Errno 2] No such file or directory: 'augmented_pizza'

[2025-05-14 01:23:09,730] [WARNING] Missing or incomplete docstring in /home/emilio/Documents/ai/pizza/src/pizza_detector.py
[2025-05-14 01:23:09,730] [WARNING] Validation passed with warnings for /home/emilio/Documents/ai/pizza/src/pizza_detector.py
[2025-05-14 01:23:09,730] [INFO] Validating script: constants.py
[2025-05-14 01:23:09,741] [WARNING] Missing or incomplete docstring in /home/emilio/Documents/ai/pizza/src/constants.py
[2025-05-14 01:23:09,742] [WARNING] Validation passed with warnings for /home/emilio/Documents/ai/pizza/src/constants.py
[2025-05-14 01:23:09,742] [INFO] Validating script: test_frame_buffer.py
[2025-05-14 01:23:09,746] [WARNING] Missing dependencies in /home/emilio/Documents/ai/pizza/src/emulation/test_frame_buffer.py: frame_buffer
[2025-05-14 01:23:09,863] [WARNING] Validation passed with warnings for /home/emilio/Documents/ai/pizza/src/emulation/test_frame_buffer.py
[2025-05-14 01:23:09,863] [INFO] Validating script: emulator-test.py
[2025-05-14 01:23:09,951] [WARNING] Missing or incomplete docstring in /home/emilio/Documents/ai/pizza/src/emulation/emulator-test.py
[2025-05-14 01:23:09,951] [WARNING] Validation passed with warnings for /home/emilio/Documents/ai/pizza/src/emulation/emulator-test.py
[2025-05-14 01:23:09,951] [INFO] Validating script: emulator.py
[2025-05-14 01:23:09,955] [WARNING] Missing dependencies in /home/emilio/Documents/ai/pizza/src/emulation/emulator.py: exceptions, constants, frame_buffer, power_manager
[2025-05-14 01:23:10,021] [WARNING] Execution test issue in /home/emilio/Documents/ai/pizza/src/emulation/emulator.py: Execution failed with error: Traceback (most recent call last):
  File "/home/emilio/Documents/ai/pizza/src/emulation/emulator.py", line 12, in <module>
    from .constants import (
ImportError: attempted relative import with no known parent package

[2025-05-14 01:23:10,023] [WARNING] Validation passed with warnings for /home/emilio/Documents/ai/pizza/src/emulation/emulator.py
[2025-05-14 01:23:10,023] [INFO] Validating script: frame_buffer.py
[2025-05-14 01:23:10,091] [INFO] Validation passed for /home/emilio/Documents/ai/pizza/src/emulation/frame_buffer.py
[2025-05-14 01:23:10,091] [INFO] Validating script: metrics.py
[2025-05-14 01:23:10,096] [WARNING] Missing dependencies in /home/emilio/Documents/ai/pizza/src/analysis/metrics.py: exceptions, constants
[2025-05-14 01:23:11,516] [WARNING] Execution test issue in /home/emilio/Documents/ai/pizza/src/analysis/metrics.py: Execution failed with error: Traceback (most recent call last):
  File "/home/emilio/Documents/ai/pizza/src/analysis/metrics.py", line 16, in <module>
    from .types import (
ImportError: attempted relative import with no known parent package

[2025-05-14 01:23:11,518] [WARNING] Validation passed with warnings for /home/emilio/Documents/ai/pizza/src/analysis/metrics.py
[2025-05-14 01:23:11,518] [INFO] Validating script: models.py
[2025-05-14 01:23:11,763] [WARNING] Missing or incomplete docstring in /home/emilio/Documents/ai/pizza/src/chatlist_ki/models.py
[2025-05-14 01:23:11,763] [WARNING] Validation passed with warnings for /home/emilio/Documents/ai/pizza/src/chatlist_ki/models.py
[2025-05-14 01:23:11,763] [INFO] Validating script: __main__.py
[2025-05-14 01:23:11,764] [WARNING] Missing dependencies in /home/emilio/Documents/ai/pizza/src/chatlist_ki/__main__.py: chat_interface, database, models
[2025-05-14 01:23:11,774] [WARNING] Execution test issue in /home/emilio/Documents/ai/pizza/src/chatlist_ki/__main__.py: Execution failed with error: Traceback (most recent call last):
  File "/home/emilio/Documents/ai/pizza/src/chatlist_ki/__main__.py", line 1, in <module>
    from .chat_interface import ChatInterface
ImportError: attempted relative import with no known parent package

[2025-05-14 01:23:11,775] [WARNING] Missing or incomplete docstring in /home/emilio/Documents/ai/pizza/src/chatlist_ki/__main__.py
[2025-05-14 01:23:11,775] [WARNING] Validation passed with warnings for /home/emilio/Documents/ai/pizza/src/chatlist_ki/__main__.py
[2025-05-14 01:23:11,775] [INFO] Validating script: __init__.py
[2025-05-14 01:23:11,775] [WARNING] Missing dependencies in /home/emilio/Documents/ai/pizza/src/chatlist_ki/__init__.py: database, models, chat_interface
[2025-05-14 01:23:11,787] [WARNING] Execution test issue in /home/emilio/Documents/ai/pizza/src/chatlist_ki/__init__.py: Execution failed with error: Traceback (most recent call last):
  File "/home/emilio/Documents/ai/pizza/src/chatlist_ki/__init__.py", line 1, in <module>
    from .models import Task, TaskStatus
ImportError: attempted relative import with no known parent package

[2025-05-14 01:23:11,787] [WARNING] Missing or incomplete docstring in /home/emilio/Documents/ai/pizza/src/chatlist_ki/__init__.py
[2025-05-14 01:23:11,787] [WARNING] Validation passed with warnings for /home/emilio/Documents/ai/pizza/src/chatlist_ki/__init__.py
[2025-05-14 01:23:11,787] [INFO] Validating script: api.py
[2025-05-14 01:23:11,914] [WARNING] Missing dependencies in /home/emilio/Documents/ai/pizza/src/chatlist_ki/api.py: database, models
[2025-05-14 01:23:12,109] [WARNING] Execution test issue in /home/emilio/Documents/ai/pizza/src/chatlist_ki/api.py: Execution failed with error: Traceback (most recent call last):
  File "/home/emilio/Documents/ai/pizza/src/chatlist_ki/api.py", line 5, in <module>
    from .database import Database, TaskManager
ImportError: attempted relative import with no known parent package

[2025-05-14 01:23:12,110] [WARNING] Missing or incomplete docstring in /home/emilio/Documents/ai/pizza/src/chatlist_ki/api.py
[2025-05-14 01:23:12,110] [WARNING] Validation passed with warnings for /home/emilio/Documents/ai/pizza/src/chatlist_ki/api.py
[2025-05-14 01:23:12,110] [INFO] Validating script: database.py
[2025-05-14 01:23:12,113] [WARNING] Missing dependencies in /home/emilio/Documents/ai/pizza/src/chatlist_ki/database.py: models
[2025-05-14 01:23:12,283] [WARNING] Execution test issue in /home/emilio/Documents/ai/pizza/src/chatlist_ki/database.py: Execution failed with error: Traceback (most recent call last):
  File "/home/emilio/Documents/ai/pizza/src/chatlist_ki/database.py", line 4, in <module>
    from .models import Base, Task, TaskStatus
ImportError: attempted relative import with no known parent package

[2025-05-14 01:23:12,283] [WARNING] Missing or incomplete docstring in /home/emilio/Documents/ai/pizza/src/chatlist_ki/database.py
[2025-05-14 01:23:12,283] [WARNING] Validation passed with warnings for /home/emilio/Documents/ai/pizza/src/chatlist_ki/database.py
[2025-05-14 01:23:12,284] [INFO] Validating script: chat_interface.py
[2025-05-14 01:23:12,285] [WARNING] Missing dependencies in /home/emilio/Documents/ai/pizza/src/chatlist_ki/chat_interface.py: database, models
[2025-05-14 01:23:12,301] [WARNING] Execution test issue in /home/emilio/Documents/ai/pizza/src/chatlist_ki/chat_interface.py: Execution failed with error: Traceback (most recent call last):
  File "/home/emilio/Documents/ai/pizza/src/chatlist_ki/chat_interface.py", line 2, in <module>
    from .database import TaskManager, Database
ImportError: attempted relative import with no known parent package

[2025-05-14 01:23:12,302] [WARNING] Missing or incomplete docstring in /home/emilio/Documents/ai/pizza/src/chatlist_ki/chat_interface.py
[2025-05-14 01:23:12,302] [WARNING] Validation passed with warnings for /home/emilio/Documents/ai/pizza/src/chatlist_ki/chat_interface.py
[2025-05-14 01:23:12,302] [INFO] Validating script: status_display.py
[2025-05-14 01:23:12,309] [WARNING] Missing dependencies in /home/emilio/Documents/ai/pizza/src/visualization/status_display.py: machine, ssd1306
[2025-05-14 01:23:12,336] [WARNING] Execution test issue in /home/emilio/Documents/ai/pizza/src/visualization/status_display.py: Execution failed with error: Traceback (most recent call last):
  File "/home/emilio/Documents/ai/pizza/src/visualization/status_display.py", line 22, in <module>
    from src.types import InferenceResult
ModuleNotFoundError: No module named 'src'

[2025-05-14 01:23:12,339] [WARNING] Validation passed with warnings for /home/emilio/Documents/ai/pizza/src/visualization/status_display.py
[2025-05-14 01:23:12,339] [INFO] Validating script: visualization.py
[2025-05-14 01:23:12,348] [WARNING] Missing dependencies in /home/emilio/Documents/ai/pizza/src/visualization/visualization.py: constants
[2025-05-14 01:23:14,047] [WARNING] Execution test issue in /home/emilio/Documents/ai/pizza/src/visualization/visualization.py: Execution failed with error: Traceback (most recent call last):
  File "/home/emilio/Documents/ai/pizza/src/visualization/visualization.py", line 15, in <module>
    from .types import (
ImportError: attempted relative import with no known parent package

[2025-05-14 01:23:14,049] [WARNING] Validation passed with warnings for /home/emilio/Documents/ai/pizza/src/visualization/visualization.py
[2025-05-14 01:23:14,049] [INFO] Validating script: exceptions.py
[2025-05-14 01:23:14,061] [INFO] Validation passed for /home/emilio/Documents/ai/pizza/src/utils/exceptions.py
[2025-05-14 01:23:14,061] [INFO] Validating script: types.py
[2025-05-14 01:23:14,075] [WARNING] Execution test issue in /home/emilio/Documents/ai/pizza/src/utils/types.py: Execution failed with error: Traceback (most recent call last):
  File "/home/emilio/Documents/ai/pizza/src/utils/types.py", line 5, in <module>
    from typing import Dict, List, Tuple, Optional, Union, NamedTuple, Callable
  File "/usr/lib/python3.12/typing.py", line 27, in <module>
    import contextlib
  File "/usr/lib/python3.12/contextlib.py", line 7, in <module>
    from functools import wraps
  File "/usr/lib/python3.12/functools.py", line 22, in <module>
    from types import GenericAlias
  File "/home/emilio/Documents/ai/pizza/src/utils/types.py", line 5, in <module>
    from typing import Dict, List, Tuple, Optional, Union, NamedTuple, Callable
ImportError: cannot import name 'Dict' from partially initialized module 'typing' (most likely due to a circular import) (/usr/lib/python3.12/typing.py)

[2025-05-14 01:23:14,076] [WARNING] Validation passed with warnings for /home/emilio/Documents/ai/pizza/src/utils/types.py
[2025-05-14 01:23:14,076] [INFO] Validating script: power_manager.py
[2025-05-14 01:23:14,080] [WARNING] Missing dependencies in /home/emilio/Documents/ai/pizza/src/utils/power_manager.py: devices, metrics, constants
[2025-05-14 01:23:14,093] [WARNING] Execution test issue in /home/emilio/Documents/ai/pizza/src/utils/power_manager.py: Execution failed with error: Traceback (most recent call last):
  File "/home/emilio/Documents/ai/pizza/src/utils/power_manager.py", line 7, in <module>
    import logging
  File "/usr/lib/python3.12/logging/__init__.py", line 26, in <module>
    import sys, os, time, io, re, traceback, warnings, weakref, collections.abc
  File "/usr/lib/python3.12/re/__init__.py", line 124, in <module>
    import enum
  File "/usr/lib/python3.12/enum.py", line 3, in <module>
    from types import MappingProxyType, DynamicClassAttribute
  File "/home/emilio/Documents/ai/pizza/src/utils/types.py", line 5, in <module>
    from typing import Dict, List, Tuple, Optional, Union, NamedTuple, Callable
  File "/usr/lib/python3.12/typing.py", line 27, in <module>
    import contextlib
  File "/usr/lib/python3.12/contextlib.py", line 7, in <module>
    from functools import wraps
  File "/usr/lib/python3.12/functools.py", line 22, in <module>
    from types import GenericAlias
ImportError: cannot import name 'GenericAlias' from partially initialized module 'types' (most likely due to a circular import) (/home/emilio/Documents/ai/pizza/src/utils/types.py)

[2025-05-14 01:23:14,095] [WARNING] Validation passed with warnings for /home/emilio/Documents/ai/pizza/src/utils/power_manager.py
[2025-05-14 01:23:14,095] [INFO] Validating script: devices.py
[2025-05-14 01:23:14,097] [WARNING] Missing dependencies in /home/emilio/Documents/ai/pizza/src/utils/devices.py: exceptions, constants
[2025-05-14 01:23:14,109] [WARNING] Execution test issue in /home/emilio/Documents/ai/pizza/src/utils/devices.py: Execution failed with error: Traceback (most recent call last):
  File "/home/emilio/Documents/ai/pizza/src/utils/devices.py", line 6, in <module>
    import logging
  File "/usr/lib/python3.12/logging/__init__.py", line 26, in <module>
    import sys, os, time, io, re, traceback, warnings, weakref, collections.abc
  File "/usr/lib/python3.12/re/__init__.py", line 124, in <module>
    import enum
  File "/usr/lib/python3.12/enum.py", line 3, in <module>
    from types import MappingProxyType, DynamicClassAttribute
  File "/home/emilio/Documents/ai/pizza/src/utils/types.py", line 5, in <module>
    from typing import Dict, List, Tuple, Optional, Union, NamedTuple, Callable
  File "/usr/lib/python3.12/typing.py", line 27, in <module>
    import contextlib
  File "/usr/lib/python3.12/contextlib.py", line 7, in <module>
    from functools import wraps
  File "/usr/lib/python3.12/functools.py", line 22, in <module>
    from types import GenericAlias
ImportError: cannot import name 'GenericAlias' from partially initialized module 'types' (most likely due to a circular import) (/home/emilio/Documents/ai/pizza/src/utils/types.py)

[2025-05-14 01:23:14,110] [WARNING] Validation passed with warnings for /home/emilio/Documents/ai/pizza/src/utils/devices.py
[2025-05-14 01:23:14,110] [INFO] Validating script: validation.py
[2025-05-14 01:23:14,112] [WARNING] Missing dependencies in /home/emilio/Documents/ai/pizza/src/utils/validation.py: exceptions, constants
[2025-05-14 01:23:14,126] [WARNING] Execution test issue in /home/emilio/Documents/ai/pizza/src/utils/validation.py: Execution failed with error: Traceback (most recent call last):
  File "/home/emilio/Documents/ai/pizza/src/utils/validation.py", line 6, in <module>
    import json
  File "/usr/lib/python3.12/json/__init__.py", line 106, in <module>
    from .decoder import JSONDecoder, JSONDecodeError
  File "/usr/lib/python3.12/json/decoder.py", line 3, in <module>
    import re
  File "/usr/lib/python3.12/re/__init__.py", line 124, in <module>
    import enum
  File "/usr/lib/python3.12/enum.py", line 3, in <module>
    from types import MappingProxyType, DynamicClassAttribute
  File "/home/emilio/Documents/ai/pizza/src/utils/types.py", line 5, in <module>
    from typing import Dict, List, Tuple, Optional, Union, NamedTuple, Callable
  File "/usr/lib/python3.12/typing.py", line 27, in <module>
    import contextlib
  File "/usr/lib/python3.12/contextlib.py", line 7, in <module>
    from functools import wraps
  File "/usr/lib/python3.12/functools.py", line 22, in <module>
    from types import GenericAlias
ImportError: cannot import name 'GenericAlias' from partially initialized module 'types' (most likely due to a circular import) (/home/emilio/Documents/ai/pizza/src/utils/types.py)

[2025-05-14 01:23:14,127] [WARNING] Validation passed with warnings for /home/emilio/Documents/ai/pizza/src/utils/validation.py
[2025-05-14 01:23:14,127] [INFO] Validating script: memory.py
[2025-05-14 01:23:14,129] [WARNING] Missing dependencies in /home/emilio/Documents/ai/pizza/src/utils/memory.py: exceptions, constants
[2025-05-14 01:23:14,143] [WARNING] Execution test issue in /home/emilio/Documents/ai/pizza/src/utils/memory.py: Execution failed with error: Traceback (most recent call last):
  File "/home/emilio/Documents/ai/pizza/src/utils/memory.py", line 5, in <module>
    import torch
  File "/home/emilio/Documents/ai/pizza/.venv/lib/python3.12/site-packages/torch/__init__.py", line 14, in <module>
    import ctypes
  File "/usr/lib/python3.12/ctypes/__init__.py", line 4, in <module>
    import types as _types
  File "/home/emilio/Documents/ai/pizza/src/utils/types.py", line 5, in <module>
    from typing import Dict, List, Tuple, Optional, Union, NamedTuple, Callable
  File "/usr/lib/python3.12/typing.py", line 27, in <module>
    import contextlib
  File "/usr/lib/python3.12/contextlib.py", line 7, in <module>
    from functools import wraps
  File "/usr/lib/python3.12/functools.py", line 22, in <module>
    from types import GenericAlias
ImportError: cannot import name 'GenericAlias' from partially initialized module 'types' (most likely due to a circular import) (/home/emilio/Documents/ai/pizza/src/utils/types.py)

[2025-05-14 01:23:14,144] [WARNING] Validation passed with warnings for /home/emilio/Documents/ai/pizza/src/utils/memory.py
[2025-05-14 01:23:14,144] [INFO] Validating script: temporal_smoother.py
[2025-05-14 01:23:14,160] [WARNING] Execution test issue in /home/emilio/Documents/ai/pizza/src/utils/temporal_smoother.py: Execution failed with error: Traceback (most recent call last):
  File "/home/emilio/Documents/ai/pizza/src/utils/temporal_smoother.py", line 9, in <module>
    import numpy as np
  File "/home/emilio/Documents/ai/pizza/.venv/lib/python3.12/site-packages/numpy/__init__.py", line 92, in <module>
    from ._globals import _NoValue, _CopyMode
  File "/home/emilio/Documents/ai/pizza/.venv/lib/python3.12/site-packages/numpy/_globals.py", line 18, in <module>
    import enum
  File "/usr/lib/python3.12/enum.py", line 3, in <module>
    from types import MappingProxyType, DynamicClassAttribute
  File "/home/emilio/Documents/ai/pizza/src/utils/types.py", line 5, in <module>
    from typing import Dict, List, Tuple, Optional, Union, NamedTuple, Callable
  File "/usr/lib/python3.12/typing.py", line 27, in <module>
    import contextlib
  File "/usr/lib/python3.12/contextlib.py", line 7, in <module>
    from functools import wraps
  File "/usr/lib/python3.12/functools.py", line 22, in <module>
    from types import GenericAlias
ImportError: cannot import name 'GenericAlias' from partially initialized module 'types' (most likely due to a circular import) (/home/emilio/Documents/ai/pizza/src/utils/types.py)

[2025-05-14 01:23:14,161] [WARNING] Validation passed with warnings for /home/emilio/Documents/ai/pizza/src/utils/temporal_smoother.py
[2025-05-14 01:23:14,161] [INFO] Validating script: utils.py
[2025-05-14 01:23:14,175] [WARNING] Execution test issue in /home/emilio/Documents/ai/pizza/src/utils/utils.py: Execution failed with error: Traceback (most recent call last):
  File "/home/emilio/Documents/ai/pizza/src/utils/utils.py", line 6, in <module>
    import logging
  File "/usr/lib/python3.12/logging/__init__.py", line 26, in <module>
    import sys, os, time, io, re, traceback, warnings, weakref, collections.abc
  File "/usr/lib/python3.12/re/__init__.py", line 124, in <module>
    import enum
  File "/usr/lib/python3.12/enum.py", line 3, in <module>
    from types import MappingProxyType, DynamicClassAttribute
  File "/home/emilio/Documents/ai/pizza/src/utils/types.py", line 5, in <module>
    from typing import Dict, List, Tuple, Optional, Union, NamedTuple, Callable
  File "/usr/lib/python3.12/typing.py", line 27, in <module>
    import contextlib
  File "/usr/lib/python3.12/contextlib.py", line 7, in <module>
    from functools import wraps
  File "/usr/lib/python3.12/functools.py", line 22, in <module>
    from types import GenericAlias
ImportError: cannot import name 'GenericAlias' from partially initialized module 'types' (most likely due to a circular import) (/home/emilio/Documents/ai/pizza/src/utils/types.py)

[2025-05-14 01:23:14,175] [WARNING] Validation passed with warnings for /home/emilio/Documents/ai/pizza/src/utils/utils.py
[2025-05-14 01:23:14,175] [INFO] Validating script: constants.py
[2025-05-14 01:23:14,188] [WARNING] Execution test issue in /home/emilio/Documents/ai/pizza/src/utils/constants.py: Execution failed with error: Traceback (most recent call last):
  File "/home/emilio/Documents/ai/pizza/src/utils/constants.py", line 5, in <module>
    from pathlib import Path
  File "/usr/lib/python3.12/pathlib.py", line 8, in <module>
    import fnmatch
  File "/usr/lib/python3.12/fnmatch.py", line 14, in <module>
    import re
  File "/usr/lib/python3.12/re/__init__.py", line 124, in <module>
    import enum
  File "/usr/lib/python3.12/enum.py", line 3, in <module>
    from types import MappingProxyType, DynamicClassAttribute
  File "/home/emilio/Documents/ai/pizza/src/utils/types.py", line 5, in <module>
    from typing import Dict, List, Tuple, Optional, Union, NamedTuple, Callable
  File "/usr/lib/python3.12/typing.py", line 27, in <module>
    import contextlib
  File "/usr/lib/python3.12/contextlib.py", line 7, in <module>
    from functools import wraps
  File "/usr/lib/python3.12/functools.py", line 22, in <module>
    from types import GenericAlias
ImportError: cannot import name 'GenericAlias' from partially initialized module 'types' (most likely due to a circular import) (/home/emilio/Documents/ai/pizza/src/utils/types.py)

[2025-05-14 01:23:14,188] [WARNING] Validation passed with warnings for /home/emilio/Documents/ai/pizza/src/utils/constants.py
[2025-05-14 01:23:14,188] [INFO] Validating script: enhanced_pizza_augmentation.py
[2025-05-14 01:23:16,257] [WARNING] Execution test issue in /home/emilio/Documents/ai/pizza/src/augmentation/enhanced_pizza_augmentation.py: Execution failed with error: 
[2025-05-14 01:23:16,270] [WARNING] Missing or incomplete docstring in /home/emilio/Documents/ai/pizza/src/augmentation/enhanced_pizza_augmentation.py
[2025-05-14 01:23:16,270] [WARNING] Validation passed with warnings for /home/emilio/Documents/ai/pizza/src/augmentation/enhanced_pizza_augmentation.py
[2025-05-14 01:23:16,270] [INFO] Validating script: augmentation_optimized.py
[2025-05-14 01:23:18,495] [WARNING] Execution test issue in /home/emilio/Documents/ai/pizza/src/augmentation/augmentation_optimized.py: Execution failed with error: Traceback (most recent call last):
  File "/home/emilio/Documents/ai/pizza/src/augmentation/augmentation_optimized.py", line 698, in <module>
    main()
  File "/home/emilio/Documents/ai/pizza/src/augmentation/augmentation_optimized.py", line 688, in main
    augment_pizza_dataset(input_dir, output_dir, img_per_original=img_per_original, batch_size=batch_size)
  File "/home/emilio/Documents/ai/pizza/src/augmentation/augmentation_optimized.py", line 512, in augment_pizza_dataset
    image_files = [os.path.join(input_dir, f) for f in os.listdir(input_dir) 
                                                       ^^^^^^^^^^^^^^^^^^^^^
FileNotFoundError: [Errno 2] No such file or directory: '/home/emilio/Documents/ai/pizza/img-pizza/'

[2025-05-14 01:23:18,498] [WARNING] Missing or incomplete docstring in /home/emilio/Documents/ai/pizza/src/augmentation/augmentation_optimized.py
[2025-05-14 01:23:18,500] [WARNING] Validation passed with warnings for /home/emilio/Documents/ai/pizza/src/augmentation/augmentation_optimized.py
[2025-05-14 01:23:18,500] [INFO] Validating script: diffusion_pizza_generator.py
[2025-05-14 01:23:22,884] [INFO] Validation passed for /home/emilio/Documents/ai/pizza/src/augmentation/diffusion_pizza_generator.py
[2025-05-14 01:23:22,884] [INFO] Validating script: augmentation.py
[2025-05-14 01:23:24,967] [WARNING] Execution test issue in /home/emilio/Documents/ai/pizza/src/augmentation/augmentation.py: Execution failed with error: 
[2025-05-14 01:23:24,976] [WARNING] Missing or incomplete docstring in /home/emilio/Documents/ai/pizza/src/augmentation/augmentation.py
[2025-05-14 01:23:24,976] [WARNING] Validation passed with warnings for /home/emilio/Documents/ai/pizza/src/augmentation/augmentation.py
[2025-05-14 01:23:24,976] [INFO] Validating script: advanced_pizza_diffusion_control.py
[2025-05-14 01:23:24,997] [WARNING] Execution test issue in /home/emilio/Documents/ai/pizza/src/augmentation/advanced_pizza_diffusion_control.py: Execution failed with error:   File "/home/emilio/Documents/ai/pizza/src/augmentation/advanced_pizza_diffusion_control.py", line 293
    image_size=image_size,
    ^^^^^^^^^^^^^^^^^^^^^
SyntaxError: keyword argument repeated: image_size

[2025-05-14 01:23:25,000] [WARNING] Validation passed with warnings for /home/emilio/Documents/ai/pizza/src/augmentation/advanced_pizza_diffusion_control.py
[2025-05-14 01:23:25,001] [INFO] Validating script: optimized-pizza-augmentation.py
[2025-05-14 01:23:27,208] [WARNING] Execution test issue in /home/emilio/Documents/ai/pizza/src/augmentation/optimized-pizza-augmentation.py: Execution failed with error: Traceback (most recent call last):
  File "/home/emilio/Documents/ai/pizza/src/augmentation/optimized-pizza-augmentation.py", line 698, in <module>
    main()
  File "/home/emilio/Documents/ai/pizza/src/augmentation/optimized-pizza-augmentation.py", line 688, in main
    augment_pizza_dataset(input_dir, output_dir, img_per_original=img_per_original, batch_size=batch_size)
  File "/home/emilio/Documents/ai/pizza/src/augmentation/optimized-pizza-augmentation.py", line 512, in augment_pizza_dataset
    image_files = [os.path.join(input_dir, f) for f in os.listdir(input_dir) 
                                                       ^^^^^^^^^^^^^^^^^^^^^
FileNotFoundError: [Errno 2] No such file or directory: '/home/emilio/Documents/ai/pizza/img-pizza/'

[2025-05-14 01:23:27,211] [WARNING] Missing or incomplete docstring in /home/emilio/Documents/ai/pizza/src/augmentation/optimized-pizza-augmentation.py
[2025-05-14 01:23:27,211] [WARNING] Validation passed with warnings for /home/emilio/Documents/ai/pizza/src/augmentation/optimized-pizza-augmentation.py
[2025-05-14 01:23:27,211] [INFO] Validating script: augment_legacy.py
[2025-05-14 01:23:29,147] [WARNING] Execution test issue in /home/emilio/Documents/ai/pizza/src/legacy/augment_legacy.py: Execution failed with error: Traceback (most recent call last):
  File "/home/emilio/Documents/ai/pizza/src/legacy/augment_legacy.py", line 176, in <module>
    augment_pizza(input_dir, output_dir, num_images, batch_size) 
    ^^^^^^^^^^^^^^^^^^^^^^^^^^^^^^^^^^^^^^^^^^^^^^^^^^^^^^^^^^^^
  File "/home/emilio/Documents/ai/pizza/src/legacy/augment_legacy.py", line 131, in augment_pizza
    image_files = [os.path.join(input_dir, f) for f in os.listdir(input_dir) 
                                                       ^^^^^^^^^^^^^^^^^^^^^
FileNotFoundError: [Errno 2] No such file or directory: 'img-pizza'

[2025-05-14 01:23:29,148] [WARNING] Missing or incomplete docstring in /home/emilio/Documents/ai/pizza/src/legacy/augment_legacy.py
[2025-05-14 01:23:29,148] [WARNING] Validation passed with warnings for /home/emilio/Documents/ai/pizza/src/legacy/augment_legacy.py
[2025-05-14 01:23:29,148] [INFO] Validating script: diffusion_data_agent.py
[2025-05-14 01:23:29,155] [WARNING] Missing dependencies in /home/emilio/Documents/ai/pizza/src/integration/diffusion_data_agent.py: cleanfid
[2025-05-14 01:23:30,844] [WARNING] Validation passed with warnings for /home/emilio/Documents/ai/pizza/src/integration/diffusion_data_agent.py
[2025-05-14 01:23:30,844] [INFO] Validating script: pizza_diffusion_integration.py
[2025-05-14 01:23:30,850] [WARNING] Missing dependencies in /home/emilio/Documents/ai/pizza/src/integration/pizza_diffusion_integration.py: optimized_pizza_augmentation, diffusion_data_agent, enhanced_pizza_augmentation
[2025-05-14 01:23:32,535] [WARNING] Execution test issue in /home/emilio/Documents/ai/pizza/src/integration/pizza_diffusion_integration.py: Execution failed with error: Traceback (most recent call last):
  File "/home/emilio/Documents/ai/pizza/src/integration/pizza_diffusion_integration.py", line 29, in <module>
    from enhanced_pizza_augmentation import (
ModuleNotFoundError: No module named 'enhanced_pizza_augmentation'

During handling of the above exception, another exception occurred:

Traceback (most recent call last):
  File "/home/emilio/Documents/ai/pizza/src/integration/pizza_diffusion_integration.py", line 40, in <module>
    from optimized_pizza_augmentation import (
ModuleNotFoundError: No module named 'optimized_pizza_augmentation'

During handling of the above exception, another exception occurred:

Traceback (most recent call last):
  File "/home/emilio/Documents/ai/pizza/src/integration/pizza_diffusion_integration.py", line 49, in <module>
    from test import (
ImportError: cannot import name 'PizzaBurningEffect' from 'test' (/usr/lib/python3.12/test/__init__.py)

[2025-05-14 01:23:32,538] [WARNING] Validation passed with warnings for /home/emilio/Documents/ai/pizza/src/integration/pizza_diffusion_integration.py
[2025-05-14 01:23:32,538] [INFO] Validating script: diffusion_training_integration.py
[2025-05-14 01:23:36,962] [WARNING] Execution test issue in /home/emilio/Documents/ai/pizza/src/integration/diffusion_training_integration.py: Execution failed with error: 2025-05-14 01:23:34.642249: I tensorflow/core/util/port.cc:153] oneDNN custom operations are on. You may see slightly different numerical results due to floating-point round-off errors from different computation orders. To turn them off, set the environment variable `TF_ENABLE_ONEDNN_OPTS=0`.
2025-05-14 01:23:34.650532: E external/local_xla/xla/stream_executor/cuda/cuda_fft.cc:467] Unable to register cuFFT factory: Attempting to register factory for plugin cuFFT when one has already been registered
WARNING: All log messages before absl::InitializeLog() is called are written to STDERR
E0000 00:00:1747178614.660669  160553 cuda_dnn.cc:8579] Unable to register cuDNN factory: Attempting to register factory for plugin cuDNN when one has already been registered
E0000 00:00:1747178614.663635  160553 cuda_blas.cc:1407] Unable to register cuBLAS factory: Attempting to register factory for plugin cuBLAS when one has already been registered
W0000 00:00:1747178614.671391  160553 computation_placer.cc:177] computation placer already registered. Please check linkage and avoid linking the same target more than once.
W0000 00:00:1747178614.671402  160553 computation_placer.cc:177] computation placer already registered. Please check linkage and avoid linking the same target more than once.
W0000 00:00:1747178614.671403  160553 computation_placer.cc:177] computation placer already registered. Please check linkage and avoid linking the same target more than once.
W0000 00:00:1747178614.671404  160553 computation_placer.cc:177] computation placer already registered. Please check linkage and avoid linking the same target more than once.
2025-05-14 01:23:34.673993: I tensorflow/core/platform/cpu_feature_guard.cc:210] This TensorFlow binary is optimized to use available CPU instructions in performance-critical operations.
To enable the following instructions: AVX2 AVX_VNNI FMA, in other operations, rebuild TensorFlow with the appropriate compiler flags.
Traceback (most recent call last):
  File "/home/emilio/Documents/ai/pizza/src/integration/diffusion_training_integration.py", line 42, in <module>
    from src.augmentation.advanced_pizza_diffusion_control import AdvancedPizzaDiffusionControl
  File "/home/emilio/Documents/ai/pizza/src/augmentation/advanced_pizza_diffusion_control.py", line 293
    image_size=image_size,
    ^^^^^^^^^^^^^^^^^^^^^
SyntaxError: keyword argument repeated: image_size

[2025-05-14 01:23:36,966] [WARNING] Validation passed with warnings for /home/emilio/Documents/ai/pizza/src/integration/diffusion_training_integration.py
[2025-05-14 01:23:36,967] [INFO] Validation complete. Summary: 19 passed, 55 with warnings, 0 failed
[2025-05-14 01:23:36,967] [INFO] Report written to /home/emilio/Documents/ai/pizza/output/pipeline_runs/20250514_012216/reports/validation_report.json
