[2025-05-14 04:06:10,644] [INFO] Found 75 Python scripts to validate
[2025-05-14 04:06:10,644] [INFO] Validating script: cleanup.py
[2025-05-14 04:06:10,727] [INFO] Validation passed for /home/emilio/Documents/ai/pizza/scripts/cleanup.py
[2025-05-14 04:06:10,728] [INFO] Validating script: filter_dataset.py
[2025-05-14 04:06:10,737] [WARNING] Missing or incomplete docstring in /home/emilio/Documents/ai/pizza/scripts/filter_dataset.py
[2025-05-14 04:06:10,737] [WARNING] Validation passed with warnings for /home/emilio/Documents/ai/pizza/scripts/filter_dataset.py
[2025-05-14 04:06:10,737] [INFO] Validating script: label_tool.py
[2025-05-14 04:06:12,808] [INFO] Validation passed for /home/emilio/Documents/ai/pizza/scripts/label_tool.py
[2025-05-14 04:06:12,808] [INFO] Validating script: framebuffer_demo.py
[2025-05-14 04:06:12,895] [WARNING] Execution test issue in /home/emilio/Documents/ai/pizza/scripts/framebuffer_demo.py: Execution failed with error: 
[2025-05-14 04:06:12,896] [WARNING] Validation passed with warnings for /home/emilio/Documents/ai/pizza/scripts/framebuffer_demo.py
[2025-05-14 04:06:12,896] [INFO] Validating script: compare_inverted_residual.py
[2025-05-14 04:06:16,390] [INFO] Validation passed for /home/emilio/Documents/ai/pizza/scripts/compare_inverted_residual.py
[2025-05-14 04:06:16,390] [INFO] Validating script: test_temporal_smoothing.py
[2025-05-14 04:06:16,672] [INFO] Validation passed for /home/emilio/Documents/ai/pizza/scripts/test_temporal_smoothing.py
[2025-05-14 04:06:16,672] [INFO] Validating script: knowledge_distillation.py
[2025-05-14 04:06:18,595] [INFO] Validation passed for /home/emilio/Documents/ai/pizza/scripts/knowledge_distillation.py
[2025-05-14 04:06:18,595] [INFO] Validating script: visualize_gradcam.py
[2025-05-14 04:06:19,140] [WARNING] Missing dependencies in /home/emilio/Documents/ai/pizza/scripts/visualize_gradcam.py: scripts
[2025-05-14 04:06:21,525] [WARNING] Validation passed with warnings for /home/emilio/Documents/ai/pizza/scripts/visualize_gradcam.py
[2025-05-14 04:06:21,525] [INFO] Validating script: classify_images.py
[2025-05-14 04:06:21,541] [WARNING] Missing or incomplete docstring in /home/emilio/Documents/ai/pizza/scripts/classify_images.py
[2025-05-14 04:06:21,541] [WARNING] Validation passed with warnings for /home/emilio/Documents/ai/pizza/scripts/classify_images.py
[2025-05-14 04:06:21,541] [INFO] Validating script: visualize_pruning.py
[2025-05-14 04:06:23,848] [INFO] Validation passed for /home/emilio/Documents/ai/pizza/scripts/visualize_pruning.py
[2025-05-14 04:06:23,848] [INFO] Validating script: compare_tiny_cnns.py
[2025-05-14 04:06:23,877] [WARNING] Missing dependencies in /home/emilio/Documents/ai/pizza/scripts/compare_tiny_cnns.py: scripts
[2025-05-14 04:06:26,257] [WARNING] Validation passed with warnings for /home/emilio/Documents/ai/pizza/scripts/compare_tiny_cnns.py
[2025-05-14 04:06:26,257] [INFO] Validating script: compare_se_models.py
[2025-05-14 04:06:28,748] [INFO] Validation passed for /home/emilio/Documents/ai/pizza/scripts/compare_se_models.py
[2025-05-14 04:06:28,748] [INFO] Validating script: automated_test_suite.py
[2025-05-14 04:06:31,096] [WARNING] Execution test issue in /home/emilio/Documents/ai/pizza/scripts/automated_test_suite.py: Execution failed with error: Traceback (most recent call last):
  File "/home/emilio/Documents/ai/pizza/scripts/automated_test_suite.py", line 53, in <module>
    from src.pizza_detector import (
ImportError: cannot import name 'load_model' from 'src.pizza_detector' (/home/emilio/Documents/ai/pizza/src/pizza_detector.py)

[2025-05-14 04:06:31,100] [WARNING] Validation passed with warnings for /home/emilio/Documents/ai/pizza/scripts/automated_test_suite.py
[2025-05-14 04:06:31,101] [INFO] Validating script: compare_hard_swish.py
[2025-05-14 04:06:33,474] [INFO] Validation passed for /home/emilio/Documents/ai/pizza/scripts/compare_hard_swish.py
[2025-05-14 04:06:33,474] [INFO] Validating script: demo_status_display.py
[2025-05-14 04:06:33,503] [WARNING] Execution test issue in /home/emilio/Documents/ai/pizza/scripts/demo_status_display.py: Execution failed with error: Traceback (most recent call last):
  File "/home/emilio/Documents/ai/pizza/scripts/demo_status_display.py", line 38, in <module>
    from src.status_display import (
ModuleNotFoundError: No module named 'src.status_display'

[2025-05-14 04:06:33,504] [WARNING] Validation passed with warnings for /home/emilio/Documents/ai/pizza/scripts/demo_status_display.py
[2025-05-14 04:06:33,504] [INFO] Validating script: test_image_preprocessing.py
[2025-05-14 04:06:33,794] [INFO] Validation passed for /home/emilio/Documents/ai/pizza/scripts/test_image_preprocessing.py
[2025-05-14 04:06:33,794] [INFO] Validating script: test_pizza_detection.py
[2025-05-14 04:06:35,650] [WARNING] Execution test issue in /home/emilio/Documents/ai/pizza/scripts/test_pizza_detection.py: Execution failed with error: Traceback (most recent call last):
  File "/home/emilio/Documents/ai/pizza/scripts/test_pizza_detection.py", line 27, in <module>
    from src.types import InferenceResult
ModuleNotFoundError: No module named 'src.types'

[2025-05-14 04:06:35,651] [WARNING] Validation passed with warnings for /home/emilio/Documents/ai/pizza/scripts/test_pizza_detection.py
[2025-05-14 04:06:35,651] [INFO] Validating script: demo_power_management.py
[2025-05-14 04:06:35,921] [WARNING] Execution test issue in /home/emilio/Documents/ai/pizza/scripts/demo_power_management.py: Execution failed with error: Traceback (most recent call last):
  File "/home/emilio/Documents/ai/pizza/scripts/demo_power_management.py", line 19, in <module>
    from src.emulator import RP2040Emulator
ModuleNotFoundError: No module named 'src.emulator'

[2025-05-14 04:06:35,922] [WARNING] Validation passed with warnings for /home/emilio/Documents/ai/pizza/scripts/demo_power_management.py
[2025-05-14 04:06:35,922] [INFO] Validating script: analyze_performance_logs.py
[2025-05-14 04:06:36,609] [INFO] Validation passed for /home/emilio/Documents/ai/pizza/scripts/analyze_performance_logs.py
[2025-05-14 04:06:36,609] [INFO] Validating script: simulate_memory_constraints.py
[2025-05-14 04:06:36,879] [WARNING] Execution test issue in /home/emilio/Documents/ai/pizza/scripts/simulate_memory_constraints.py: Execution failed with error: Traceback (most recent call last):
  File "/home/emilio/Documents/ai/pizza/scripts/simulate_memory_constraints.py", line 17, in <module>
    from src.constants import (
ImportError: cannot import name 'RP2040_CLOCK_SPEED_MHZ' from 'src.constants' (/home/emilio/Documents/ai/pizza/src/constants.py). Did you mean: 'RP2040_CLOCK_SPEED'?

[2025-05-14 04:06:36,881] [WARNING] Validation passed with warnings for /home/emilio/Documents/ai/pizza/scripts/simulate_memory_constraints.py
[2025-05-14 04:06:36,881] [INFO] Validating script: simulate_clahe_resources.py
[2025-05-14 04:06:37,163] [INFO] Validation passed for /home/emilio/Documents/ai/pizza/scripts/simulate_clahe_resources.py
[2025-05-14 04:06:37,163] [INFO] Validating script: run_pizza_tests.py
[2025-05-14 04:06:37,187] [INFO] Validation passed for /home/emilio/Documents/ai/pizza/scripts/run_pizza_tests.py
[2025-05-14 04:06:37,188] [INFO] Validating script: run_pruning_clustering.py
[2025-05-14 04:06:37,190] [WARNING] Missing dependencies in /home/emilio/Documents/ai/pizza/scripts/run_pruning_clustering.py: config, scripts
[2025-05-14 04:06:39,030] [WARNING] Validation passed with warnings for /home/emilio/Documents/ai/pizza/scripts/run_pruning_clustering.py
[2025-05-14 04:06:39,030] [INFO] Validating script: augment_dataset.py
[2025-05-14 04:06:39,146] [INFO] Validation passed for /home/emilio/Documents/ai/pizza/scripts/augment_dataset.py
[2025-05-14 04:06:39,146] [INFO] Validating script: train_pizza_model.py
[2025-05-14 04:06:40,983] [INFO] Validation passed for /home/emilio/Documents/ai/pizza/scripts/train_pizza_model.py
[2025-05-14 04:06:40,983] [INFO] Validating script: simulate_lighting_conditions.py
[2025-05-14 04:06:41,255] [WARNING] Execution test issue in /home/emilio/Documents/ai/pizza/scripts/simulate_lighting_conditions.py: Execution failed with error: Traceback (most recent call last):
  File "/home/emilio/Documents/ai/pizza/scripts/simulate_lighting_conditions.py", line 17, in <module>
    from src.emulator import RP2040Emulator
ModuleNotFoundError: No module named 'src.emulator'

[2025-05-14 04:06:41,256] [WARNING] Validation passed with warnings for /home/emilio/Documents/ai/pizza/scripts/simulate_lighting_conditions.py
[2025-05-14 04:06:41,256] [INFO] Validating script: quantization_aware_training.py
[2025-05-14 04:06:43,198] [INFO] Validation passed for /home/emilio/Documents/ai/pizza/scripts/quantization_aware_training.py
[2025-05-14 04:06:43,198] [INFO] Validating script: simulate_power_consumption.py
[2025-05-14 04:06:43,465] [WARNING] Execution test issue in /home/emilio/Documents/ai/pizza/scripts/simulate_power_consumption.py: Execution failed with error: Traceback (most recent call last):
  File "/home/emilio/Documents/ai/pizza/scripts/simulate_power_consumption.py", line 18, in <module>
    from src.constants import (
ImportError: cannot import name 'RP2040_CLOCK_SPEED_MHZ' from 'src.constants' (/home/emilio/Documents/ai/pizza/src/constants.py). Did you mean: 'RP2040_CLOCK_SPEED'?

[2025-05-14 04:06:43,466] [WARNING] Validation passed with warnings for /home/emilio/Documents/ai/pizza/scripts/simulate_power_consumption.py
[2025-05-14 04:06:43,466] [INFO] Validating script: generate_pizza_dataset.py
[2025-05-14 04:06:47,863] [INFO] Validation passed for /home/emilio/Documents/ai/pizza/scripts/generate_pizza_dataset.py
[2025-05-14 04:06:47,863] [INFO] Validating script: hyperparameter_search.py
[2025-05-14 04:06:50,289] [INFO] Validation passed for /home/emilio/Documents/ai/pizza/scripts/hyperparameter_search.py
[2025-05-14 04:06:50,289] [INFO] Validating script: extract_frames.py
[2025-05-14 04:06:50,301] [WARNING] Missing or incomplete docstring in /home/emilio/Documents/ai/pizza/scripts/extract_frames.py
[2025-05-14 04:06:50,301] [WARNING] Validation passed with warnings for /home/emilio/Documents/ai/pizza/scripts/extract_frames.py
[2025-05-14 04:06:50,301] [INFO] Validating script: validate_integration.py
[2025-05-14 04:06:50,337] [INFO] Validation passed for /home/emilio/Documents/ai/pizza/scripts/ci/validate_integration.py
[2025-05-14 04:06:50,337] [INFO] Validating script: validate_scripts.py
[2025-05-14 04:06:50,423] [INFO] Validation passed for /home/emilio/Documents/ai/pizza/scripts/ci/validate_scripts.py
[2025-05-14 04:06:50,423] [INFO] Validating script: generate_pipeline_report.py
[2025-05-14 04:06:50,703] [INFO] Validation passed for /home/emilio/Documents/ai/pizza/scripts/ci/generate_pipeline_report.py
[2025-05-14 04:06:50,703] [INFO] Validating script: generate_optimization_summary.py
[2025-05-14 04:06:50,980] [INFO] Validation passed for /home/emilio/Documents/ai/pizza/scripts/ci/generate_optimization_summary.py
[2025-05-14 04:06:50,980] [INFO] Validating script: weight_pruning.py
[2025-05-14 04:06:50,989] [WARNING] Missing dependencies in /home/emilio/Documents/ai/pizza/scripts/model_optimization/weight_pruning.py: config
[2025-05-14 04:06:52,858] [WARNING] Validation passed with warnings for /home/emilio/Documents/ai/pizza/scripts/model_optimization/weight_pruning.py
[2025-05-14 04:06:52,858] [INFO] Validating script: micropizzanet_early_exit.py
[2025-05-14 04:06:54,711] [INFO] Validation passed for /home/emilio/Documents/ai/pizza/scripts/early_exit/micropizzanet_early_exit.py
[2025-05-14 04:06:54,712] [INFO] Validating script: verify_model.py
[2025-05-14 04:06:56,309] [WARNING] Missing or incomplete docstring in /home/emilio/Documents/ai/pizza/models/rp2040_export/verify_model.py
[2025-05-14 04:06:56,309] [WARNING] Validation passed with warnings for /home/emilio/Documents/ai/pizza/models/rp2040_export/verify_model.py
[2025-05-14 04:06:56,309] [INFO] Validating script: pizza-baking-detection-final.py
[2025-05-14 04:06:57,339] [WARNING] Missing dependencies in /home/emilio/Documents/ai/pizza/src/pizza-baking-detection-final.py: onnx_tf
[2025-05-14 04:07:01,871] [WARNING] Missing or incomplete docstring in /home/emilio/Documents/ai/pizza/src/pizza-baking-detection-final.py
[2025-05-14 04:07:01,871] [WARNING] Validation passed with warnings for /home/emilio/Documents/ai/pizza/src/pizza-baking-detection-final.py
[2025-05-14 04:07:01,871] [INFO] Validating script: metrics.py
[2025-05-14 04:07:02,996] [INFO] Validation passed for /home/emilio/Documents/ai/pizza/src/metrics.py
[2025-05-14 04:07:02,996] [INFO] Validating script: __init__.py
[2025-05-14 04:07:03,005] [WARNING] Missing or incomplete docstring in /home/emilio/Documents/ai/pizza/src/__init__.py
[2025-05-14 04:07:03,005] [WARNING] Validation passed with warnings for /home/emilio/Documents/ai/pizza/src/__init__.py
[2025-05-14 04:07:03,005] [INFO] Validating script: pizza_detector.py
[2025-05-14 04:07:03,027] [WARNING] Missing dependencies in /home/emilio/Documents/ai/pizza/src/pizza_detector.py: onnx_tf
[2025-05-14 04:07:07,708] [WARNING] Missing or incomplete docstring in /home/emilio/Documents/ai/pizza/src/pizza_detector.py
[2025-05-14 04:07:07,708] [WARNING] Validation passed with warnings for /home/emilio/Documents/ai/pizza/src/pizza_detector.py
[2025-05-14 04:07:07,708] [INFO] Validating script: constants.py
[2025-05-14 04:07:07,735] [INFO] Validation passed for /home/emilio/Documents/ai/pizza/src/constants.py
[2025-05-14 04:07:07,735] [INFO] Validating script: test_frame_buffer.py
[2025-05-14 04:07:07,737] [WARNING] Missing dependencies in /home/emilio/Documents/ai/pizza/src/emulation/test_frame_buffer.py: frame_buffer
[2025-05-14 04:07:07,840] [WARNING] Validation passed with warnings for /home/emilio/Documents/ai/pizza/src/emulation/test_frame_buffer.py
[2025-05-14 04:07:07,840] [INFO] Validating script: emulator-test.py
[2025-05-14 04:07:07,949] [WARNING] Missing or incomplete docstring in /home/emilio/Documents/ai/pizza/src/emulation/emulator-test.py
[2025-05-14 04:07:07,949] [WARNING] Validation passed with warnings for /home/emilio/Documents/ai/pizza/src/emulation/emulator-test.py
[2025-05-14 04:07:07,949] [INFO] Validating script: emulator.py
[2025-05-14 04:07:07,953] [WARNING] Missing dependencies in /home/emilio/Documents/ai/pizza/src/emulation/emulator.py: frame_buffer, power_manager, constants, exceptions
[2025-05-14 04:07:08,042] [WARNING] Execution test issue in /home/emilio/Documents/ai/pizza/src/emulation/emulator.py: Execution failed with error: Traceback (most recent call last):
  File "/home/emilio/Documents/ai/pizza/src/emulation/emulator.py", line 12, in <module>
    from .constants import (
ImportError: attempted relative import with no known parent package

[2025-05-14 04:07:08,044] [WARNING] Validation passed with warnings for /home/emilio/Documents/ai/pizza/src/emulation/emulator.py
[2025-05-14 04:07:08,044] [INFO] Validating script: frame_buffer.py
[2025-05-14 04:07:08,138] [INFO] Validation passed for /home/emilio/Documents/ai/pizza/src/emulation/frame_buffer.py
[2025-05-14 04:07:08,138] [INFO] Validating script: metrics.py
[2025-05-14 04:07:08,143] [WARNING] Missing dependencies in /home/emilio/Documents/ai/pizza/src/analysis/metrics.py: constants, exceptions
[2025-05-14 04:07:09,559] [WARNING] Execution test issue in /home/emilio/Documents/ai/pizza/src/analysis/metrics.py: Execution failed with error: Traceback (most recent call last):
  File "/home/emilio/Documents/ai/pizza/src/analysis/metrics.py", line 16, in <module>
    from .types import (
ImportError: attempted relative import with no known parent package

[2025-05-14 04:07:09,561] [WARNING] Validation passed with warnings for /home/emilio/Documents/ai/pizza/src/analysis/metrics.py
[2025-05-14 04:07:09,561] [INFO] Validating script: models.py
[2025-05-14 04:07:09,783] [WARNING] Missing or incomplete docstring in /home/emilio/Documents/ai/pizza/src/chatlist_ki/models.py
[2025-05-14 04:07:09,783] [WARNING] Validation passed with warnings for /home/emilio/Documents/ai/pizza/src/chatlist_ki/models.py
[2025-05-14 04:07:09,783] [INFO] Validating script: __main__.py
[2025-05-14 04:07:09,784] [WARNING] Missing dependencies in /home/emilio/Documents/ai/pizza/src/chatlist_ki/__main__.py: chat_interface, database, models
[2025-05-14 04:07:09,792] [WARNING] Execution test issue in /home/emilio/Documents/ai/pizza/src/chatlist_ki/__main__.py: Execution failed with error: Traceback (most recent call last):
  File "/home/emilio/Documents/ai/pizza/src/chatlist_ki/__main__.py", line 1, in <module>
    from .chat_interface import ChatInterface
ImportError: attempted relative import with no known parent package

[2025-05-14 04:07:09,792] [WARNING] Missing or incomplete docstring in /home/emilio/Documents/ai/pizza/src/chatlist_ki/__main__.py
[2025-05-14 04:07:09,792] [WARNING] Validation passed with warnings for /home/emilio/Documents/ai/pizza/src/chatlist_ki/__main__.py
[2025-05-14 04:07:09,792] [INFO] Validating script: __init__.py
[2025-05-14 04:07:09,793] [WARNING] Missing dependencies in /home/emilio/Documents/ai/pizza/src/chatlist_ki/__init__.py: models, database, chat_interface
[2025-05-14 04:07:09,803] [WARNING] Execution test issue in /home/emilio/Documents/ai/pizza/src/chatlist_ki/__init__.py: Execution failed with error: Traceback (most recent call last):
  File "/home/emilio/Documents/ai/pizza/src/chatlist_ki/__init__.py", line 1, in <module>
    from .models import Task, TaskStatus
ImportError: attempted relative import with no known parent package

[2025-05-14 04:07:09,804] [WARNING] Missing or incomplete docstring in /home/emilio/Documents/ai/pizza/src/chatlist_ki/__init__.py
[2025-05-14 04:07:09,804] [WARNING] Validation passed with warnings for /home/emilio/Documents/ai/pizza/src/chatlist_ki/__init__.py
[2025-05-14 04:07:09,804] [INFO] Validating script: api.py
[2025-05-14 04:07:09,922] [WARNING] Missing dependencies in /home/emilio/Documents/ai/pizza/src/chatlist_ki/api.py: database, models
[2025-05-14 04:07:10,109] [WARNING] Execution test issue in /home/emilio/Documents/ai/pizza/src/chatlist_ki/api.py: Execution failed with error: Traceback (most recent call last):
  File "/home/emilio/Documents/ai/pizza/src/chatlist_ki/api.py", line 5, in <module>
    from .database import Database, TaskManager
ImportError: attempted relative import with no known parent package

[2025-05-14 04:07:10,110] [WARNING] Missing or incomplete docstring in /home/emilio/Documents/ai/pizza/src/chatlist_ki/api.py
[2025-05-14 04:07:10,110] [WARNING] Validation passed with warnings for /home/emilio/Documents/ai/pizza/src/chatlist_ki/api.py
[2025-05-14 04:07:10,110] [INFO] Validating script: database.py
[2025-05-14 04:07:10,113] [WARNING] Missing dependencies in /home/emilio/Documents/ai/pizza/src/chatlist_ki/database.py: models
[2025-05-14 04:07:10,274] [WARNING] Execution test issue in /home/emilio/Documents/ai/pizza/src/chatlist_ki/database.py: Execution failed with error: Traceback (most recent call last):
  File "/home/emilio/Documents/ai/pizza/src/chatlist_ki/database.py", line 4, in <module>
    from .models import Base, Task, TaskStatus
ImportError: attempted relative import with no known parent package

[2025-05-14 04:07:10,275] [WARNING] Missing or incomplete docstring in /home/emilio/Documents/ai/pizza/src/chatlist_ki/database.py
[2025-05-14 04:07:10,275] [WARNING] Validation passed with warnings for /home/emilio/Documents/ai/pizza/src/chatlist_ki/database.py
[2025-05-14 04:07:10,275] [INFO] Validating script: chat_interface.py
[2025-05-14 04:07:10,278] [WARNING] Missing dependencies in /home/emilio/Documents/ai/pizza/src/chatlist_ki/chat_interface.py: models, database
[2025-05-14 04:07:10,298] [WARNING] Execution test issue in /home/emilio/Documents/ai/pizza/src/chatlist_ki/chat_interface.py: Execution failed with error: Traceback (most recent call last):
  File "/home/emilio/Documents/ai/pizza/src/chatlist_ki/chat_interface.py", line 2, in <module>
    from .database import TaskManager, Database
ImportError: attempted relative import with no known parent package

[2025-05-14 04:07:10,299] [WARNING] Missing or incomplete docstring in /home/emilio/Documents/ai/pizza/src/chatlist_ki/chat_interface.py
[2025-05-14 04:07:10,299] [WARNING] Validation passed with warnings for /home/emilio/Documents/ai/pizza/src/chatlist_ki/chat_interface.py
[2025-05-14 04:07:10,299] [INFO] Validating script: status_display.py
[2025-05-14 04:07:10,305] [WARNING] Missing dependencies in /home/emilio/Documents/ai/pizza/src/visualization/status_display.py: ssd1306, machine
[2025-05-14 04:07:10,330] [WARNING] Execution test issue in /home/emilio/Documents/ai/pizza/src/visualization/status_display.py: Execution failed with error: Traceback (most recent call last):
  File "/home/emilio/Documents/ai/pizza/src/visualization/status_display.py", line 22, in <module>
    from src.types import InferenceResult
ModuleNotFoundError: No module named 'src'

[2025-05-14 04:07:10,332] [WARNING] Validation passed with warnings for /home/emilio/Documents/ai/pizza/src/visualization/status_display.py
[2025-05-14 04:07:10,332] [INFO] Validating script: visualization.py
[2025-05-14 04:07:10,341] [WARNING] Missing dependencies in /home/emilio/Documents/ai/pizza/src/visualization/visualization.py: constants
[2025-05-14 04:07:11,965] [WARNING] Execution test issue in /home/emilio/Documents/ai/pizza/src/visualization/visualization.py: Execution failed with error: Traceback (most recent call last):
  File "/home/emilio/Documents/ai/pizza/src/visualization/visualization.py", line 15, in <module>
    from .types import (
ImportError: attempted relative import with no known parent package

[2025-05-14 04:07:11,967] [WARNING] Validation passed with warnings for /home/emilio/Documents/ai/pizza/src/visualization/visualization.py
[2025-05-14 04:07:11,967] [INFO] Validating script: exceptions.py
[2025-05-14 04:07:11,977] [INFO] Validation passed for /home/emilio/Documents/ai/pizza/src/utils/exceptions.py
[2025-05-14 04:07:11,977] [INFO] Validating script: types.py
[2025-05-14 04:07:11,990] [WARNING] Execution test issue in /home/emilio/Documents/ai/pizza/src/utils/types.py: Execution failed with error: Traceback (most recent call last):
  File "/home/emilio/Documents/ai/pizza/src/utils/types.py", line 5, in <module>
    from typing import Dict, List, Tuple, Optional, Union, NamedTuple, Callable
  File "/usr/lib/python3.12/typing.py", line 27, in <module>
    import contextlib
  File "/usr/lib/python3.12/contextlib.py", line 7, in <module>
    from functools import wraps
  File "/usr/lib/python3.12/functools.py", line 22, in <module>
    from types import GenericAlias
  File "/home/emilio/Documents/ai/pizza/src/utils/types.py", line 5, in <module>
    from typing import Dict, List, Tuple, Optional, Union, NamedTuple, Callable
ImportError: cannot import name 'Dict' from partially initialized module 'typing' (most likely due to a circular import) (/usr/lib/python3.12/typing.py)

[2025-05-14 04:07:11,990] [WARNING] Validation passed with warnings for /home/emilio/Documents/ai/pizza/src/utils/types.py
[2025-05-14 04:07:11,990] [INFO] Validating script: power_manager.py
[2025-05-14 04:07:11,996] [WARNING] Missing dependencies in /home/emilio/Documents/ai/pizza/src/utils/power_manager.py: constants, metrics, devices
[2025-05-14 04:07:12,011] [WARNING] Execution test issue in /home/emilio/Documents/ai/pizza/src/utils/power_manager.py: Execution failed with error: Traceback (most recent call last):
  File "/home/emilio/Documents/ai/pizza/src/utils/power_manager.py", line 7, in <module>
    import logging
  File "/usr/lib/python3.12/logging/__init__.py", line 26, in <module>
    import sys, os, time, io, re, traceback, warnings, weakref, collections.abc
  File "/usr/lib/python3.12/re/__init__.py", line 124, in <module>
    import enum
  File "/usr/lib/python3.12/enum.py", line 3, in <module>
    from types import MappingProxyType, DynamicClassAttribute
  File "/home/emilio/Documents/ai/pizza/src/utils/types.py", line 5, in <module>
    from typing import Dict, List, Tuple, Optional, Union, NamedTuple, Callable
  File "/usr/lib/python3.12/typing.py", line 27, in <module>
    import contextlib
  File "/usr/lib/python3.12/contextlib.py", line 7, in <module>
    from functools import wraps
  File "/usr/lib/python3.12/functools.py", line 22, in <module>
    from types import GenericAlias
ImportError: cannot import name 'GenericAlias' from partially initialized module 'types' (most likely due to a circular import) (/home/emilio/Documents/ai/pizza/src/utils/types.py)

[2025-05-14 04:07:12,012] [WARNING] Validation passed with warnings for /home/emilio/Documents/ai/pizza/src/utils/power_manager.py
[2025-05-14 04:07:12,012] [INFO] Validating script: devices.py
[2025-05-14 04:07:12,014] [WARNING] Missing dependencies in /home/emilio/Documents/ai/pizza/src/utils/devices.py: constants, exceptions
[2025-05-14 04:07:12,027] [WARNING] Execution test issue in /home/emilio/Documents/ai/pizza/src/utils/devices.py: Execution failed with error: Traceback (most recent call last):
  File "/home/emilio/Documents/ai/pizza/src/utils/devices.py", line 6, in <module>
    import logging
  File "/usr/lib/python3.12/logging/__init__.py", line 26, in <module>
    import sys, os, time, io, re, traceback, warnings, weakref, collections.abc
  File "/usr/lib/python3.12/re/__init__.py", line 124, in <module>
    import enum
  File "/usr/lib/python3.12/enum.py", line 3, in <module>
    from types import MappingProxyType, DynamicClassAttribute
  File "/home/emilio/Documents/ai/pizza/src/utils/types.py", line 5, in <module>
    from typing import Dict, List, Tuple, Optional, Union, NamedTuple, Callable
  File "/usr/lib/python3.12/typing.py", line 27, in <module>
    import contextlib
  File "/usr/lib/python3.12/contextlib.py", line 7, in <module>
    from functools import wraps
  File "/usr/lib/python3.12/functools.py", line 22, in <module>
    from types import GenericAlias
ImportError: cannot import name 'GenericAlias' from partially initialized module 'types' (most likely due to a circular import) (/home/emilio/Documents/ai/pizza/src/utils/types.py)

[2025-05-14 04:07:12,028] [WARNING] Validation passed with warnings for /home/emilio/Documents/ai/pizza/src/utils/devices.py
[2025-05-14 04:07:12,028] [INFO] Validating script: validation.py
[2025-05-14 04:07:12,030] [WARNING] Missing dependencies in /home/emilio/Documents/ai/pizza/src/utils/validation.py: constants, exceptions
[2025-05-14 04:07:12,043] [WARNING] Execution test issue in /home/emilio/Documents/ai/pizza/src/utils/validation.py: Execution failed with error: Traceback (most recent call last):
  File "/home/emilio/Documents/ai/pizza/src/utils/validation.py", line 6, in <module>
    import json
  File "/usr/lib/python3.12/json/__init__.py", line 106, in <module>
    from .decoder import JSONDecoder, JSONDecodeError
  File "/usr/lib/python3.12/json/decoder.py", line 3, in <module>
    import re
  File "/usr/lib/python3.12/re/__init__.py", line 124, in <module>
    import enum
  File "/usr/lib/python3.12/enum.py", line 3, in <module>
    from types import MappingProxyType, DynamicClassAttribute
  File "/home/emilio/Documents/ai/pizza/src/utils/types.py", line 5, in <module>
    from typing import Dict, List, Tuple, Optional, Union, NamedTuple, Callable
  File "/usr/lib/python3.12/typing.py", line 27, in <module>
    import contextlib
  File "/usr/lib/python3.12/contextlib.py", line 7, in <module>
    from functools import wraps
  File "/usr/lib/python3.12/functools.py", line 22, in <module>
    from types import GenericAlias
ImportError: cannot import name 'GenericAlias' from partially initialized module 'types' (most likely due to a circular import) (/home/emilio/Documents/ai/pizza/src/utils/types.py)

[2025-05-14 04:07:12,044] [WARNING] Validation passed with warnings for /home/emilio/Documents/ai/pizza/src/utils/validation.py
[2025-05-14 04:07:12,044] [INFO] Validating script: memory.py
[2025-05-14 04:07:12,046] [WARNING] Missing dependencies in /home/emilio/Documents/ai/pizza/src/utils/memory.py: exceptions, constants
[2025-05-14 04:07:12,058] [WARNING] Execution test issue in /home/emilio/Documents/ai/pizza/src/utils/memory.py: Execution failed with error: Traceback (most recent call last):
  File "/home/emilio/Documents/ai/pizza/src/utils/memory.py", line 5, in <module>
    import torch
  File "/home/emilio/Documents/ai/pizza/.venv/lib/python3.12/site-packages/torch/__init__.py", line 14, in <module>
    import ctypes
  File "/usr/lib/python3.12/ctypes/__init__.py", line 4, in <module>
    import types as _types
  File "/home/emilio/Documents/ai/pizza/src/utils/types.py", line 5, in <module>
    from typing import Dict, List, Tuple, Optional, Union, NamedTuple, Callable
  File "/usr/lib/python3.12/typing.py", line 27, in <module>
    import contextlib
  File "/usr/lib/python3.12/contextlib.py", line 7, in <module>
    from functools import wraps
  File "/usr/lib/python3.12/functools.py", line 22, in <module>
    from types import GenericAlias
ImportError: cannot import name 'GenericAlias' from partially initialized module 'types' (most likely due to a circular import) (/home/emilio/Documents/ai/pizza/src/utils/types.py)

[2025-05-14 04:07:12,059] [WARNING] Validation passed with warnings for /home/emilio/Documents/ai/pizza/src/utils/memory.py
[2025-05-14 04:07:12,059] [INFO] Validating script: temporal_smoother.py
[2025-05-14 04:07:12,075] [WARNING] Execution test issue in /home/emilio/Documents/ai/pizza/src/utils/temporal_smoother.py: Execution failed with error: Traceback (most recent call last):
  File "/home/emilio/Documents/ai/pizza/src/utils/temporal_smoother.py", line 9, in <module>
    import numpy as np
  File "/home/emilio/Documents/ai/pizza/.venv/lib/python3.12/site-packages/numpy/__init__.py", line 92, in <module>
    from ._globals import _NoValue, _CopyMode
  File "/home/emilio/Documents/ai/pizza/.venv/lib/python3.12/site-packages/numpy/_globals.py", line 18, in <module>
    import enum
  File "/usr/lib/python3.12/enum.py", line 3, in <module>
    from types import MappingProxyType, DynamicClassAttribute
  File "/home/emilio/Documents/ai/pizza/src/utils/types.py", line 5, in <module>
    from typing import Dict, List, Tuple, Optional, Union, NamedTuple, Callable
  File "/usr/lib/python3.12/typing.py", line 27, in <module>
    import contextlib
  File "/usr/lib/python3.12/contextlib.py", line 7, in <module>
    from functools import wraps
  File "/usr/lib/python3.12/functools.py", line 22, in <module>
    from types import GenericAlias
ImportError: cannot import name 'GenericAlias' from partially initialized module 'types' (most likely due to a circular import) (/home/emilio/Documents/ai/pizza/src/utils/types.py)

[2025-05-14 04:07:12,076] [WARNING] Validation passed with warnings for /home/emilio/Documents/ai/pizza/src/utils/temporal_smoother.py
[2025-05-14 04:07:12,076] [INFO] Validating script: utils.py
[2025-05-14 04:07:12,089] [WARNING] Execution test issue in /home/emilio/Documents/ai/pizza/src/utils/utils.py: Execution failed with error: Traceback (most recent call last):
  File "/home/emilio/Documents/ai/pizza/src/utils/utils.py", line 6, in <module>
    import logging
  File "/usr/lib/python3.12/logging/__init__.py", line 26, in <module>
    import sys, os, time, io, re, traceback, warnings, weakref, collections.abc
  File "/usr/lib/python3.12/re/__init__.py", line 124, in <module>
    import enum
  File "/usr/lib/python3.12/enum.py", line 3, in <module>
    from types import MappingProxyType, DynamicClassAttribute
  File "/home/emilio/Documents/ai/pizza/src/utils/types.py", line 5, in <module>
    from typing import Dict, List, Tuple, Optional, Union, NamedTuple, Callable
  File "/usr/lib/python3.12/typing.py", line 27, in <module>
    import contextlib
  File "/usr/lib/python3.12/contextlib.py", line 7, in <module>
    from functools import wraps
  File "/usr/lib/python3.12/functools.py", line 22, in <module>
    from types import GenericAlias
ImportError: cannot import name 'GenericAlias' from partially initialized module 'types' (most likely due to a circular import) (/home/emilio/Documents/ai/pizza/src/utils/types.py)

[2025-05-14 04:07:12,090] [WARNING] Validation passed with warnings for /home/emilio/Documents/ai/pizza/src/utils/utils.py
[2025-05-14 04:07:12,090] [INFO] Validating script: constants.py
[2025-05-14 04:07:12,103] [WARNING] Execution test issue in /home/emilio/Documents/ai/pizza/src/utils/constants.py: Execution failed with error: Traceback (most recent call last):
  File "/home/emilio/Documents/ai/pizza/src/utils/constants.py", line 5, in <module>
    from pathlib import Path
  File "/usr/lib/python3.12/pathlib.py", line 8, in <module>
    import fnmatch
  File "/usr/lib/python3.12/fnmatch.py", line 14, in <module>
    import re
  File "/usr/lib/python3.12/re/__init__.py", line 124, in <module>
    import enum
  File "/usr/lib/python3.12/enum.py", line 3, in <module>
    from types import MappingProxyType, DynamicClassAttribute
  File "/home/emilio/Documents/ai/pizza/src/utils/types.py", line 5, in <module>
    from typing import Dict, List, Tuple, Optional, Union, NamedTuple, Callable
  File "/usr/lib/python3.12/typing.py", line 27, in <module>
    import contextlib
  File "/usr/lib/python3.12/contextlib.py", line 7, in <module>
    from functools import wraps
  File "/usr/lib/python3.12/functools.py", line 22, in <module>
    from types import GenericAlias
ImportError: cannot import name 'GenericAlias' from partially initialized module 'types' (most likely due to a circular import) (/home/emilio/Documents/ai/pizza/src/utils/types.py)

[2025-05-14 04:07:12,104] [WARNING] Validation passed with warnings for /home/emilio/Documents/ai/pizza/src/utils/constants.py
[2025-05-14 04:07:12,104] [INFO] Validating script: enhanced_pizza_augmentation.py
[2025-05-14 04:07:14,067] [WARNING] Execution test issue in /home/emilio/Documents/ai/pizza/src/augmentation/enhanced_pizza_augmentation.py: Execution failed with error: 
[2025-05-14 04:07:14,076] [WARNING] Missing or incomplete docstring in /home/emilio/Documents/ai/pizza/src/augmentation/enhanced_pizza_augmentation.py
[2025-05-14 04:07:14,076] [WARNING] Validation passed with warnings for /home/emilio/Documents/ai/pizza/src/augmentation/enhanced_pizza_augmentation.py
[2025-05-14 04:07:14,076] [INFO] Validating script: augmentation_optimized.py
[2025-05-14 04:07:16,182] [WARNING] Execution test issue in /home/emilio/Documents/ai/pizza/src/augmentation/augmentation_optimized.py: Execution failed with error: Traceback (most recent call last):
  File "/home/emilio/Documents/ai/pizza/src/augmentation/augmentation_optimized.py", line 698, in <module>
    main()
  File "/home/emilio/Documents/ai/pizza/src/augmentation/augmentation_optimized.py", line 688, in main
    augment_pizza_dataset(input_dir, output_dir, img_per_original=img_per_original, batch_size=batch_size)
  File "/home/emilio/Documents/ai/pizza/src/augmentation/augmentation_optimized.py", line 512, in augment_pizza_dataset
    image_files = [os.path.join(input_dir, f) for f in os.listdir(input_dir) 
                                                       ^^^^^^^^^^^^^^^^^^^^^
FileNotFoundError: [Errno 2] No such file or directory: '/home/emilio/Documents/ai/pizza/img-pizza/'

[2025-05-14 04:07:16,185] [WARNING] Missing or incomplete docstring in /home/emilio/Documents/ai/pizza/src/augmentation/augmentation_optimized.py
[2025-05-14 04:07:16,185] [WARNING] Validation passed with warnings for /home/emilio/Documents/ai/pizza/src/augmentation/augmentation_optimized.py
[2025-05-14 04:07:16,186] [INFO] Validating script: diffusion_pizza_generator.py
[2025-05-14 04:07:20,402] [INFO] Validation passed for /home/emilio/Documents/ai/pizza/src/augmentation/diffusion_pizza_generator.py
[2025-05-14 04:07:20,402] [INFO] Validating script: augmentation.py
[2025-05-14 04:07:22,441] [WARNING] Execution test issue in /home/emilio/Documents/ai/pizza/src/augmentation/augmentation.py: Execution failed with error: 
[2025-05-14 04:07:22,449] [WARNING] Missing or incomplete docstring in /home/emilio/Documents/ai/pizza/src/augmentation/augmentation.py
[2025-05-14 04:07:22,449] [WARNING] Validation passed with warnings for /home/emilio/Documents/ai/pizza/src/augmentation/augmentation.py
[2025-05-14 04:07:22,449] [INFO] Validating script: advanced_pizza_diffusion_control.py
[2025-05-14 04:07:24,065] [WARNING] Execution test issue in /home/emilio/Documents/ai/pizza/src/augmentation/advanced_pizza_diffusion_control.py: Execution failed with error: Traceback (most recent call last):
  File "/home/emilio/Documents/ai/pizza/src/augmentation/advanced_pizza_diffusion_control.py", line 36, in <module>
    from src.augmentation.diffusion_pizza_generator import PizzaDiffusionGenerator, PIZZA_STAGES
ModuleNotFoundError: No module named 'src'

[2025-05-14 04:07:24,068] [WARNING] Validation passed with warnings for /home/emilio/Documents/ai/pizza/src/augmentation/advanced_pizza_diffusion_control.py
[2025-05-14 04:07:24,068] [INFO] Validating script: optimized-pizza-augmentation.py
[2025-05-14 04:07:26,174] [WARNING] Execution test issue in /home/emilio/Documents/ai/pizza/src/augmentation/optimized-pizza-augmentation.py: Execution failed with error: Traceback (most recent call last):
  File "/home/emilio/Documents/ai/pizza/src/augmentation/optimized-pizza-augmentation.py", line 698, in <module>
    main()
  File "/home/emilio/Documents/ai/pizza/src/augmentation/optimized-pizza-augmentation.py", line 688, in main
    augment_pizza_dataset(input_dir, output_dir, img_per_original=img_per_original, batch_size=batch_size)
  File "/home/emilio/Documents/ai/pizza/src/augmentation/optimized-pizza-augmentation.py", line 512, in augment_pizza_dataset
    image_files = [os.path.join(input_dir, f) for f in os.listdir(input_dir) 
                                                       ^^^^^^^^^^^^^^^^^^^^^
FileNotFoundError: [Errno 2] No such file or directory: '/home/emilio/Documents/ai/pizza/img-pizza/'

[2025-05-14 04:07:26,177] [WARNING] Missing or incomplete docstring in /home/emilio/Documents/ai/pizza/src/augmentation/optimized-pizza-augmentation.py
[2025-05-14 04:07:26,177] [WARNING] Validation passed with warnings for /home/emilio/Documents/ai/pizza/src/augmentation/optimized-pizza-augmentation.py
[2025-05-14 04:07:26,177] [INFO] Validating script: augment_legacy.py
[2025-05-14 04:07:28,017] [WARNING] Execution test issue in /home/emilio/Documents/ai/pizza/src/legacy/augment_legacy.py: Execution failed with error: Traceback (most recent call last):
  File "/home/emilio/Documents/ai/pizza/src/legacy/augment_legacy.py", line 176, in <module>
    augment_pizza(input_dir, output_dir, num_images, batch_size) 
    ^^^^^^^^^^^^^^^^^^^^^^^^^^^^^^^^^^^^^^^^^^^^^^^^^^^^^^^^^^^^
  File "/home/emilio/Documents/ai/pizza/src/legacy/augment_legacy.py", line 131, in augment_pizza
    image_files = [os.path.join(input_dir, f) for f in os.listdir(input_dir) 
                                                       ^^^^^^^^^^^^^^^^^^^^^
FileNotFoundError: [Errno 2] No such file or directory: 'img-pizza'

[2025-05-14 04:07:28,019] [WARNING] Missing or incomplete docstring in /home/emilio/Documents/ai/pizza/src/legacy/augment_legacy.py
[2025-05-14 04:07:28,019] [WARNING] Validation passed with warnings for /home/emilio/Documents/ai/pizza/src/legacy/augment_legacy.py
[2025-05-14 04:07:28,019] [INFO] Validating script: diffusion_data_agent.py
[2025-05-14 04:07:28,026] [WARNING] Missing dependencies in /home/emilio/Documents/ai/pizza/src/integration/diffusion_data_agent.py: cleanfid
[2025-05-14 04:07:29,621] [WARNING] Validation passed with warnings for /home/emilio/Documents/ai/pizza/src/integration/diffusion_data_agent.py
[2025-05-14 04:07:29,621] [INFO] Validating script: pizza_diffusion_integration.py
[2025-05-14 04:07:29,626] [WARNING] Missing dependencies in /home/emilio/Documents/ai/pizza/src/integration/pizza_diffusion_integration.py: enhanced_pizza_augmentation, optimized_pizza_augmentation, diffusion_data_agent
[2025-05-14 04:07:31,226] [WARNING] Execution test issue in /home/emilio/Documents/ai/pizza/src/integration/pizza_diffusion_integration.py: Execution failed with error: Traceback (most recent call last):
  File "/home/emilio/Documents/ai/pizza/src/integration/pizza_diffusion_integration.py", line 29, in <module>
    from enhanced_pizza_augmentation import (
ModuleNotFoundError: No module named 'enhanced_pizza_augmentation'

During handling of the above exception, another exception occurred:

Traceback (most recent call last):
  File "/home/emilio/Documents/ai/pizza/src/integration/pizza_diffusion_integration.py", line 40, in <module>
    from optimized_pizza_augmentation import (
ModuleNotFoundError: No module named 'optimized_pizza_augmentation'

During handling of the above exception, another exception occurred:

Traceback (most recent call last):
  File "/home/emilio/Documents/ai/pizza/src/integration/pizza_diffusion_integration.py", line 49, in <module>
    from test import (
ImportError: cannot import name 'PizzaBurningEffect' from 'test' (/usr/lib/python3.12/test/__init__.py)

[2025-05-14 04:07:31,229] [WARNING] Validation passed with warnings for /home/emilio/Documents/ai/pizza/src/integration/pizza_diffusion_integration.py
[2025-05-14 04:07:31,229] [INFO] Validating script: diffusion_training_integration.py
[2025-05-14 04:07:35,477] [INFO] Validation passed for /home/emilio/Documents/ai/pizza/src/integration/diffusion_training_integration.py
[2025-05-14 04:07:35,478] [INFO] Validation complete. Summary: 28 passed, 47 with warnings, 0 failed
[2025-05-14 04:07:35,478] [INFO] Report written to /home/emilio/Documents/ai/pizza/output/pipeline_runs/20250514_040610/reports/validation_report.json
