[2025-05-14 03:31:54,609] [INFO] Found 75 Python scripts to validate
[2025-05-14 03:31:54,609] [INFO] Validating script: cleanup.py
[2025-05-14 03:31:54,682] [INFO] Validation passed for /home/emilio/Documents/ai/pizza/scripts/cleanup.py
[2025-05-14 03:31:54,682] [INFO] Validating script: filter_dataset.py
[2025-05-14 03:31:54,693] [WARNING] Missing or incomplete docstring in /home/emilio/Documents/ai/pizza/scripts/filter_dataset.py
[2025-05-14 03:31:54,693] [WARNING] Validation passed with warnings for /home/emilio/Documents/ai/pizza/scripts/filter_dataset.py
[2025-05-14 03:31:54,693] [INFO] Validating script: label_tool.py
[2025-05-14 03:31:56,859] [INFO] Validation passed for /home/emilio/Documents/ai/pizza/scripts/label_tool.py
[2025-05-14 03:31:56,859] [INFO] Validating script: framebuffer_demo.py
[2025-05-14 03:31:56,948] [WARNING] Execution test issue in /home/emilio/Documents/ai/pizza/scripts/framebuffer_demo.py: Execution failed with error: 
[2025-05-14 03:31:56,949] [WARNING] Validation passed with warnings for /home/emilio/Documents/ai/pizza/scripts/framebuffer_demo.py
[2025-05-14 03:31:56,949] [INFO] Validating script: compare_inverted_residual.py
[2025-05-14 03:32:00,640] [INFO] Validation passed for /home/emilio/Documents/ai/pizza/scripts/compare_inverted_residual.py
[2025-05-14 03:32:00,640] [INFO] Validating script: test_temporal_smoothing.py
[2025-05-14 03:32:00,941] [INFO] Validation passed for /home/emilio/Documents/ai/pizza/scripts/test_temporal_smoothing.py
[2025-05-14 03:32:00,941] [INFO] Validating script: knowledge_distillation.py
[2025-05-14 03:32:02,916] [INFO] Validation passed for /home/emilio/Documents/ai/pizza/scripts/knowledge_distillation.py
[2025-05-14 03:32:02,916] [INFO] Validating script: visualize_gradcam.py
[2025-05-14 03:32:03,527] [WARNING] Missing dependencies in /home/emilio/Documents/ai/pizza/scripts/visualize_gradcam.py: scripts
[2025-05-14 03:32:06,024] [WARNING] Validation passed with warnings for /home/emilio/Documents/ai/pizza/scripts/visualize_gradcam.py
[2025-05-14 03:32:06,024] [INFO] Validating script: classify_images.py
[2025-05-14 03:32:06,032] [WARNING] Missing or incomplete docstring in /home/emilio/Documents/ai/pizza/scripts/classify_images.py
[2025-05-14 03:32:06,032] [WARNING] Validation passed with warnings for /home/emilio/Documents/ai/pizza/scripts/classify_images.py
[2025-05-14 03:32:06,032] [INFO] Validating script: visualize_pruning.py
[2025-05-14 03:32:08,518] [INFO] Validation passed for /home/emilio/Documents/ai/pizza/scripts/visualize_pruning.py
[2025-05-14 03:32:08,518] [INFO] Validating script: compare_tiny_cnns.py
[2025-05-14 03:32:08,547] [WARNING] Missing dependencies in /home/emilio/Documents/ai/pizza/scripts/compare_tiny_cnns.py: scripts
[2025-05-14 03:32:11,049] [WARNING] Validation passed with warnings for /home/emilio/Documents/ai/pizza/scripts/compare_tiny_cnns.py
[2025-05-14 03:32:11,049] [INFO] Validating script: compare_se_models.py
[2025-05-14 03:32:13,653] [INFO] Validation passed for /home/emilio/Documents/ai/pizza/scripts/compare_se_models.py
[2025-05-14 03:32:13,653] [INFO] Validating script: automated_test_suite.py
[2025-05-14 03:32:16,179] [WARNING] Execution test issue in /home/emilio/Documents/ai/pizza/scripts/automated_test_suite.py: Execution failed with error: Traceback (most recent call last):
  File "/home/emilio/Documents/ai/pizza/scripts/automated_test_suite.py", line 53, in <module>
    from src.pizza_detector import (
ImportError: cannot import name 'load_model' from 'src.pizza_detector' (/home/emilio/Documents/ai/pizza/src/pizza_detector.py)

[2025-05-14 03:32:16,183] [WARNING] Validation passed with warnings for /home/emilio/Documents/ai/pizza/scripts/automated_test_suite.py
[2025-05-14 03:32:16,183] [INFO] Validating script: compare_hard_swish.py
[2025-05-14 03:32:18,727] [INFO] Validation passed for /home/emilio/Documents/ai/pizza/scripts/compare_hard_swish.py
[2025-05-14 03:32:18,727] [INFO] Validating script: demo_status_display.py
[2025-05-14 03:32:18,755] [WARNING] Execution test issue in /home/emilio/Documents/ai/pizza/scripts/demo_status_display.py: Execution failed with error: Traceback (most recent call last):
  File "/home/emilio/Documents/ai/pizza/scripts/demo_status_display.py", line 38, in <module>
    from src.status_display import (
ModuleNotFoundError: No module named 'src.status_display'

[2025-05-14 03:32:18,756] [WARNING] Validation passed with warnings for /home/emilio/Documents/ai/pizza/scripts/demo_status_display.py
[2025-05-14 03:32:18,756] [INFO] Validating script: test_image_preprocessing.py
[2025-05-14 03:32:19,085] [INFO] Validation passed for /home/emilio/Documents/ai/pizza/scripts/test_image_preprocessing.py
[2025-05-14 03:32:19,085] [INFO] Validating script: test_pizza_detection.py
[2025-05-14 03:32:21,088] [WARNING] Execution test issue in /home/emilio/Documents/ai/pizza/scripts/test_pizza_detection.py: Execution failed with error: Traceback (most recent call last):
  File "/home/emilio/Documents/ai/pizza/scripts/test_pizza_detection.py", line 27, in <module>
    from src.types import InferenceResult
ModuleNotFoundError: No module named 'src.types'

[2025-05-14 03:32:21,090] [WARNING] Validation passed with warnings for /home/emilio/Documents/ai/pizza/scripts/test_pizza_detection.py
[2025-05-14 03:32:21,090] [INFO] Validating script: demo_power_management.py
[2025-05-14 03:32:21,395] [WARNING] Execution test issue in /home/emilio/Documents/ai/pizza/scripts/demo_power_management.py: Execution failed with error: Traceback (most recent call last):
  File "/home/emilio/Documents/ai/pizza/scripts/demo_power_management.py", line 19, in <module>
    from src.emulator import RP2040Emulator
ModuleNotFoundError: No module named 'src.emulator'

[2025-05-14 03:32:21,397] [WARNING] Validation passed with warnings for /home/emilio/Documents/ai/pizza/scripts/demo_power_management.py
[2025-05-14 03:32:21,397] [INFO] Validating script: analyze_performance_logs.py
[2025-05-14 03:32:22,153] [INFO] Validation passed for /home/emilio/Documents/ai/pizza/scripts/analyze_performance_logs.py
[2025-05-14 03:32:22,153] [INFO] Validating script: simulate_memory_constraints.py
[2025-05-14 03:32:22,469] [WARNING] Execution test issue in /home/emilio/Documents/ai/pizza/scripts/simulate_memory_constraints.py: Execution failed with error: Traceback (most recent call last):
  File "/home/emilio/Documents/ai/pizza/scripts/simulate_memory_constraints.py", line 17, in <module>
    from src.constants import (
ImportError: cannot import name 'RP2040_CLOCK_SPEED_MHZ' from 'src.constants' (/home/emilio/Documents/ai/pizza/src/constants.py). Did you mean: 'RP2040_CLOCK_SPEED'?

[2025-05-14 03:32:22,471] [WARNING] Validation passed with warnings for /home/emilio/Documents/ai/pizza/scripts/simulate_memory_constraints.py
[2025-05-14 03:32:22,471] [INFO] Validating script: simulate_clahe_resources.py
[2025-05-14 03:32:22,798] [INFO] Validation passed for /home/emilio/Documents/ai/pizza/scripts/simulate_clahe_resources.py
[2025-05-14 03:32:22,798] [INFO] Validating script: run_pizza_tests.py
[2025-05-14 03:32:22,824] [INFO] Validation passed for /home/emilio/Documents/ai/pizza/scripts/run_pizza_tests.py
[2025-05-14 03:32:22,824] [INFO] Validating script: run_pruning_clustering.py
[2025-05-14 03:32:22,826] [WARNING] Missing dependencies in /home/emilio/Documents/ai/pizza/scripts/run_pruning_clustering.py: scripts, config
[2025-05-14 03:32:24,831] [WARNING] Validation passed with warnings for /home/emilio/Documents/ai/pizza/scripts/run_pruning_clustering.py
[2025-05-14 03:32:24,831] [INFO] Validating script: augment_dataset.py
[2025-05-14 03:32:24,935] [INFO] Validation passed for /home/emilio/Documents/ai/pizza/scripts/augment_dataset.py
[2025-05-14 03:32:24,935] [INFO] Validating script: train_pizza_model.py
[2025-05-14 03:32:26,998] [INFO] Validation passed for /home/emilio/Documents/ai/pizza/scripts/train_pizza_model.py
[2025-05-14 03:32:26,998] [INFO] Validating script: simulate_lighting_conditions.py
[2025-05-14 03:32:27,312] [WARNING] Execution test issue in /home/emilio/Documents/ai/pizza/scripts/simulate_lighting_conditions.py: Execution failed with error: Traceback (most recent call last):
  File "/home/emilio/Documents/ai/pizza/scripts/simulate_lighting_conditions.py", line 17, in <module>
    from src.emulator import RP2040Emulator
ModuleNotFoundError: No module named 'src.emulator'

[2025-05-14 03:32:27,313] [WARNING] Validation passed with warnings for /home/emilio/Documents/ai/pizza/scripts/simulate_lighting_conditions.py
[2025-05-14 03:32:27,313] [INFO] Validating script: quantization_aware_training.py
[2025-05-14 03:32:29,329] [INFO] Validation passed for /home/emilio/Documents/ai/pizza/scripts/quantization_aware_training.py
[2025-05-14 03:32:29,329] [INFO] Validating script: simulate_power_consumption.py
[2025-05-14 03:32:29,650] [WARNING] Execution test issue in /home/emilio/Documents/ai/pizza/scripts/simulate_power_consumption.py: Execution failed with error: Traceback (most recent call last):
  File "/home/emilio/Documents/ai/pizza/scripts/simulate_power_consumption.py", line 18, in <module>
    from src.constants import (
ImportError: cannot import name 'RP2040_CLOCK_SPEED_MHZ' from 'src.constants' (/home/emilio/Documents/ai/pizza/src/constants.py). Did you mean: 'RP2040_CLOCK_SPEED'?

[2025-05-14 03:32:29,651] [WARNING] Validation passed with warnings for /home/emilio/Documents/ai/pizza/scripts/simulate_power_consumption.py
[2025-05-14 03:32:29,651] [INFO] Validating script: generate_pizza_dataset.py
[2025-05-14 03:32:34,297] [INFO] Validation passed for /home/emilio/Documents/ai/pizza/scripts/generate_pizza_dataset.py
[2025-05-14 03:32:34,297] [INFO] Validating script: hyperparameter_search.py
[2025-05-14 03:32:37,023] [INFO] Validation passed for /home/emilio/Documents/ai/pizza/scripts/hyperparameter_search.py
[2025-05-14 03:32:37,023] [INFO] Validating script: extract_frames.py
[2025-05-14 03:32:37,052] [WARNING] Missing or incomplete docstring in /home/emilio/Documents/ai/pizza/scripts/extract_frames.py
[2025-05-14 03:32:37,053] [WARNING] Validation passed with warnings for /home/emilio/Documents/ai/pizza/scripts/extract_frames.py
[2025-05-14 03:32:37,053] [INFO] Validating script: validate_integration.py
[2025-05-14 03:32:37,113] [INFO] Validation passed for /home/emilio/Documents/ai/pizza/scripts/ci/validate_integration.py
[2025-05-14 03:32:37,113] [INFO] Validating script: validate_scripts.py
[2025-05-14 03:32:37,197] [INFO] Validation passed for /home/emilio/Documents/ai/pizza/scripts/ci/validate_scripts.py
[2025-05-14 03:32:37,197] [INFO] Validating script: generate_pipeline_report.py
[2025-05-14 03:32:37,534] [INFO] Validation passed for /home/emilio/Documents/ai/pizza/scripts/ci/generate_pipeline_report.py
[2025-05-14 03:32:37,534] [INFO] Validating script: generate_optimization_summary.py
[2025-05-14 03:32:37,830] [INFO] Validation passed for /home/emilio/Documents/ai/pizza/scripts/ci/generate_optimization_summary.py
[2025-05-14 03:32:37,830] [INFO] Validating script: weight_pruning.py
[2025-05-14 03:32:37,839] [WARNING] Missing dependencies in /home/emilio/Documents/ai/pizza/scripts/model_optimization/weight_pruning.py: config
[2025-05-14 03:32:39,832] [WARNING] Validation passed with warnings for /home/emilio/Documents/ai/pizza/scripts/model_optimization/weight_pruning.py
[2025-05-14 03:32:39,832] [INFO] Validating script: micropizzanet_early_exit.py
[2025-05-14 03:32:41,934] [INFO] Validation passed for /home/emilio/Documents/ai/pizza/scripts/early_exit/micropizzanet_early_exit.py
[2025-05-14 03:32:41,934] [INFO] Validating script: verify_model.py
[2025-05-14 03:32:43,795] [WARNING] Missing or incomplete docstring in /home/emilio/Documents/ai/pizza/models/rp2040_export/verify_model.py
[2025-05-14 03:32:43,796] [WARNING] Validation passed with warnings for /home/emilio/Documents/ai/pizza/models/rp2040_export/verify_model.py
[2025-05-14 03:32:43,796] [INFO] Validating script: pizza-baking-detection-final.py
[2025-05-14 03:32:44,937] [WARNING] Missing dependencies in /home/emilio/Documents/ai/pizza/src/pizza-baking-detection-final.py: onnx_tf
[2025-05-14 03:32:49,428] [WARNING] Missing or incomplete docstring in /home/emilio/Documents/ai/pizza/src/pizza-baking-detection-final.py
[2025-05-14 03:32:49,428] [WARNING] Validation passed with warnings for /home/emilio/Documents/ai/pizza/src/pizza-baking-detection-final.py
[2025-05-14 03:32:49,428] [INFO] Validating script: metrics.py
[2025-05-14 03:32:50,591] [INFO] Validation passed for /home/emilio/Documents/ai/pizza/src/metrics.py
[2025-05-14 03:32:50,591] [INFO] Validating script: __init__.py
[2025-05-14 03:32:50,601] [WARNING] Missing or incomplete docstring in /home/emilio/Documents/ai/pizza/src/__init__.py
[2025-05-14 03:32:50,601] [WARNING] Validation passed with warnings for /home/emilio/Documents/ai/pizza/src/__init__.py
[2025-05-14 03:32:50,601] [INFO] Validating script: pizza_detector.py
[2025-05-14 03:32:50,627] [WARNING] Missing dependencies in /home/emilio/Documents/ai/pizza/src/pizza_detector.py: onnx_tf
[2025-05-14 03:32:55,170] [WARNING] Missing or incomplete docstring in /home/emilio/Documents/ai/pizza/src/pizza_detector.py
[2025-05-14 03:32:55,170] [WARNING] Validation passed with warnings for /home/emilio/Documents/ai/pizza/src/pizza_detector.py
[2025-05-14 03:32:55,170] [INFO] Validating script: constants.py
[2025-05-14 03:32:55,193] [INFO] Validation passed for /home/emilio/Documents/ai/pizza/src/constants.py
[2025-05-14 03:32:55,193] [INFO] Validating script: test_frame_buffer.py
[2025-05-14 03:32:55,196] [WARNING] Missing dependencies in /home/emilio/Documents/ai/pizza/src/emulation/test_frame_buffer.py: frame_buffer
[2025-05-14 03:32:55,275] [WARNING] Validation passed with warnings for /home/emilio/Documents/ai/pizza/src/emulation/test_frame_buffer.py
[2025-05-14 03:32:55,275] [INFO] Validating script: emulator-test.py
[2025-05-14 03:32:55,401] [WARNING] Missing or incomplete docstring in /home/emilio/Documents/ai/pizza/src/emulation/emulator-test.py
[2025-05-14 03:32:55,401] [WARNING] Validation passed with warnings for /home/emilio/Documents/ai/pizza/src/emulation/emulator-test.py
[2025-05-14 03:32:55,401] [INFO] Validating script: emulator.py
[2025-05-14 03:32:55,406] [WARNING] Missing dependencies in /home/emilio/Documents/ai/pizza/src/emulation/emulator.py: power_manager, constants, exceptions, frame_buffer
[2025-05-14 03:32:55,494] [WARNING] Execution test issue in /home/emilio/Documents/ai/pizza/src/emulation/emulator.py: Execution failed with error: Traceback (most recent call last):
  File "/home/emilio/Documents/ai/pizza/src/emulation/emulator.py", line 12, in <module>
    from .constants import (
ImportError: attempted relative import with no known parent package

[2025-05-14 03:32:55,496] [WARNING] Validation passed with warnings for /home/emilio/Documents/ai/pizza/src/emulation/emulator.py
[2025-05-14 03:32:55,496] [INFO] Validating script: frame_buffer.py
[2025-05-14 03:32:55,595] [INFO] Validation passed for /home/emilio/Documents/ai/pizza/src/emulation/frame_buffer.py
[2025-05-14 03:32:55,596] [INFO] Validating script: metrics.py
[2025-05-14 03:32:55,601] [WARNING] Missing dependencies in /home/emilio/Documents/ai/pizza/src/analysis/metrics.py: constants, exceptions
[2025-05-14 03:32:57,089] [WARNING] Execution test issue in /home/emilio/Documents/ai/pizza/src/analysis/metrics.py: Execution failed with error: Traceback (most recent call last):
  File "/home/emilio/Documents/ai/pizza/src/analysis/metrics.py", line 16, in <module>
    from .types import (
ImportError: attempted relative import with no known parent package

[2025-05-14 03:32:57,091] [WARNING] Validation passed with warnings for /home/emilio/Documents/ai/pizza/src/analysis/metrics.py
[2025-05-14 03:32:57,091] [INFO] Validating script: models.py
[2025-05-14 03:32:57,340] [WARNING] Missing or incomplete docstring in /home/emilio/Documents/ai/pizza/src/chatlist_ki/models.py
[2025-05-14 03:32:57,340] [WARNING] Validation passed with warnings for /home/emilio/Documents/ai/pizza/src/chatlist_ki/models.py
[2025-05-14 03:32:57,340] [INFO] Validating script: __main__.py
[2025-05-14 03:32:57,341] [WARNING] Missing dependencies in /home/emilio/Documents/ai/pizza/src/chatlist_ki/__main__.py: chat_interface, models, database
[2025-05-14 03:32:57,351] [WARNING] Execution test issue in /home/emilio/Documents/ai/pizza/src/chatlist_ki/__main__.py: Execution failed with error: Traceback (most recent call last):
  File "/home/emilio/Documents/ai/pizza/src/chatlist_ki/__main__.py", line 1, in <module>
    from .chat_interface import ChatInterface
ImportError: attempted relative import with no known parent package

[2025-05-14 03:32:57,352] [WARNING] Missing or incomplete docstring in /home/emilio/Documents/ai/pizza/src/chatlist_ki/__main__.py
[2025-05-14 03:32:57,352] [WARNING] Validation passed with warnings for /home/emilio/Documents/ai/pizza/src/chatlist_ki/__main__.py
[2025-05-14 03:32:57,352] [INFO] Validating script: __init__.py
[2025-05-14 03:32:57,352] [WARNING] Missing dependencies in /home/emilio/Documents/ai/pizza/src/chatlist_ki/__init__.py: chat_interface, models, database
[2025-05-14 03:32:57,365] [WARNING] Execution test issue in /home/emilio/Documents/ai/pizza/src/chatlist_ki/__init__.py: Execution failed with error: Traceback (most recent call last):
  File "/home/emilio/Documents/ai/pizza/src/chatlist_ki/__init__.py", line 1, in <module>
    from .models import Task, TaskStatus
ImportError: attempted relative import with no known parent package

[2025-05-14 03:32:57,365] [WARNING] Missing or incomplete docstring in /home/emilio/Documents/ai/pizza/src/chatlist_ki/__init__.py
[2025-05-14 03:32:57,365] [WARNING] Validation passed with warnings for /home/emilio/Documents/ai/pizza/src/chatlist_ki/__init__.py
[2025-05-14 03:32:57,365] [INFO] Validating script: api.py
[2025-05-14 03:32:57,490] [WARNING] Missing dependencies in /home/emilio/Documents/ai/pizza/src/chatlist_ki/api.py: models, database
[2025-05-14 03:32:57,709] [WARNING] Execution test issue in /home/emilio/Documents/ai/pizza/src/chatlist_ki/api.py: Execution failed with error: Traceback (most recent call last):
  File "/home/emilio/Documents/ai/pizza/src/chatlist_ki/api.py", line 5, in <module>
    from .database import Database, TaskManager
ImportError: attempted relative import with no known parent package

[2025-05-14 03:32:57,710] [WARNING] Missing or incomplete docstring in /home/emilio/Documents/ai/pizza/src/chatlist_ki/api.py
[2025-05-14 03:32:57,710] [WARNING] Validation passed with warnings for /home/emilio/Documents/ai/pizza/src/chatlist_ki/api.py
[2025-05-14 03:32:57,710] [INFO] Validating script: database.py
[2025-05-14 03:32:57,714] [WARNING] Missing dependencies in /home/emilio/Documents/ai/pizza/src/chatlist_ki/database.py: models
[2025-05-14 03:32:57,898] [WARNING] Execution test issue in /home/emilio/Documents/ai/pizza/src/chatlist_ki/database.py: Execution failed with error: Traceback (most recent call last):
  File "/home/emilio/Documents/ai/pizza/src/chatlist_ki/database.py", line 4, in <module>
    from .models import Base, Task, TaskStatus
ImportError: attempted relative import with no known parent package

[2025-05-14 03:32:57,899] [WARNING] Missing or incomplete docstring in /home/emilio/Documents/ai/pizza/src/chatlist_ki/database.py
[2025-05-14 03:32:57,899] [WARNING] Validation passed with warnings for /home/emilio/Documents/ai/pizza/src/chatlist_ki/database.py
[2025-05-14 03:32:57,899] [INFO] Validating script: chat_interface.py
[2025-05-14 03:32:57,901] [WARNING] Missing dependencies in /home/emilio/Documents/ai/pizza/src/chatlist_ki/chat_interface.py: models, database
[2025-05-14 03:32:57,919] [WARNING] Execution test issue in /home/emilio/Documents/ai/pizza/src/chatlist_ki/chat_interface.py: Execution failed with error: Traceback (most recent call last):
  File "/home/emilio/Documents/ai/pizza/src/chatlist_ki/chat_interface.py", line 2, in <module>
    from .database import TaskManager, Database
ImportError: attempted relative import with no known parent package

[2025-05-14 03:32:57,920] [WARNING] Missing or incomplete docstring in /home/emilio/Documents/ai/pizza/src/chatlist_ki/chat_interface.py
[2025-05-14 03:32:57,920] [WARNING] Validation passed with warnings for /home/emilio/Documents/ai/pizza/src/chatlist_ki/chat_interface.py
[2025-05-14 03:32:57,920] [INFO] Validating script: status_display.py
[2025-05-14 03:32:57,928] [WARNING] Missing dependencies in /home/emilio/Documents/ai/pizza/src/visualization/status_display.py: machine, ssd1306
[2025-05-14 03:32:57,956] [WARNING] Execution test issue in /home/emilio/Documents/ai/pizza/src/visualization/status_display.py: Execution failed with error: Traceback (most recent call last):
  File "/home/emilio/Documents/ai/pizza/src/visualization/status_display.py", line 22, in <module>
    from src.types import InferenceResult
ModuleNotFoundError: No module named 'src'

[2025-05-14 03:32:57,958] [WARNING] Validation passed with warnings for /home/emilio/Documents/ai/pizza/src/visualization/status_display.py
[2025-05-14 03:32:57,958] [INFO] Validating script: visualization.py
[2025-05-14 03:32:57,969] [WARNING] Missing dependencies in /home/emilio/Documents/ai/pizza/src/visualization/visualization.py: constants
[2025-05-14 03:32:59,737] [WARNING] Execution test issue in /home/emilio/Documents/ai/pizza/src/visualization/visualization.py: Execution failed with error: Traceback (most recent call last):
  File "/home/emilio/Documents/ai/pizza/src/visualization/visualization.py", line 15, in <module>
    from .types import (
ImportError: attempted relative import with no known parent package

[2025-05-14 03:32:59,738] [WARNING] Validation passed with warnings for /home/emilio/Documents/ai/pizza/src/visualization/visualization.py
[2025-05-14 03:32:59,738] [INFO] Validating script: exceptions.py
[2025-05-14 03:32:59,751] [INFO] Validation passed for /home/emilio/Documents/ai/pizza/src/utils/exceptions.py
[2025-05-14 03:32:59,751] [INFO] Validating script: types.py
[2025-05-14 03:32:59,766] [WARNING] Execution test issue in /home/emilio/Documents/ai/pizza/src/utils/types.py: Execution failed with error: Traceback (most recent call last):
  File "/home/emilio/Documents/ai/pizza/src/utils/types.py", line 5, in <module>
    from typing import Dict, List, Tuple, Optional, Union, NamedTuple, Callable
  File "/usr/lib/python3.12/typing.py", line 27, in <module>
    import contextlib
  File "/usr/lib/python3.12/contextlib.py", line 7, in <module>
    from functools import wraps
  File "/usr/lib/python3.12/functools.py", line 22, in <module>
    from types import GenericAlias
  File "/home/emilio/Documents/ai/pizza/src/utils/types.py", line 5, in <module>
    from typing import Dict, List, Tuple, Optional, Union, NamedTuple, Callable
ImportError: cannot import name 'Dict' from partially initialized module 'typing' (most likely due to a circular import) (/usr/lib/python3.12/typing.py)

[2025-05-14 03:32:59,767] [WARNING] Validation passed with warnings for /home/emilio/Documents/ai/pizza/src/utils/types.py
[2025-05-14 03:32:59,767] [INFO] Validating script: power_manager.py
[2025-05-14 03:32:59,771] [WARNING] Missing dependencies in /home/emilio/Documents/ai/pizza/src/utils/power_manager.py: metrics, devices, constants
[2025-05-14 03:32:59,793] [WARNING] Execution test issue in /home/emilio/Documents/ai/pizza/src/utils/power_manager.py: Execution failed with error: Traceback (most recent call last):
  File "/home/emilio/Documents/ai/pizza/src/utils/power_manager.py", line 7, in <module>
    import logging
  File "/usr/lib/python3.12/logging/__init__.py", line 26, in <module>
    import sys, os, time, io, re, traceback, warnings, weakref, collections.abc
  File "/usr/lib/python3.12/re/__init__.py", line 124, in <module>
    import enum
  File "/usr/lib/python3.12/enum.py", line 3, in <module>
    from types import MappingProxyType, DynamicClassAttribute
  File "/home/emilio/Documents/ai/pizza/src/utils/types.py", line 5, in <module>
    from typing import Dict, List, Tuple, Optional, Union, NamedTuple, Callable
  File "/usr/lib/python3.12/typing.py", line 27, in <module>
    import contextlib
  File "/usr/lib/python3.12/contextlib.py", line 7, in <module>
    from functools import wraps
  File "/usr/lib/python3.12/functools.py", line 22, in <module>
    from types import GenericAlias
ImportError: cannot import name 'GenericAlias' from partially initialized module 'types' (most likely due to a circular import) (/home/emilio/Documents/ai/pizza/src/utils/types.py)

[2025-05-14 03:32:59,795] [WARNING] Validation passed with warnings for /home/emilio/Documents/ai/pizza/src/utils/power_manager.py
[2025-05-14 03:32:59,795] [INFO] Validating script: devices.py
[2025-05-14 03:32:59,797] [WARNING] Missing dependencies in /home/emilio/Documents/ai/pizza/src/utils/devices.py: exceptions, constants
[2025-05-14 03:32:59,812] [WARNING] Execution test issue in /home/emilio/Documents/ai/pizza/src/utils/devices.py: Execution failed with error: Traceback (most recent call last):
  File "/home/emilio/Documents/ai/pizza/src/utils/devices.py", line 6, in <module>
    import logging
  File "/usr/lib/python3.12/logging/__init__.py", line 26, in <module>
    import sys, os, time, io, re, traceback, warnings, weakref, collections.abc
  File "/usr/lib/python3.12/re/__init__.py", line 124, in <module>
    import enum
  File "/usr/lib/python3.12/enum.py", line 3, in <module>
    from types import MappingProxyType, DynamicClassAttribute
  File "/home/emilio/Documents/ai/pizza/src/utils/types.py", line 5, in <module>
    from typing import Dict, List, Tuple, Optional, Union, NamedTuple, Callable
  File "/usr/lib/python3.12/typing.py", line 27, in <module>
    import contextlib
  File "/usr/lib/python3.12/contextlib.py", line 7, in <module>
    from functools import wraps
  File "/usr/lib/python3.12/functools.py", line 22, in <module>
    from types import GenericAlias
ImportError: cannot import name 'GenericAlias' from partially initialized module 'types' (most likely due to a circular import) (/home/emilio/Documents/ai/pizza/src/utils/types.py)

[2025-05-14 03:32:59,813] [WARNING] Validation passed with warnings for /home/emilio/Documents/ai/pizza/src/utils/devices.py
[2025-05-14 03:32:59,813] [INFO] Validating script: validation.py
[2025-05-14 03:32:59,816] [WARNING] Missing dependencies in /home/emilio/Documents/ai/pizza/src/utils/validation.py: exceptions, constants
[2025-05-14 03:32:59,830] [WARNING] Execution test issue in /home/emilio/Documents/ai/pizza/src/utils/validation.py: Execution failed with error: Traceback (most recent call last):
  File "/home/emilio/Documents/ai/pizza/src/utils/validation.py", line 6, in <module>
    import json
  File "/usr/lib/python3.12/json/__init__.py", line 106, in <module>
    from .decoder import JSONDecoder, JSONDecodeError
  File "/usr/lib/python3.12/json/decoder.py", line 3, in <module>
    import re
  File "/usr/lib/python3.12/re/__init__.py", line 124, in <module>
    import enum
  File "/usr/lib/python3.12/enum.py", line 3, in <module>
    from types import MappingProxyType, DynamicClassAttribute
  File "/home/emilio/Documents/ai/pizza/src/utils/types.py", line 5, in <module>
    from typing import Dict, List, Tuple, Optional, Union, NamedTuple, Callable
  File "/usr/lib/python3.12/typing.py", line 27, in <module>
    import contextlib
  File "/usr/lib/python3.12/contextlib.py", line 7, in <module>
    from functools import wraps
  File "/usr/lib/python3.12/functools.py", line 22, in <module>
    from types import GenericAlias
ImportError: cannot import name 'GenericAlias' from partially initialized module 'types' (most likely due to a circular import) (/home/emilio/Documents/ai/pizza/src/utils/types.py)

[2025-05-14 03:32:59,831] [WARNING] Validation passed with warnings for /home/emilio/Documents/ai/pizza/src/utils/validation.py
[2025-05-14 03:32:59,832] [INFO] Validating script: memory.py
[2025-05-14 03:32:59,833] [WARNING] Missing dependencies in /home/emilio/Documents/ai/pizza/src/utils/memory.py: exceptions, constants
[2025-05-14 03:32:59,857] [WARNING] Execution test issue in /home/emilio/Documents/ai/pizza/src/utils/memory.py: Execution failed with error: Traceback (most recent call last):
  File "/home/emilio/Documents/ai/pizza/src/utils/memory.py", line 5, in <module>
    import torch
  File "/home/emilio/Documents/ai/pizza/.venv/lib/python3.12/site-packages/torch/__init__.py", line 14, in <module>
    import ctypes
  File "/usr/lib/python3.12/ctypes/__init__.py", line 4, in <module>
    import types as _types
  File "/home/emilio/Documents/ai/pizza/src/utils/types.py", line 5, in <module>
    from typing import Dict, List, Tuple, Optional, Union, NamedTuple, Callable
  File "/usr/lib/python3.12/typing.py", line 27, in <module>
    import contextlib
  File "/usr/lib/python3.12/contextlib.py", line 7, in <module>
    from functools import wraps
  File "/usr/lib/python3.12/functools.py", line 22, in <module>
    from types import GenericAlias
ImportError: cannot import name 'GenericAlias' from partially initialized module 'types' (most likely due to a circular import) (/home/emilio/Documents/ai/pizza/src/utils/types.py)

[2025-05-14 03:32:59,858] [WARNING] Validation passed with warnings for /home/emilio/Documents/ai/pizza/src/utils/memory.py
[2025-05-14 03:32:59,858] [INFO] Validating script: temporal_smoother.py
[2025-05-14 03:32:59,884] [WARNING] Execution test issue in /home/emilio/Documents/ai/pizza/src/utils/temporal_smoother.py: Execution failed with error: Traceback (most recent call last):
  File "/home/emilio/Documents/ai/pizza/src/utils/temporal_smoother.py", line 9, in <module>
    import numpy as np
  File "/home/emilio/Documents/ai/pizza/.venv/lib/python3.12/site-packages/numpy/__init__.py", line 92, in <module>
    from ._globals import _NoValue, _CopyMode
  File "/home/emilio/Documents/ai/pizza/.venv/lib/python3.12/site-packages/numpy/_globals.py", line 18, in <module>
    import enum
  File "/usr/lib/python3.12/enum.py", line 3, in <module>
    from types import MappingProxyType, DynamicClassAttribute
  File "/home/emilio/Documents/ai/pizza/src/utils/types.py", line 5, in <module>
    from typing import Dict, List, Tuple, Optional, Union, NamedTuple, Callable
  File "/usr/lib/python3.12/typing.py", line 27, in <module>
    import contextlib
  File "/usr/lib/python3.12/contextlib.py", line 7, in <module>
    from functools import wraps
  File "/usr/lib/python3.12/functools.py", line 22, in <module>
    from types import GenericAlias
ImportError: cannot import name 'GenericAlias' from partially initialized module 'types' (most likely due to a circular import) (/home/emilio/Documents/ai/pizza/src/utils/types.py)

[2025-05-14 03:32:59,886] [WARNING] Validation passed with warnings for /home/emilio/Documents/ai/pizza/src/utils/temporal_smoother.py
[2025-05-14 03:32:59,886] [INFO] Validating script: utils.py
[2025-05-14 03:32:59,901] [WARNING] Execution test issue in /home/emilio/Documents/ai/pizza/src/utils/utils.py: Execution failed with error: Traceback (most recent call last):
  File "/home/emilio/Documents/ai/pizza/src/utils/utils.py", line 6, in <module>
    import logging
  File "/usr/lib/python3.12/logging/__init__.py", line 26, in <module>
    import sys, os, time, io, re, traceback, warnings, weakref, collections.abc
  File "/usr/lib/python3.12/re/__init__.py", line 124, in <module>
    import enum
  File "/usr/lib/python3.12/enum.py", line 3, in <module>
    from types import MappingProxyType, DynamicClassAttribute
  File "/home/emilio/Documents/ai/pizza/src/utils/types.py", line 5, in <module>
    from typing import Dict, List, Tuple, Optional, Union, NamedTuple, Callable
  File "/usr/lib/python3.12/typing.py", line 27, in <module>
    import contextlib
  File "/usr/lib/python3.12/contextlib.py", line 7, in <module>
    from functools import wraps
  File "/usr/lib/python3.12/functools.py", line 22, in <module>
    from types import GenericAlias
ImportError: cannot import name 'GenericAlias' from partially initialized module 'types' (most likely due to a circular import) (/home/emilio/Documents/ai/pizza/src/utils/types.py)

[2025-05-14 03:32:59,902] [WARNING] Validation passed with warnings for /home/emilio/Documents/ai/pizza/src/utils/utils.py
[2025-05-14 03:32:59,902] [INFO] Validating script: constants.py
[2025-05-14 03:32:59,922] [WARNING] Execution test issue in /home/emilio/Documents/ai/pizza/src/utils/constants.py: Execution failed with error: Traceback (most recent call last):
  File "/home/emilio/Documents/ai/pizza/src/utils/constants.py", line 5, in <module>
    from pathlib import Path
  File "/usr/lib/python3.12/pathlib.py", line 8, in <module>
    import fnmatch
  File "/usr/lib/python3.12/fnmatch.py", line 14, in <module>
    import re
  File "/usr/lib/python3.12/re/__init__.py", line 124, in <module>
    import enum
  File "/usr/lib/python3.12/enum.py", line 3, in <module>
    from types import MappingProxyType, DynamicClassAttribute
  File "/home/emilio/Documents/ai/pizza/src/utils/types.py", line 5, in <module>
    from typing import Dict, List, Tuple, Optional, Union, NamedTuple, Callable
  File "/usr/lib/python3.12/typing.py", line 27, in <module>
    import contextlib
  File "/usr/lib/python3.12/contextlib.py", line 7, in <module>
    from functools import wraps
  File "/usr/lib/python3.12/functools.py", line 22, in <module>
    from types import GenericAlias
ImportError: cannot import name 'GenericAlias' from partially initialized module 'types' (most likely due to a circular import) (/home/emilio/Documents/ai/pizza/src/utils/types.py)

[2025-05-14 03:32:59,923] [WARNING] Validation passed with warnings for /home/emilio/Documents/ai/pizza/src/utils/constants.py
[2025-05-14 03:32:59,923] [INFO] Validating script: enhanced_pizza_augmentation.py
[2025-05-14 03:33:02,002] [WARNING] Execution test issue in /home/emilio/Documents/ai/pizza/src/augmentation/enhanced_pizza_augmentation.py: Execution failed with error: 
[2025-05-14 03:33:02,013] [WARNING] Missing or incomplete docstring in /home/emilio/Documents/ai/pizza/src/augmentation/enhanced_pizza_augmentation.py
[2025-05-14 03:33:02,013] [WARNING] Validation passed with warnings for /home/emilio/Documents/ai/pizza/src/augmentation/enhanced_pizza_augmentation.py
[2025-05-14 03:33:02,013] [INFO] Validating script: augmentation_optimized.py
[2025-05-14 03:33:04,198] [WARNING] Execution test issue in /home/emilio/Documents/ai/pizza/src/augmentation/augmentation_optimized.py: Execution failed with error: Traceback (most recent call last):
  File "/home/emilio/Documents/ai/pizza/src/augmentation/augmentation_optimized.py", line 698, in <module>
    main()
  File "/home/emilio/Documents/ai/pizza/src/augmentation/augmentation_optimized.py", line 688, in main
    augment_pizza_dataset(input_dir, output_dir, img_per_original=img_per_original, batch_size=batch_size)
  File "/home/emilio/Documents/ai/pizza/src/augmentation/augmentation_optimized.py", line 512, in augment_pizza_dataset
    image_files = [os.path.join(input_dir, f) for f in os.listdir(input_dir) 
                                                       ^^^^^^^^^^^^^^^^^^^^^
FileNotFoundError: [Errno 2] No such file or directory: '/home/emilio/Documents/ai/pizza/img-pizza/'

[2025-05-14 03:33:04,201] [WARNING] Missing or incomplete docstring in /home/emilio/Documents/ai/pizza/src/augmentation/augmentation_optimized.py
[2025-05-14 03:33:04,201] [WARNING] Validation passed with warnings for /home/emilio/Documents/ai/pizza/src/augmentation/augmentation_optimized.py
[2025-05-14 03:33:04,201] [INFO] Validating script: diffusion_pizza_generator.py
[2025-05-14 03:33:08,559] [INFO] Validation passed for /home/emilio/Documents/ai/pizza/src/augmentation/diffusion_pizza_generator.py
[2025-05-14 03:33:08,559] [INFO] Validating script: augmentation.py
