[2025-05-13 22:17:21,990] [INFO] Found 72 Python scripts to validate
[2025-05-13 22:17:21,990] [INFO] Validating script: cleanup.py
[2025-05-13 22:17:22,036] [INFO] Validation passed for /home/emilio/Documents/ai/pizza/scripts/cleanup.py
[2025-05-13 22:17:22,036] [INFO] Validating script: filter_dataset.py
[2025-05-13 22:17:22,044] [WARNING] Missing or incomplete docstring in /home/emilio/Documents/ai/pizza/scripts/filter_dataset.py
[2025-05-13 22:17:22,045] [WARNING] Validation passed with warnings for /home/emilio/Documents/ai/pizza/scripts/filter_dataset.py
[2025-05-13 22:17:22,045] [INFO] Validating script: label_tool.py
[2025-05-13 22:17:25,887] [INFO] Validation passed for /home/emilio/Documents/ai/pizza/scripts/label_tool.py
[2025-05-13 22:17:25,888] [INFO] Validating script: framebuffer_demo.py
[2025-05-13 22:17:25,893] [WARNING] Missing dependencies in /home/emilio/Documents/ai/pizza/scripts/framebuffer_demo.py: tabulate
[2025-05-13 22:17:25,908] [WARNING] Execution test issue in /home/emilio/Documents/ai/pizza/scripts/framebuffer_demo.py: Execution failed with error: Traceback (most recent call last):
  File "/home/emilio/Documents/ai/pizza/scripts/framebuffer_demo.py", line 11, in <module>
    from tabulate import tabulate
ModuleNotFoundError: No module named 'tabulate'

[2025-05-13 22:17:25,910] [WARNING] Validation passed with warnings for /home/emilio/Documents/ai/pizza/scripts/framebuffer_demo.py
[2025-05-13 22:17:25,910] [INFO] Validating script: compare_inverted_residual.py
[2025-05-13 22:17:30,325] [INFO] Validation passed for /home/emilio/Documents/ai/pizza/scripts/compare_inverted_residual.py
[2025-05-13 22:17:30,325] [INFO] Validating script: test_temporal_smoothing.py
[2025-05-13 22:17:30,675] [INFO] Validation passed for /home/emilio/Documents/ai/pizza/scripts/test_temporal_smoothing.py
[2025-05-13 22:17:30,675] [INFO] Validating script: knowledge_distillation.py
[2025-05-13 22:17:32,811] [INFO] Validation passed for /home/emilio/Documents/ai/pizza/scripts/knowledge_distillation.py
[2025-05-13 22:17:32,811] [INFO] Validating script: visualize_gradcam.py
[2025-05-13 22:17:33,532] [WARNING] Missing dependencies in /home/emilio/Documents/ai/pizza/scripts/visualize_gradcam.py: fpdf, scripts
[2025-05-13 22:17:36,256] [WARNING] Execution test issue in /home/emilio/Documents/ai/pizza/scripts/visualize_gradcam.py: Execution failed with error: Traceback (most recent call last):
  File "/home/emilio/Documents/ai/pizza/scripts/visualize_gradcam.py", line 52, in <module>
    from scripts.compare_tiny_cnns import MCUNet, MobilePizzaNet
  File "/home/emilio/Documents/ai/pizza/scripts/compare_tiny_cnns.py", line 52, in <module>
    from src.metrics import ModelMetrics
ModuleNotFoundError: No module named 'src.metrics'

[2025-05-13 22:17:36,261] [WARNING] Validation passed with warnings for /home/emilio/Documents/ai/pizza/scripts/visualize_gradcam.py
[2025-05-13 22:17:36,261] [INFO] Validating script: classify_images.py
[2025-05-13 22:17:36,274] [WARNING] Missing or incomplete docstring in /home/emilio/Documents/ai/pizza/scripts/classify_images.py
[2025-05-13 22:17:36,274] [WARNING] Validation passed with warnings for /home/emilio/Documents/ai/pizza/scripts/classify_images.py
[2025-05-13 22:17:36,274] [INFO] Validating script: visualize_pruning.py
[2025-05-13 22:17:38,876] [INFO] Validation passed for /home/emilio/Documents/ai/pizza/scripts/visualize_pruning.py
[2025-05-13 22:17:38,876] [INFO] Validating script: compare_tiny_cnns.py
[2025-05-13 22:17:38,986] [WARNING] Missing dependencies in /home/emilio/Documents/ai/pizza/scripts/compare_tiny_cnns.py: scripts
[2025-05-13 22:17:41,652] [WARNING] Execution test issue in /home/emilio/Documents/ai/pizza/scripts/compare_tiny_cnns.py: Execution failed with error: Traceback (most recent call last):
  File "/home/emilio/Documents/ai/pizza/scripts/compare_tiny_cnns.py", line 52, in <module>
    from src.metrics import ModelMetrics
ModuleNotFoundError: No module named 'src.metrics'

[2025-05-13 22:17:41,656] [WARNING] Validation passed with warnings for /home/emilio/Documents/ai/pizza/scripts/compare_tiny_cnns.py
[2025-05-13 22:17:41,656] [INFO] Validating script: compare_se_models.py
[2025-05-13 22:17:44,379] [INFO] Validation passed for /home/emilio/Documents/ai/pizza/scripts/compare_se_models.py
[2025-05-13 22:17:44,379] [INFO] Validating script: automated_test_suite.py
[2025-05-13 22:17:47,011] [WARNING] Execution test issue in /home/emilio/Documents/ai/pizza/scripts/automated_test_suite.py: Execution failed with error: Traceback (most recent call last):
  File "/home/emilio/Documents/ai/pizza/scripts/automated_test_suite.py", line 53, in <module>
    from src.pizza_detector import (
ImportError: cannot import name 'load_model' from 'src.pizza_detector' (/home/emilio/Documents/ai/pizza/src/pizza_detector.py)

[2025-05-13 22:17:47,016] [WARNING] Validation passed with warnings for /home/emilio/Documents/ai/pizza/scripts/automated_test_suite.py
[2025-05-13 22:17:47,017] [INFO] Validating script: compare_hard_swish.py
[2025-05-13 22:17:49,734] [INFO] Validation passed for /home/emilio/Documents/ai/pizza/scripts/compare_hard_swish.py
[2025-05-13 22:17:49,735] [INFO] Validating script: demo_status_display.py
[2025-05-13 22:17:49,762] [WARNING] Execution test issue in /home/emilio/Documents/ai/pizza/scripts/demo_status_display.py: Execution failed with error: Traceback (most recent call last):
  File "/home/emilio/Documents/ai/pizza/scripts/demo_status_display.py", line 38, in <module>
    from src.status_display import (
ModuleNotFoundError: No module named 'src.status_display'

[2025-05-13 22:17:49,764] [WARNING] Validation passed with warnings for /home/emilio/Documents/ai/pizza/scripts/demo_status_display.py
[2025-05-13 22:17:49,764] [INFO] Validating script: test_image_preprocessing.py
[2025-05-13 22:17:50,129] [WARNING] Execution test issue in /home/emilio/Documents/ai/pizza/scripts/test_image_preprocessing.py: Execution failed with error: Traceback (most recent call last):
  File "/home/emilio/Documents/ai/pizza/scripts/test_image_preprocessing.py", line 22, in <module>
    from src.constants import INPUT_SIZE
ModuleNotFoundError: No module named 'src.constants'

[2025-05-13 22:17:50,130] [WARNING] Validation passed with warnings for /home/emilio/Documents/ai/pizza/scripts/test_image_preprocessing.py
[2025-05-13 22:17:50,130] [INFO] Validating script: test_pizza_detection.py
[2025-05-13 22:17:52,211] [WARNING] Execution test issue in /home/emilio/Documents/ai/pizza/scripts/test_pizza_detection.py: Execution failed with error: Traceback (most recent call last):
  File "/home/emilio/Documents/ai/pizza/scripts/test_pizza_detection.py", line 26, in <module>
    from src.constants import INPUT_SIZE, IMAGE_MEAN, IMAGE_STD
ModuleNotFoundError: No module named 'src.constants'

[2025-05-13 22:17:52,213] [WARNING] Validation passed with warnings for /home/emilio/Documents/ai/pizza/scripts/test_pizza_detection.py
[2025-05-13 22:17:52,213] [INFO] Validating script: demo_power_management.py
[2025-05-13 22:17:52,540] [WARNING] Execution test issue in /home/emilio/Documents/ai/pizza/scripts/demo_power_management.py: Execution failed with error: Traceback (most recent call last):
  File "/home/emilio/Documents/ai/pizza/scripts/demo_power_management.py", line 19, in <module>
    from src.emulator import RP2040Emulator
ModuleNotFoundError: No module named 'src.emulator'

[2025-05-13 22:17:52,542] [WARNING] Validation passed with warnings for /home/emilio/Documents/ai/pizza/scripts/demo_power_management.py
[2025-05-13 22:17:52,542] [INFO] Validating script: analyze_performance_logs.py
[2025-05-13 22:17:52,551] [WARNING] Missing dependencies in /home/emilio/Documents/ai/pizza/scripts/analyze_performance_logs.py: serial
[2025-05-13 22:17:53,347] [WARNING] Execution test issue in /home/emilio/Documents/ai/pizza/scripts/analyze_performance_logs.py: Execution failed with error: Traceback (most recent call last):
  File "/home/emilio/Documents/ai/pizza/scripts/analyze_performance_logs.py", line 27, in <module>
    import serial
ModuleNotFoundError: No module named 'serial'

[2025-05-13 22:17:53,351] [WARNING] Validation passed with warnings for /home/emilio/Documents/ai/pizza/scripts/analyze_performance_logs.py
[2025-05-13 22:17:53,351] [INFO] Validating script: simulate_memory_constraints.py
[2025-05-13 22:17:53,691] [WARNING] Execution test issue in /home/emilio/Documents/ai/pizza/scripts/simulate_memory_constraints.py: Execution failed with error: Traceback (most recent call last):
  File "/home/emilio/Documents/ai/pizza/scripts/simulate_memory_constraints.py", line 17, in <module>
    from src.constants import (
ModuleNotFoundError: No module named 'src.constants'

[2025-05-13 22:17:53,694] [WARNING] Validation passed with warnings for /home/emilio/Documents/ai/pizza/scripts/simulate_memory_constraints.py
[2025-05-13 22:17:53,694] [INFO] Validating script: simulate_clahe_resources.py
[2025-05-13 22:17:54,013] [WARNING] Execution test issue in /home/emilio/Documents/ai/pizza/scripts/simulate_clahe_resources.py: Execution failed with error: Traceback (most recent call last):
  File "/home/emilio/Documents/ai/pizza/scripts/simulate_clahe_resources.py", line 22, in <module>
    from src.constants import INPUT_SIZE
ModuleNotFoundError: No module named 'src.constants'

[2025-05-13 22:17:54,015] [WARNING] Validation passed with warnings for /home/emilio/Documents/ai/pizza/scripts/simulate_clahe_resources.py
[2025-05-13 22:17:54,016] [INFO] Validating script: run_pizza_tests.py
[2025-05-13 22:17:54,047] [INFO] Validation passed for /home/emilio/Documents/ai/pizza/scripts/run_pizza_tests.py
[2025-05-13 22:17:54,047] [INFO] Validating script: run_pruning_clustering.py
[2025-05-13 22:17:54,049] [WARNING] Missing dependencies in /home/emilio/Documents/ai/pizza/scripts/run_pruning_clustering.py: config, scripts
[2025-05-13 22:17:56,129] [WARNING] Validation passed with warnings for /home/emilio/Documents/ai/pizza/scripts/run_pruning_clustering.py
[2025-05-13 22:17:56,130] [INFO] Validating script: augment_dataset.py
[2025-05-13 22:17:56,138] [WARNING] Missing or incomplete docstring in /home/emilio/Documents/ai/pizza/scripts/augment_dataset.py
[2025-05-13 22:17:56,138] [WARNING] Validation passed with warnings for /home/emilio/Documents/ai/pizza/scripts/augment_dataset.py
[2025-05-13 22:17:56,138] [INFO] Validating script: train_pizza_model.py
[2025-05-13 22:17:58,207] [WARNING] Execution test issue in /home/emilio/Documents/ai/pizza/scripts/train_pizza_model.py: Execution failed with error: Traceback (most recent call last):
  File "/home/emilio/Documents/ai/pizza/scripts/train_pizza_model.py", line 28, in <module>
    from src.constants import INPUT_SIZE, IMAGE_MEAN, IMAGE_STD
ModuleNotFoundError: No module named 'src.constants'

[2025-05-13 22:17:58,210] [WARNING] Validation passed with warnings for /home/emilio/Documents/ai/pizza/scripts/train_pizza_model.py
[2025-05-13 22:17:58,211] [INFO] Validating script: simulate_lighting_conditions.py
[2025-05-13 22:17:58,530] [WARNING] Execution test issue in /home/emilio/Documents/ai/pizza/scripts/simulate_lighting_conditions.py: Execution failed with error: Traceback (most recent call last):
  File "/home/emilio/Documents/ai/pizza/scripts/simulate_lighting_conditions.py", line 17, in <module>
    from src.emulator import RP2040Emulator
ModuleNotFoundError: No module named 'src.emulator'

[2025-05-13 22:17:58,532] [WARNING] Validation passed with warnings for /home/emilio/Documents/ai/pizza/scripts/simulate_lighting_conditions.py
[2025-05-13 22:17:58,532] [INFO] Validating script: quantization_aware_training.py
[2025-05-13 22:18:00,715] [INFO] Validation passed for /home/emilio/Documents/ai/pizza/scripts/quantization_aware_training.py
[2025-05-13 22:18:00,715] [INFO] Validating script: simulate_power_consumption.py
[2025-05-13 22:18:01,047] [WARNING] Execution test issue in /home/emilio/Documents/ai/pizza/scripts/simulate_power_consumption.py: Execution failed with error: Traceback (most recent call last):
  File "/home/emilio/Documents/ai/pizza/scripts/simulate_power_consumption.py", line 18, in <module>
    from src.constants import (
ModuleNotFoundError: No module named 'src.constants'

[2025-05-13 22:18:01,048] [WARNING] Validation passed with warnings for /home/emilio/Documents/ai/pizza/scripts/simulate_power_consumption.py
[2025-05-13 22:18:01,049] [INFO] Validating script: generate_pizza_dataset.py
[2025-05-13 22:18:03,648] [WARNING] Execution test issue in /home/emilio/Documents/ai/pizza/scripts/generate_pizza_dataset.py: Execution failed with error:   File "/home/emilio/Documents/ai/pizza/scripts/generate_pizza_dataset.py", line 253
    image_size=args.image_size,
    ^^^^^^^^^^^^^^^^^^^^^^^^^^
SyntaxError: keyword argument repeated: image_size

[2025-05-13 22:18:03,650] [WARNING] Validation passed with warnings for /home/emilio/Documents/ai/pizza/scripts/generate_pizza_dataset.py
[2025-05-13 22:18:03,650] [INFO] Validating script: hyperparameter_search.py
[2025-05-13 22:18:06,381] [WARNING] Execution test issue in /home/emilio/Documents/ai/pizza/scripts/hyperparameter_search.py: Execution failed with error: Traceback (most recent call last):
  File "/home/emilio/Documents/ai/pizza/scripts/hyperparameter_search.py", line 45, in <module>
    from src.metrics import ModelMetrics
ModuleNotFoundError: No module named 'src.metrics'

[2025-05-13 22:18:06,385] [WARNING] Validation passed with warnings for /home/emilio/Documents/ai/pizza/scripts/hyperparameter_search.py
[2025-05-13 22:18:06,386] [INFO] Validating script: extract_frames.py
[2025-05-13 22:18:06,395] [WARNING] Missing or incomplete docstring in /home/emilio/Documents/ai/pizza/scripts/extract_frames.py
[2025-05-13 22:18:06,395] [WARNING] Validation passed with warnings for /home/emilio/Documents/ai/pizza/scripts/extract_frames.py
[2025-05-13 22:18:06,396] [INFO] Validating script: validate_integration.py
[2025-05-13 22:18:06,433] [INFO] Validation passed for /home/emilio/Documents/ai/pizza/scripts/ci/validate_integration.py
[2025-05-13 22:18:06,433] [INFO] Validating script: validate_scripts.py
[2025-05-13 22:18:06,532] [INFO] Validation passed for /home/emilio/Documents/ai/pizza/scripts/ci/validate_scripts.py
[2025-05-13 22:18:06,532] [INFO] Validating script: generate_pipeline_report.py
[2025-05-13 22:18:06,541] [WARNING] Missing or incomplete docstring in /home/emilio/Documents/ai/pizza/scripts/ci/generate_pipeline_report.py
[2025-05-13 22:18:06,542] [WARNING] Validation passed with warnings for /home/emilio/Documents/ai/pizza/scripts/ci/generate_pipeline_report.py
[2025-05-13 22:18:06,542] [INFO] Validating script: weight_pruning.py
[2025-05-13 22:18:06,551] [WARNING] Missing dependencies in /home/emilio/Documents/ai/pizza/scripts/model_optimization/weight_pruning.py: config
[2025-05-13 22:18:08,694] [WARNING] Validation passed with warnings for /home/emilio/Documents/ai/pizza/scripts/model_optimization/weight_pruning.py
[2025-05-13 22:18:08,694] [INFO] Validating script: micropizzanet_early_exit.py
[2025-05-13 22:18:10,821] [INFO] Validation passed for /home/emilio/Documents/ai/pizza/scripts/early_exit/micropizzanet_early_exit.py
[2025-05-13 22:18:10,821] [INFO] Validating script: verify_model.py
[2025-05-13 22:18:10,821] [ERROR] Syntax error in /home/emilio/Documents/ai/pizza/models/rp2040_export/verify_model.py: Syntax error at line 52: invalid syntax. Perhaps you forgot a comma?
[2025-05-13 22:18:10,822] [WARNING] Missing or incomplete docstring in /home/emilio/Documents/ai/pizza/models/rp2040_export/verify_model.py
[2025-05-13 22:18:10,822] [WARNING] Validation passed with warnings for /home/emilio/Documents/ai/pizza/models/rp2040_export/verify_model.py
[2025-05-13 22:18:10,822] [INFO] Validating script: pizza-baking-detection-final.py
[2025-05-13 22:18:13,617] [WARNING] Missing dependencies in /home/emilio/Documents/ai/pizza/src/pizza-baking-detection-final.py: onnx_tf
[2025-05-13 22:18:15,732] [WARNING] Execution test issue in /home/emilio/Documents/ai/pizza/src/pizza-baking-detection-final.py: Execution failed with error: 2025-05-13 22:18:15,289 - INFO - ================================================================================
2025-05-13 22:18:15,289 - INFO - RP2040 PIZZA-ERKENNUNGSSYSTEM - DETAILLIERTE KONFIGURATION
2025-05-13 22:18:15,289 - INFO - ================================================================================
2025-05-13 22:18:15,289 - INFO - Hardware: RP2040 - 133MHz, 264KB RAM, 2048KB Flash
2025-05-13 22:18:15,289 - INFO - Kamera: OV2640 - 320x240, 7 FPS
2025-05-13 22:18:15,289 - INFO - Stromversorgung: CR123A - 1500mAh, 8.33h aktiv, 3000.00h standby
2025-05-13 22:18:15,289 - INFO - Modellparameter: 48x48 Eingabegröße, 8-Bit Quantisierung
2025-05-13 22:18:15,289 - INFO - Speicherbeschränkungen: Max. 180KB Modellgröße, 100KB Laufzeit-RAM
2025-05-13 22:18:15,289 - INFO - ================================================================================
2025-05-13 22:18:15,289 - ERROR - Fehler im Optimierungsprozess: [Errno 2] No such file or directory: 'augmented_pizza'
Traceback (most recent call last):
  File "/home/emilio/Documents/ai/pizza/src/pizza-baking-detection-final.py", line 2230, in main
    analyzer = PizzaDatasetAnalysis(config.DATA_DIR)
               ^^^^^^^^^^^^^^^^^^^^^^^^^^^^^^^^^^^^^
  File "/home/emilio/Documents/ai/pizza/src/pizza-baking-detection-final.py", line 107, in __init__
    self.class_dirs = [d for d in os.listdir(data_dir)
                                 ^^^^^^^^^^^^^^^^^^^^
FileNotFoundError: [Errno 2] No such file or directory: 'augmented_pizza'
Traceback (most recent call last):
  File "/home/emilio/Documents/ai/pizza/src/pizza-baking-detection-final.py", line 2302, in <module>
    main()
  File "/home/emilio/Documents/ai/pizza/src/pizza-baking-detection-final.py", line 2230, in main
    analyzer = PizzaDatasetAnalysis(config.DATA_DIR)
               ^^^^^^^^^^^^^^^^^^^^^^^^^^^^^^^^^^^^^
  File "/home/emilio/Documents/ai/pizza/src/pizza-baking-detection-final.py", line 107, in __init__
    self.class_dirs = [d for d in os.listdir(data_dir) 
                                  ^^^^^^^^^^^^^^^^^^^^
FileNotFoundError: [Errno 2] No such file or directory: 'augmented_pizza'

[2025-05-13 22:18:15,742] [WARNING] Missing or incomplete docstring in /home/emilio/Documents/ai/pizza/src/pizza-baking-detection-final.py
[2025-05-13 22:18:15,742] [WARNING] Validation passed with warnings for /home/emilio/Documents/ai/pizza/src/pizza-baking-detection-final.py
[2025-05-13 22:18:15,742] [INFO] Validating script: __init__.py
[2025-05-13 22:18:15,751] [WARNING] Missing or incomplete docstring in /home/emilio/Documents/ai/pizza/src/__init__.py
[2025-05-13 22:18:15,751] [WARNING] Validation passed with warnings for /home/emilio/Documents/ai/pizza/src/__init__.py
[2025-05-13 22:18:15,751] [INFO] Validating script: pizza_detector.py
[2025-05-13 22:18:15,779] [WARNING] Missing dependencies in /home/emilio/Documents/ai/pizza/src/pizza_detector.py: onnx_tf
[2025-05-13 22:18:17,845] [WARNING] Execution test issue in /home/emilio/Documents/ai/pizza/src/pizza_detector.py: Execution failed with error: 2025-05-13 22:18:17,426 - INFO - ================================================================================
2025-05-13 22:18:17,426 - INFO - RP2040 PIZZA-ERKENNUNGSSYSTEM - DETAILLIERTE KONFIGURATION
2025-05-13 22:18:17,426 - INFO - ================================================================================
2025-05-13 22:18:17,426 - INFO - Hardware: RP2040 - 133MHz, 264KB RAM, 2048KB Flash
2025-05-13 22:18:17,426 - INFO - Kamera: OV2640 - 320x240, 7 FPS
2025-05-13 22:18:17,426 - INFO - Stromversorgung: CR123A - 1500mAh, 8.33h aktiv, 3000.00h standby
2025-05-13 22:18:17,426 - INFO - Modellparameter: 48x48 Eingabegröße, 8-Bit Quantisierung
2025-05-13 22:18:17,426 - INFO - Speicherbeschränkungen: Max. 180KB Modellgröße, 100KB Laufzeit-RAM
2025-05-13 22:18:17,426 - INFO - ================================================================================
2025-05-13 22:18:17,426 - ERROR - Fehler im Optimierungsprozess: [Errno 2] No such file or directory: 'augmented_pizza'
Traceback (most recent call last):
  File "/home/emilio/Documents/ai/pizza/src/pizza_detector.py", line 2475, in main
    analyzer = PizzaDatasetAnalysis(config.DATA_DIR)
               ^^^^^^^^^^^^^^^^^^^^^^^^^^^^^^^^^^^^^
  File "/home/emilio/Documents/ai/pizza/src/pizza_detector.py", line 107, in __init__
    self.class_dirs = [d for d in os.listdir(data_dir)
                                 ^^^^^^^^^^^^^^^^^^^^
FileNotFoundError: [Errno 2] No such file or directory: 'augmented_pizza'
Traceback (most recent call last):
  File "/home/emilio/Documents/ai/pizza/src/pizza_detector.py", line 2547, in <module>
    main()
  File "/home/emilio/Documents/ai/pizza/src/pizza_detector.py", line 2475, in main
    analyzer = PizzaDatasetAnalysis(config.DATA_DIR)
               ^^^^^^^^^^^^^^^^^^^^^^^^^^^^^^^^^^^^^
  File "/home/emilio/Documents/ai/pizza/src/pizza_detector.py", line 107, in __init__
    self.class_dirs = [d for d in os.listdir(data_dir) 
                                  ^^^^^^^^^^^^^^^^^^^^
FileNotFoundError: [Errno 2] No such file or directory: 'augmented_pizza'

[2025-05-13 22:18:17,855] [WARNING] Missing or incomplete docstring in /home/emilio/Documents/ai/pizza/src/pizza_detector.py
[2025-05-13 22:18:17,855] [WARNING] Validation passed with warnings for /home/emilio/Documents/ai/pizza/src/pizza_detector.py
[2025-05-13 22:18:17,855] [INFO] Validating script: test_frame_buffer.py
[2025-05-13 22:18:17,858] [WARNING] Missing dependencies in /home/emilio/Documents/ai/pizza/src/emulation/test_frame_buffer.py: frame_buffer
[2025-05-13 22:18:17,967] [WARNING] Validation passed with warnings for /home/emilio/Documents/ai/pizza/src/emulation/test_frame_buffer.py
[2025-05-13 22:18:17,967] [INFO] Validating script: emulator-test.py
[2025-05-13 22:18:18,076] [WARNING] Missing or incomplete docstring in /home/emilio/Documents/ai/pizza/src/emulation/emulator-test.py
[2025-05-13 22:18:18,076] [WARNING] Validation passed with warnings for /home/emilio/Documents/ai/pizza/src/emulation/emulator-test.py
[2025-05-13 22:18:18,076] [INFO] Validating script: emulator.py
[2025-05-13 22:18:18,081] [WARNING] Missing dependencies in /home/emilio/Documents/ai/pizza/src/emulation/emulator.py: constants, exceptions, frame_buffer, power_manager
[2025-05-13 22:18:18,189] [WARNING] Execution test issue in /home/emilio/Documents/ai/pizza/src/emulation/emulator.py: Execution failed with error: Traceback (most recent call last):
  File "/home/emilio/Documents/ai/pizza/src/emulation/emulator.py", line 12, in <module>
    from .constants import (
ImportError: attempted relative import with no known parent package

[2025-05-13 22:18:18,191] [WARNING] Validation passed with warnings for /home/emilio/Documents/ai/pizza/src/emulation/emulator.py
[2025-05-13 22:18:18,191] [INFO] Validating script: frame_buffer.py
[2025-05-13 22:18:18,303] [INFO] Validation passed for /home/emilio/Documents/ai/pizza/src/emulation/frame_buffer.py
[2025-05-13 22:18:18,303] [INFO] Validating script: metrics.py
[2025-05-13 22:18:18,308] [WARNING] Missing dependencies in /home/emilio/Documents/ai/pizza/src/analysis/metrics.py: constants, exceptions
[2025-05-13 22:18:19,906] [WARNING] Execution test issue in /home/emilio/Documents/ai/pizza/src/analysis/metrics.py: Execution failed with error: Traceback (most recent call last):
  File "/home/emilio/Documents/ai/pizza/src/analysis/metrics.py", line 16, in <module>
    from .types import (
ImportError: attempted relative import with no known parent package

[2025-05-13 22:18:19,908] [WARNING] Validation passed with warnings for /home/emilio/Documents/ai/pizza/src/analysis/metrics.py
[2025-05-13 22:18:19,908] [INFO] Validating script: models.py
[2025-05-13 22:18:20,206] [WARNING] Missing or incomplete docstring in /home/emilio/Documents/ai/pizza/src/chatlist_ki/models.py
[2025-05-13 22:18:20,206] [WARNING] Validation passed with warnings for /home/emilio/Documents/ai/pizza/src/chatlist_ki/models.py
[2025-05-13 22:18:20,206] [INFO] Validating script: __main__.py
[2025-05-13 22:18:20,207] [WARNING] Missing dependencies in /home/emilio/Documents/ai/pizza/src/chatlist_ki/__main__.py: database, chat_interface, models
[2025-05-13 22:18:20,216] [WARNING] Execution test issue in /home/emilio/Documents/ai/pizza/src/chatlist_ki/__main__.py: Execution failed with error: Traceback (most recent call last):
  File "/home/emilio/Documents/ai/pizza/src/chatlist_ki/__main__.py", line 1, in <module>
    from .chat_interface import ChatInterface
ImportError: attempted relative import with no known parent package

[2025-05-13 22:18:20,217] [WARNING] Missing or incomplete docstring in /home/emilio/Documents/ai/pizza/src/chatlist_ki/__main__.py
[2025-05-13 22:18:20,217] [WARNING] Validation passed with warnings for /home/emilio/Documents/ai/pizza/src/chatlist_ki/__main__.py
[2025-05-13 22:18:20,217] [INFO] Validating script: __init__.py
[2025-05-13 22:18:20,217] [WARNING] Missing dependencies in /home/emilio/Documents/ai/pizza/src/chatlist_ki/__init__.py: models, database, chat_interface
[2025-05-13 22:18:20,227] [WARNING] Execution test issue in /home/emilio/Documents/ai/pizza/src/chatlist_ki/__init__.py: Execution failed with error: Traceback (most recent call last):
  File "/home/emilio/Documents/ai/pizza/src/chatlist_ki/__init__.py", line 1, in <module>
    from .models import Task, TaskStatus
ImportError: attempted relative import with no known parent package

[2025-05-13 22:18:20,227] [WARNING] Missing or incomplete docstring in /home/emilio/Documents/ai/pizza/src/chatlist_ki/__init__.py
[2025-05-13 22:18:20,227] [WARNING] Validation passed with warnings for /home/emilio/Documents/ai/pizza/src/chatlist_ki/__init__.py
[2025-05-13 22:18:20,227] [INFO] Validating script: api.py
[2025-05-13 22:18:20,529] [WARNING] Missing dependencies in /home/emilio/Documents/ai/pizza/src/chatlist_ki/api.py: database, models
[2025-05-13 22:18:20,731] [WARNING] Execution test issue in /home/emilio/Documents/ai/pizza/src/chatlist_ki/api.py: Execution failed with error: Traceback (most recent call last):
  File "/home/emilio/Documents/ai/pizza/src/chatlist_ki/api.py", line 5, in <module>
    from .database import Database, TaskManager
ImportError: attempted relative import with no known parent package

[2025-05-13 22:18:20,732] [WARNING] Missing or incomplete docstring in /home/emilio/Documents/ai/pizza/src/chatlist_ki/api.py
[2025-05-13 22:18:20,732] [WARNING] Validation passed with warnings for /home/emilio/Documents/ai/pizza/src/chatlist_ki/api.py
[2025-05-13 22:18:20,732] [INFO] Validating script: database.py
[2025-05-13 22:18:20,735] [WARNING] Missing dependencies in /home/emilio/Documents/ai/pizza/src/chatlist_ki/database.py: models
[2025-05-13 22:18:20,928] [WARNING] Execution test issue in /home/emilio/Documents/ai/pizza/src/chatlist_ki/database.py: Execution failed with error: Traceback (most recent call last):
  File "/home/emilio/Documents/ai/pizza/src/chatlist_ki/database.py", line 4, in <module>
    from .models import Base, Task, TaskStatus
ImportError: attempted relative import with no known parent package

[2025-05-13 22:18:20,929] [WARNING] Missing or incomplete docstring in /home/emilio/Documents/ai/pizza/src/chatlist_ki/database.py
[2025-05-13 22:18:20,929] [WARNING] Validation passed with warnings for /home/emilio/Documents/ai/pizza/src/chatlist_ki/database.py
[2025-05-13 22:18:20,929] [INFO] Validating script: chat_interface.py
[2025-05-13 22:18:20,931] [WARNING] Missing dependencies in /home/emilio/Documents/ai/pizza/src/chatlist_ki/chat_interface.py: database, models
[2025-05-13 22:18:20,950] [WARNING] Execution test issue in /home/emilio/Documents/ai/pizza/src/chatlist_ki/chat_interface.py: Execution failed with error: Traceback (most recent call last):
  File "/home/emilio/Documents/ai/pizza/src/chatlist_ki/chat_interface.py", line 2, in <module>
    from .database import TaskManager, Database
ImportError: attempted relative import with no known parent package

[2025-05-13 22:18:20,951] [WARNING] Missing or incomplete docstring in /home/emilio/Documents/ai/pizza/src/chatlist_ki/chat_interface.py
[2025-05-13 22:18:20,951] [WARNING] Validation passed with warnings for /home/emilio/Documents/ai/pizza/src/chatlist_ki/chat_interface.py
[2025-05-13 22:18:20,951] [INFO] Validating script: status_display.py
[2025-05-13 22:18:20,957] [WARNING] Missing dependencies in /home/emilio/Documents/ai/pizza/src/visualization/status_display.py: machine, ssd1306
[2025-05-13 22:18:20,981] [WARNING] Execution test issue in /home/emilio/Documents/ai/pizza/src/visualization/status_display.py: Execution failed with error: Traceback (most recent call last):
  File "/home/emilio/Documents/ai/pizza/src/visualization/status_display.py", line 22, in <module>
    from src.types import InferenceResult
ModuleNotFoundError: No module named 'src'

[2025-05-13 22:18:20,983] [WARNING] Validation passed with warnings for /home/emilio/Documents/ai/pizza/src/visualization/status_display.py
[2025-05-13 22:18:20,984] [INFO] Validating script: visualization.py
[2025-05-13 22:18:21,000] [WARNING] Missing dependencies in /home/emilio/Documents/ai/pizza/src/visualization/visualization.py: constants
[2025-05-13 22:18:22,839] [WARNING] Execution test issue in /home/emilio/Documents/ai/pizza/src/visualization/visualization.py: Execution failed with error: Traceback (most recent call last):
  File "/home/emilio/Documents/ai/pizza/src/visualization/visualization.py", line 15, in <module>
    from .types import (
ImportError: attempted relative import with no known parent package

[2025-05-13 22:18:22,841] [WARNING] Validation passed with warnings for /home/emilio/Documents/ai/pizza/src/visualization/visualization.py
[2025-05-13 22:18:22,841] [INFO] Validating script: exceptions.py
[2025-05-13 22:18:22,852] [INFO] Validation passed for /home/emilio/Documents/ai/pizza/src/utils/exceptions.py
[2025-05-13 22:18:22,852] [INFO] Validating script: types.py
[2025-05-13 22:18:22,869] [WARNING] Execution test issue in /home/emilio/Documents/ai/pizza/src/utils/types.py: Execution failed with error: Traceback (most recent call last):
  File "/home/emilio/Documents/ai/pizza/src/utils/types.py", line 5, in <module>
    from typing import Dict, List, Tuple, Optional, Union, NamedTuple, Callable
  File "/usr/lib/python3.12/typing.py", line 27, in <module>
    import contextlib
  File "/usr/lib/python3.12/contextlib.py", line 7, in <module>
    from functools import wraps
  File "/usr/lib/python3.12/functools.py", line 22, in <module>
    from types import GenericAlias
  File "/home/emilio/Documents/ai/pizza/src/utils/types.py", line 5, in <module>
    from typing import Dict, List, Tuple, Optional, Union, NamedTuple, Callable
ImportError: cannot import name 'Dict' from partially initialized module 'typing' (most likely due to a circular import) (/usr/lib/python3.12/typing.py)

[2025-05-13 22:18:22,870] [WARNING] Validation passed with warnings for /home/emilio/Documents/ai/pizza/src/utils/types.py
[2025-05-13 22:18:22,870] [INFO] Validating script: power_manager.py
[2025-05-13 22:18:22,874] [WARNING] Missing dependencies in /home/emilio/Documents/ai/pizza/src/utils/power_manager.py: devices, constants, metrics
[2025-05-13 22:18:22,891] [WARNING] Execution test issue in /home/emilio/Documents/ai/pizza/src/utils/power_manager.py: Execution failed with error: Traceback (most recent call last):
  File "/home/emilio/Documents/ai/pizza/src/utils/power_manager.py", line 7, in <module>
    import logging
  File "/usr/lib/python3.12/logging/__init__.py", line 26, in <module>
    import sys, os, time, io, re, traceback, warnings, weakref, collections.abc
  File "/usr/lib/python3.12/re/__init__.py", line 124, in <module>
    import enum
  File "/usr/lib/python3.12/enum.py", line 3, in <module>
    from types import MappingProxyType, DynamicClassAttribute
  File "/home/emilio/Documents/ai/pizza/src/utils/types.py", line 5, in <module>
    from typing import Dict, List, Tuple, Optional, Union, NamedTuple, Callable
  File "/usr/lib/python3.12/typing.py", line 27, in <module>
    import contextlib
  File "/usr/lib/python3.12/contextlib.py", line 7, in <module>
    from functools import wraps
  File "/usr/lib/python3.12/functools.py", line 22, in <module>
    from types import GenericAlias
ImportError: cannot import name 'GenericAlias' from partially initialized module 'types' (most likely due to a circular import) (/home/emilio/Documents/ai/pizza/src/utils/types.py)

[2025-05-13 22:18:22,893] [WARNING] Validation passed with warnings for /home/emilio/Documents/ai/pizza/src/utils/power_manager.py
[2025-05-13 22:18:22,893] [INFO] Validating script: devices.py
[2025-05-13 22:18:22,895] [WARNING] Missing dependencies in /home/emilio/Documents/ai/pizza/src/utils/devices.py: constants, exceptions
[2025-05-13 22:18:22,907] [WARNING] Execution test issue in /home/emilio/Documents/ai/pizza/src/utils/devices.py: Execution failed with error: Traceback (most recent call last):
  File "/home/emilio/Documents/ai/pizza/src/utils/devices.py", line 6, in <module>
    import logging
  File "/usr/lib/python3.12/logging/__init__.py", line 26, in <module>
    import sys, os, time, io, re, traceback, warnings, weakref, collections.abc
  File "/usr/lib/python3.12/re/__init__.py", line 124, in <module>
    import enum
  File "/usr/lib/python3.12/enum.py", line 3, in <module>
    from types import MappingProxyType, DynamicClassAttribute
  File "/home/emilio/Documents/ai/pizza/src/utils/types.py", line 5, in <module>
    from typing import Dict, List, Tuple, Optional, Union, NamedTuple, Callable
  File "/usr/lib/python3.12/typing.py", line 27, in <module>
    import contextlib
  File "/usr/lib/python3.12/contextlib.py", line 7, in <module>
    from functools import wraps
  File "/usr/lib/python3.12/functools.py", line 22, in <module>
    from types import GenericAlias
ImportError: cannot import name 'GenericAlias' from partially initialized module 'types' (most likely due to a circular import) (/home/emilio/Documents/ai/pizza/src/utils/types.py)

[2025-05-13 22:18:22,908] [WARNING] Validation passed with warnings for /home/emilio/Documents/ai/pizza/src/utils/devices.py
[2025-05-13 22:18:22,909] [INFO] Validating script: validation.py
[2025-05-13 22:18:22,911] [WARNING] Missing dependencies in /home/emilio/Documents/ai/pizza/src/utils/validation.py: constants, exceptions
[2025-05-13 22:18:22,929] [WARNING] Execution test issue in /home/emilio/Documents/ai/pizza/src/utils/validation.py: Execution failed with error: Traceback (most recent call last):
  File "/home/emilio/Documents/ai/pizza/src/utils/validation.py", line 6, in <module>
    import json
  File "/usr/lib/python3.12/json/__init__.py", line 106, in <module>
    from .decoder import JSONDecoder, JSONDecodeError
  File "/usr/lib/python3.12/json/decoder.py", line 3, in <module>
    import re
  File "/usr/lib/python3.12/re/__init__.py", line 124, in <module>
    import enum
  File "/usr/lib/python3.12/enum.py", line 3, in <module>
    from types import MappingProxyType, DynamicClassAttribute
  File "/home/emilio/Documents/ai/pizza/src/utils/types.py", line 5, in <module>
    from typing import Dict, List, Tuple, Optional, Union, NamedTuple, Callable
  File "/usr/lib/python3.12/typing.py", line 27, in <module>
    import contextlib
  File "/usr/lib/python3.12/contextlib.py", line 7, in <module>
    from functools import wraps
  File "/usr/lib/python3.12/functools.py", line 22, in <module>
    from types import GenericAlias
ImportError: cannot import name 'GenericAlias' from partially initialized module 'types' (most likely due to a circular import) (/home/emilio/Documents/ai/pizza/src/utils/types.py)

[2025-05-13 22:18:22,930] [WARNING] Validation passed with warnings for /home/emilio/Documents/ai/pizza/src/utils/validation.py
[2025-05-13 22:18:22,930] [INFO] Validating script: memory.py
[2025-05-13 22:18:22,932] [WARNING] Missing dependencies in /home/emilio/Documents/ai/pizza/src/utils/memory.py: constants, exceptions
[2025-05-13 22:18:22,950] [WARNING] Execution test issue in /home/emilio/Documents/ai/pizza/src/utils/memory.py: Execution failed with error: Traceback (most recent call last):
  File "/home/emilio/Documents/ai/pizza/src/utils/memory.py", line 5, in <module>
    import torch
  File "/home/emilio/Documents/ai/pizza/.venv/lib/python3.12/site-packages/torch/__init__.py", line 14, in <module>
    import ctypes
  File "/usr/lib/python3.12/ctypes/__init__.py", line 4, in <module>
    import types as _types
  File "/home/emilio/Documents/ai/pizza/src/utils/types.py", line 5, in <module>
    from typing import Dict, List, Tuple, Optional, Union, NamedTuple, Callable
  File "/usr/lib/python3.12/typing.py", line 27, in <module>
    import contextlib
  File "/usr/lib/python3.12/contextlib.py", line 7, in <module>
    from functools import wraps
  File "/usr/lib/python3.12/functools.py", line 22, in <module>
    from types import GenericAlias
ImportError: cannot import name 'GenericAlias' from partially initialized module 'types' (most likely due to a circular import) (/home/emilio/Documents/ai/pizza/src/utils/types.py)

[2025-05-13 22:18:22,950] [WARNING] Validation passed with warnings for /home/emilio/Documents/ai/pizza/src/utils/memory.py
[2025-05-13 22:18:22,951] [INFO] Validating script: temporal_smoother.py
[2025-05-13 22:18:22,970] [WARNING] Execution test issue in /home/emilio/Documents/ai/pizza/src/utils/temporal_smoother.py: Execution failed with error: Traceback (most recent call last):
  File "/home/emilio/Documents/ai/pizza/src/utils/temporal_smoother.py", line 9, in <module>
    import numpy as np
  File "/home/emilio/Documents/ai/pizza/.venv/lib/python3.12/site-packages/numpy/__init__.py", line 92, in <module>
    from ._globals import _NoValue, _CopyMode
  File "/home/emilio/Documents/ai/pizza/.venv/lib/python3.12/site-packages/numpy/_globals.py", line 18, in <module>
    import enum
  File "/usr/lib/python3.12/enum.py", line 3, in <module>
    from types import MappingProxyType, DynamicClassAttribute
  File "/home/emilio/Documents/ai/pizza/src/utils/types.py", line 5, in <module>
    from typing import Dict, List, Tuple, Optional, Union, NamedTuple, Callable
  File "/usr/lib/python3.12/typing.py", line 27, in <module>
    import contextlib
  File "/usr/lib/python3.12/contextlib.py", line 7, in <module>
    from functools import wraps
  File "/usr/lib/python3.12/functools.py", line 22, in <module>
    from types import GenericAlias
ImportError: cannot import name 'GenericAlias' from partially initialized module 'types' (most likely due to a circular import) (/home/emilio/Documents/ai/pizza/src/utils/types.py)

[2025-05-13 22:18:22,971] [WARNING] Validation passed with warnings for /home/emilio/Documents/ai/pizza/src/utils/temporal_smoother.py
[2025-05-13 22:18:22,971] [INFO] Validating script: utils.py
[2025-05-13 22:18:22,985] [WARNING] Execution test issue in /home/emilio/Documents/ai/pizza/src/utils/utils.py: Execution failed with error: Traceback (most recent call last):
  File "/home/emilio/Documents/ai/pizza/src/utils/utils.py", line 6, in <module>
    import logging
  File "/usr/lib/python3.12/logging/__init__.py", line 26, in <module>
    import sys, os, time, io, re, traceback, warnings, weakref, collections.abc
  File "/usr/lib/python3.12/re/__init__.py", line 124, in <module>
    import enum
  File "/usr/lib/python3.12/enum.py", line 3, in <module>
    from types import MappingProxyType, DynamicClassAttribute
  File "/home/emilio/Documents/ai/pizza/src/utils/types.py", line 5, in <module>
    from typing import Dict, List, Tuple, Optional, Union, NamedTuple, Callable
  File "/usr/lib/python3.12/typing.py", line 27, in <module>
    import contextlib
  File "/usr/lib/python3.12/contextlib.py", line 7, in <module>
    from functools import wraps
  File "/usr/lib/python3.12/functools.py", line 22, in <module>
    from types import GenericAlias
ImportError: cannot import name 'GenericAlias' from partially initialized module 'types' (most likely due to a circular import) (/home/emilio/Documents/ai/pizza/src/utils/types.py)

[2025-05-13 22:18:22,986] [WARNING] Validation passed with warnings for /home/emilio/Documents/ai/pizza/src/utils/utils.py
[2025-05-13 22:18:22,986] [INFO] Validating script: constants.py
[2025-05-13 22:18:23,002] [WARNING] Execution test issue in /home/emilio/Documents/ai/pizza/src/utils/constants.py: Execution failed with error: Traceback (most recent call last):
  File "/home/emilio/Documents/ai/pizza/src/utils/constants.py", line 5, in <module>
    from pathlib import Path
  File "/usr/lib/python3.12/pathlib.py", line 8, in <module>
    import fnmatch
  File "/usr/lib/python3.12/fnmatch.py", line 14, in <module>
    import re
  File "/usr/lib/python3.12/re/__init__.py", line 124, in <module>
    import enum
  File "/usr/lib/python3.12/enum.py", line 3, in <module>
    from types import MappingProxyType, DynamicClassAttribute
  File "/home/emilio/Documents/ai/pizza/src/utils/types.py", line 5, in <module>
    from typing import Dict, List, Tuple, Optional, Union, NamedTuple, Callable
  File "/usr/lib/python3.12/typing.py", line 27, in <module>
    import contextlib
  File "/usr/lib/python3.12/contextlib.py", line 7, in <module>
    from functools import wraps
  File "/usr/lib/python3.12/functools.py", line 22, in <module>
    from types import GenericAlias
ImportError: cannot import name 'GenericAlias' from partially initialized module 'types' (most likely due to a circular import) (/home/emilio/Documents/ai/pizza/src/utils/types.py)

[2025-05-13 22:18:23,003] [WARNING] Validation passed with warnings for /home/emilio/Documents/ai/pizza/src/utils/constants.py
[2025-05-13 22:18:23,003] [INFO] Validating script: enhanced_pizza_augmentation.py
[2025-05-13 22:18:25,260] [WARNING] Execution test issue in /home/emilio/Documents/ai/pizza/src/augmentation/enhanced_pizza_augmentation.py: Execution failed with error: 
[2025-05-13 22:18:25,269] [WARNING] Missing or incomplete docstring in /home/emilio/Documents/ai/pizza/src/augmentation/enhanced_pizza_augmentation.py
[2025-05-13 22:18:25,269] [WARNING] Validation passed with warnings for /home/emilio/Documents/ai/pizza/src/augmentation/enhanced_pizza_augmentation.py
[2025-05-13 22:18:25,269] [INFO] Validating script: augmentation_optimized.py
[2025-05-13 22:18:27,675] [WARNING] Execution test issue in /home/emilio/Documents/ai/pizza/src/augmentation/augmentation_optimized.py: Execution failed with error: Traceback (most recent call last):
  File "/home/emilio/Documents/ai/pizza/src/augmentation/augmentation_optimized.py", line 698, in <module>
    main()
  File "/home/emilio/Documents/ai/pizza/src/augmentation/augmentation_optimized.py", line 688, in main
    augment_pizza_dataset(input_dir, output_dir, img_per_original=img_per_original, batch_size=batch_size)
  File "/home/emilio/Documents/ai/pizza/src/augmentation/augmentation_optimized.py", line 512, in augment_pizza_dataset
    image_files = [os.path.join(input_dir, f) for f in os.listdir(input_dir) 
                                                       ^^^^^^^^^^^^^^^^^^^^^
FileNotFoundError: [Errno 2] No such file or directory: '/home/emilio/Documents/ai/pizza/img-pizza/'

[2025-05-13 22:18:27,678] [WARNING] Missing or incomplete docstring in /home/emilio/Documents/ai/pizza/src/augmentation/augmentation_optimized.py
[2025-05-13 22:18:27,678] [WARNING] Validation passed with warnings for /home/emilio/Documents/ai/pizza/src/augmentation/augmentation_optimized.py
[2025-05-13 22:18:27,678] [INFO] Validating script: diffusion_pizza_generator.py
[2025-05-13 22:18:27,679] [ERROR] Syntax error in /home/emilio/Documents/ai/pizza/src/augmentation/diffusion_pizza_generator.py: Syntax error at line 164: parameter without a default follows parameter with a default
[2025-05-13 22:18:27,680] [WARNING] Missing or incomplete docstring in /home/emilio/Documents/ai/pizza/src/augmentation/diffusion_pizza_generator.py
[2025-05-13 22:18:27,680] [WARNING] Validation passed with warnings for /home/emilio/Documents/ai/pizza/src/augmentation/diffusion_pizza_generator.py
[2025-05-13 22:18:27,680] [INFO] Validating script: augmentation.py
[2025-05-13 22:18:29,910] [WARNING] Execution test issue in /home/emilio/Documents/ai/pizza/src/augmentation/augmentation.py: Execution failed with error: 
[2025-05-13 22:18:29,921] [WARNING] Missing or incomplete docstring in /home/emilio/Documents/ai/pizza/src/augmentation/augmentation.py
[2025-05-13 22:18:29,921] [WARNING] Validation passed with warnings for /home/emilio/Documents/ai/pizza/src/augmentation/augmentation.py
[2025-05-13 22:18:29,921] [INFO] Validating script: advanced_pizza_diffusion_control.py
[2025-05-13 22:18:29,922] [ERROR] Syntax error in /home/emilio/Documents/ai/pizza/src/augmentation/advanced_pizza_diffusion_control.py: Syntax error at line 117: parameter without a default follows parameter with a default
[2025-05-13 22:18:29,924] [WARNING] Missing or incomplete docstring in /home/emilio/Documents/ai/pizza/src/augmentation/advanced_pizza_diffusion_control.py
[2025-05-13 22:18:29,924] [WARNING] Validation passed with warnings for /home/emilio/Documents/ai/pizza/src/augmentation/advanced_pizza_diffusion_control.py
[2025-05-13 22:18:29,924] [INFO] Validating script: optimized-pizza-augmentation.py
[2025-05-13 22:18:32,357] [WARNING] Execution test issue in /home/emilio/Documents/ai/pizza/src/augmentation/optimized-pizza-augmentation.py: Execution failed with error: Traceback (most recent call last):
  File "/home/emilio/Documents/ai/pizza/src/augmentation/optimized-pizza-augmentation.py", line 698, in <module>
    main()
  File "/home/emilio/Documents/ai/pizza/src/augmentation/optimized-pizza-augmentation.py", line 688, in main
    augment_pizza_dataset(input_dir, output_dir, img_per_original=img_per_original, batch_size=batch_size)
  File "/home/emilio/Documents/ai/pizza/src/augmentation/optimized-pizza-augmentation.py", line 512, in augment_pizza_dataset
    image_files = [os.path.join(input_dir, f) for f in os.listdir(input_dir) 
                                                       ^^^^^^^^^^^^^^^^^^^^^
FileNotFoundError: [Errno 2] No such file or directory: '/home/emilio/Documents/ai/pizza/img-pizza/'

[2025-05-13 22:18:32,361] [WARNING] Missing or incomplete docstring in /home/emilio/Documents/ai/pizza/src/augmentation/optimized-pizza-augmentation.py
[2025-05-13 22:18:32,361] [WARNING] Validation passed with warnings for /home/emilio/Documents/ai/pizza/src/augmentation/optimized-pizza-augmentation.py
[2025-05-13 22:18:32,361] [INFO] Validating script: augment_legacy.py
[2025-05-13 22:18:34,486] [WARNING] Execution test issue in /home/emilio/Documents/ai/pizza/src/legacy/augment_legacy.py: Execution failed with error: Traceback (most recent call last):
  File "/home/emilio/Documents/ai/pizza/src/legacy/augment_legacy.py", line 176, in <module>
    augment_pizza(input_dir, output_dir, num_images, batch_size) 
    ^^^^^^^^^^^^^^^^^^^^^^^^^^^^^^^^^^^^^^^^^^^^^^^^^^^^^^^^^^^^
  File "/home/emilio/Documents/ai/pizza/src/legacy/augment_legacy.py", line 131, in augment_pizza
    image_files = [os.path.join(input_dir, f) for f in os.listdir(input_dir) 
                                                       ^^^^^^^^^^^^^^^^^^^^^
FileNotFoundError: [Errno 2] No such file or directory: 'img-pizza'

[2025-05-13 22:18:34,488] [WARNING] Missing or incomplete docstring in /home/emilio/Documents/ai/pizza/src/legacy/augment_legacy.py
[2025-05-13 22:18:34,488] [WARNING] Validation passed with warnings for /home/emilio/Documents/ai/pizza/src/legacy/augment_legacy.py
[2025-05-13 22:18:34,488] [INFO] Validating script: diffusion_data_agent.py
[2025-05-13 22:18:34,497] [WARNING] Missing dependencies in /home/emilio/Documents/ai/pizza/src/integration/diffusion_data_agent.py: cleanfid
[2025-05-13 22:18:36,384] [WARNING] Validation passed with warnings for /home/emilio/Documents/ai/pizza/src/integration/diffusion_data_agent.py
[2025-05-13 22:18:36,384] [INFO] Validating script: pizza_diffusion_integration.py
[2025-05-13 22:18:36,391] [WARNING] Missing dependencies in /home/emilio/Documents/ai/pizza/src/integration/pizza_diffusion_integration.py: optimized_pizza_augmentation, diffusion_data_agent, enhanced_pizza_augmentation
[2025-05-13 22:18:38,211] [WARNING] Execution test issue in /home/emilio/Documents/ai/pizza/src/integration/pizza_diffusion_integration.py: Execution failed with error: Traceback (most recent call last):
  File "/home/emilio/Documents/ai/pizza/src/integration/pizza_diffusion_integration.py", line 29, in <module>
    from enhanced_pizza_augmentation import (
ModuleNotFoundError: No module named 'enhanced_pizza_augmentation'

During handling of the above exception, another exception occurred:

Traceback (most recent call last):
  File "/home/emilio/Documents/ai/pizza/src/integration/pizza_diffusion_integration.py", line 40, in <module>
    from optimized_pizza_augmentation import (
ModuleNotFoundError: No module named 'optimized_pizza_augmentation'

During handling of the above exception, another exception occurred:

Traceback (most recent call last):
  File "/home/emilio/Documents/ai/pizza/src/integration/pizza_diffusion_integration.py", line 49, in <module>
    from test import (
ImportError: cannot import name 'PizzaBurningEffect' from 'test' (/usr/lib/python3.12/test/__init__.py)

[2025-05-13 22:18:38,214] [WARNING] Validation passed with warnings for /home/emilio/Documents/ai/pizza/src/integration/pizza_diffusion_integration.py
[2025-05-13 22:18:38,214] [INFO] Validating script: diffusion_training_integration.py
[2025-05-13 22:18:40,202] [WARNING] Execution test issue in /home/emilio/Documents/ai/pizza/src/integration/diffusion_training_integration.py: Execution failed with error: Traceback (most recent call last):
  File "/home/emilio/Documents/ai/pizza/src/integration/diffusion_training_integration.py", line 41, in <module>
    from src.augmentation.diffusion_pizza_generator import PizzaDiffusionGenerator, PIZZA_STAGES
  File "/home/emilio/Documents/ai/pizza/src/augmentation/diffusion_pizza_generator.py", line 164
    self, 
    ^^^^
SyntaxError: parameter without a default follows parameter with a default

[2025-05-13 22:18:40,207] [WARNING] Validation passed with warnings for /home/emilio/Documents/ai/pizza/src/integration/diffusion_training_integration.py
[2025-05-13 22:18:40,208] [INFO] Validation complete. Summary: 15 passed, 57 with warnings, 0 failed
[2025-05-13 22:18:40,208] [INFO] Report written to validation_report.json
