[2025-05-14 12:53:20,926] [INFO] Found 75 Python scripts to validate
[2025-05-14 12:53:20,927] [INFO] Validating script: cleanup.py
[2025-05-14 12:53:21,107] [INFO] Validation passed for /home/emilio/Documents/ai/pizza/scripts/cleanup.py
[2025-05-14 12:53:21,107] [INFO] Validating script: filter_dataset.py
[2025-05-14 12:53:21,116] [WARNING] Missing or incomplete docstring in /home/emilio/Documents/ai/pizza/scripts/filter_dataset.py
[2025-05-14 12:53:21,116] [WARNING] Validation passed with warnings for /home/emilio/Documents/ai/pizza/scripts/filter_dataset.py
[2025-05-14 12:53:21,116] [INFO] Validating script: label_tool.py
[2025-05-14 12:53:23,312] [INFO] Validation passed for /home/emilio/Documents/ai/pizza/scripts/label_tool.py
[2025-05-14 12:53:23,312] [INFO] Validating script: framebuffer_demo.py
[2025-05-14 12:53:23,406] [WARNING] Execution test issue in /home/emilio/Documents/ai/pizza/scripts/framebuffer_demo.py: Execution failed with error: 
[2025-05-14 12:53:23,408] [WARNING] Validation passed with warnings for /home/emilio/Documents/ai/pizza/scripts/framebuffer_demo.py
[2025-05-14 12:53:23,408] [INFO] Validating script: compare_inverted_residual.py
[2025-05-14 12:53:27,113] [INFO] Validation passed for /home/emilio/Documents/ai/pizza/scripts/compare_inverted_residual.py
[2025-05-14 12:53:27,113] [INFO] Validating script: test_temporal_smoothing.py
[2025-05-14 12:53:27,462] [INFO] Validation passed for /home/emilio/Documents/ai/pizza/scripts/test_temporal_smoothing.py
[2025-05-14 12:53:27,462] [INFO] Validating script: knowledge_distillation.py
[2025-05-14 12:53:29,458] [INFO] Validation passed for /home/emilio/Documents/ai/pizza/scripts/knowledge_distillation.py
[2025-05-14 12:53:29,458] [INFO] Validating script: visualize_gradcam.py
[2025-05-14 12:53:30,054] [WARNING] Missing dependencies in /home/emilio/Documents/ai/pizza/scripts/visualize_gradcam.py: scripts
[2025-05-14 12:53:32,568] [WARNING] Validation passed with warnings for /home/emilio/Documents/ai/pizza/scripts/visualize_gradcam.py
[2025-05-14 12:53:32,568] [INFO] Validating script: classify_images.py
[2025-05-14 12:53:32,581] [WARNING] Missing or incomplete docstring in /home/emilio/Documents/ai/pizza/scripts/classify_images.py
[2025-05-14 12:53:32,582] [WARNING] Validation passed with warnings for /home/emilio/Documents/ai/pizza/scripts/classify_images.py
[2025-05-14 12:53:32,582] [INFO] Validating script: visualize_pruning.py
[2025-05-14 12:53:35,059] [INFO] Validation passed for /home/emilio/Documents/ai/pizza/scripts/visualize_pruning.py
[2025-05-14 12:53:35,059] [INFO] Validating script: compare_tiny_cnns.py
[2025-05-14 12:53:35,088] [WARNING] Missing dependencies in /home/emilio/Documents/ai/pizza/scripts/compare_tiny_cnns.py: scripts
[2025-05-14 12:53:37,553] [WARNING] Validation passed with warnings for /home/emilio/Documents/ai/pizza/scripts/compare_tiny_cnns.py
[2025-05-14 12:53:37,553] [INFO] Validating script: compare_se_models.py
[2025-05-14 12:53:40,138] [INFO] Validation passed for /home/emilio/Documents/ai/pizza/scripts/compare_se_models.py
[2025-05-14 12:53:40,138] [INFO] Validating script: automated_test_suite.py
[2025-05-14 12:53:42,648] [WARNING] Execution test issue in /home/emilio/Documents/ai/pizza/scripts/automated_test_suite.py: Execution failed with error: Traceback (most recent call last):
  File "/home/emilio/Documents/ai/pizza/scripts/automated_test_suite.py", line 53, in <module>
    from src.pizza_detector import (
ImportError: cannot import name 'load_model' from 'src.pizza_detector' (/home/emilio/Documents/ai/pizza/src/pizza_detector.py)

[2025-05-14 12:53:42,652] [WARNING] Validation passed with warnings for /home/emilio/Documents/ai/pizza/scripts/automated_test_suite.py
[2025-05-14 12:53:42,652] [INFO] Validating script: compare_hard_swish.py
[2025-05-14 12:53:45,178] [INFO] Validation passed for /home/emilio/Documents/ai/pizza/scripts/compare_hard_swish.py
[2025-05-14 12:53:45,178] [INFO] Validating script: demo_status_display.py
[2025-05-14 12:53:45,210] [WARNING] Execution test issue in /home/emilio/Documents/ai/pizza/scripts/demo_status_display.py: Execution failed with error: Traceback (most recent call last):
  File "/home/emilio/Documents/ai/pizza/scripts/demo_status_display.py", line 38, in <module>
    from src.status_display import (
ModuleNotFoundError: No module named 'src.status_display'

[2025-05-14 12:53:45,211] [WARNING] Validation passed with warnings for /home/emilio/Documents/ai/pizza/scripts/demo_status_display.py
[2025-05-14 12:53:45,211] [INFO] Validating script: test_image_preprocessing.py
[2025-05-14 12:53:45,533] [INFO] Validation passed for /home/emilio/Documents/ai/pizza/scripts/test_image_preprocessing.py
[2025-05-14 12:53:45,533] [INFO] Validating script: test_pizza_detection.py
[2025-05-14 12:53:47,557] [WARNING] Execution test issue in /home/emilio/Documents/ai/pizza/scripts/test_pizza_detection.py: Execution failed with error: Traceback (most recent call last):
  File "/home/emilio/Documents/ai/pizza/scripts/test_pizza_detection.py", line 27, in <module>
    from src.types import InferenceResult
ModuleNotFoundError: No module named 'src.types'

[2025-05-14 12:53:47,558] [WARNING] Validation passed with warnings for /home/emilio/Documents/ai/pizza/scripts/test_pizza_detection.py
[2025-05-14 12:53:47,559] [INFO] Validating script: demo_power_management.py
[2025-05-14 12:53:47,876] [WARNING] Execution test issue in /home/emilio/Documents/ai/pizza/scripts/demo_power_management.py: Execution failed with error: Traceback (most recent call last):
  File "/home/emilio/Documents/ai/pizza/scripts/demo_power_management.py", line 19, in <module>
    from src.emulator import RP2040Emulator
ModuleNotFoundError: No module named 'src.emulator'

[2025-05-14 12:53:47,878] [WARNING] Validation passed with warnings for /home/emilio/Documents/ai/pizza/scripts/demo_power_management.py
[2025-05-14 12:53:47,878] [INFO] Validating script: analyze_performance_logs.py
[2025-05-14 12:53:48,608] [INFO] Validation passed for /home/emilio/Documents/ai/pizza/scripts/analyze_performance_logs.py
[2025-05-14 12:53:48,608] [INFO] Validating script: simulate_memory_constraints.py
[2025-05-14 12:53:48,898] [WARNING] Execution test issue in /home/emilio/Documents/ai/pizza/scripts/simulate_memory_constraints.py: Execution failed with error: Traceback (most recent call last):
  File "/home/emilio/Documents/ai/pizza/scripts/simulate_memory_constraints.py", line 17, in <module>
    from src.constants import (
ImportError: cannot import name 'RP2040_CLOCK_SPEED_MHZ' from 'src.constants' (/home/emilio/Documents/ai/pizza/src/constants.py). Did you mean: 'RP2040_CLOCK_SPEED'?

[2025-05-14 12:53:48,900] [WARNING] Validation passed with warnings for /home/emilio/Documents/ai/pizza/scripts/simulate_memory_constraints.py
[2025-05-14 12:53:48,900] [INFO] Validating script: simulate_clahe_resources.py
[2025-05-14 12:53:49,220] [INFO] Validation passed for /home/emilio/Documents/ai/pizza/scripts/simulate_clahe_resources.py
[2025-05-14 12:53:49,220] [INFO] Validating script: run_pizza_tests.py
[2025-05-14 12:53:49,245] [INFO] Validation passed for /home/emilio/Documents/ai/pizza/scripts/run_pizza_tests.py
[2025-05-14 12:53:49,245] [INFO] Validating script: run_pruning_clustering.py
[2025-05-14 12:53:49,247] [WARNING] Missing dependencies in /home/emilio/Documents/ai/pizza/scripts/run_pruning_clustering.py: config, scripts
[2025-05-14 12:53:51,229] [WARNING] Validation passed with warnings for /home/emilio/Documents/ai/pizza/scripts/run_pruning_clustering.py
[2025-05-14 12:53:51,229] [INFO] Validating script: augment_dataset.py
[2025-05-14 12:53:51,345] [INFO] Validation passed for /home/emilio/Documents/ai/pizza/scripts/augment_dataset.py
[2025-05-14 12:53:51,345] [INFO] Validating script: train_pizza_model.py
[2025-05-14 12:53:53,287] [INFO] Validation passed for /home/emilio/Documents/ai/pizza/scripts/train_pizza_model.py
[2025-05-14 12:53:53,287] [INFO] Validating script: simulate_lighting_conditions.py
[2025-05-14 12:53:53,565] [WARNING] Execution test issue in /home/emilio/Documents/ai/pizza/scripts/simulate_lighting_conditions.py: Execution failed with error: Traceback (most recent call last):
  File "/home/emilio/Documents/ai/pizza/scripts/simulate_lighting_conditions.py", line 17, in <module>
    from src.emulator import RP2040Emulator
ModuleNotFoundError: No module named 'src.emulator'

[2025-05-14 12:53:53,566] [WARNING] Validation passed with warnings for /home/emilio/Documents/ai/pizza/scripts/simulate_lighting_conditions.py
[2025-05-14 12:53:53,566] [INFO] Validating script: quantization_aware_training.py
[2025-05-14 12:53:55,583] [INFO] Validation passed for /home/emilio/Documents/ai/pizza/scripts/quantization_aware_training.py
[2025-05-14 12:53:55,583] [INFO] Validating script: simulate_power_consumption.py
[2025-05-14 12:53:55,874] [WARNING] Execution test issue in /home/emilio/Documents/ai/pizza/scripts/simulate_power_consumption.py: Execution failed with error: Traceback (most recent call last):
  File "/home/emilio/Documents/ai/pizza/scripts/simulate_power_consumption.py", line 18, in <module>
    from src.constants import (
ImportError: cannot import name 'RP2040_CLOCK_SPEED_MHZ' from 'src.constants' (/home/emilio/Documents/ai/pizza/src/constants.py). Did you mean: 'RP2040_CLOCK_SPEED'?

[2025-05-14 12:53:55,876] [WARNING] Validation passed with warnings for /home/emilio/Documents/ai/pizza/scripts/simulate_power_consumption.py
[2025-05-14 12:53:55,876] [INFO] Validating script: generate_pizza_dataset.py
[2025-05-14 12:54:00,527] [INFO] Validation passed for /home/emilio/Documents/ai/pizza/scripts/generate_pizza_dataset.py
[2025-05-14 12:54:00,527] [INFO] Validating script: hyperparameter_search.py
[2025-05-14 12:54:03,103] [INFO] Validation passed for /home/emilio/Documents/ai/pizza/scripts/hyperparameter_search.py
[2025-05-14 12:54:03,104] [INFO] Validating script: extract_frames.py
[2025-05-14 12:54:03,112] [WARNING] Missing or incomplete docstring in /home/emilio/Documents/ai/pizza/scripts/extract_frames.py
[2025-05-14 12:54:03,112] [WARNING] Validation passed with warnings for /home/emilio/Documents/ai/pizza/scripts/extract_frames.py
[2025-05-14 12:54:03,112] [INFO] Validating script: validate_integration.py
[2025-05-14 12:54:03,152] [INFO] Validation passed for /home/emilio/Documents/ai/pizza/scripts/ci/validate_integration.py
[2025-05-14 12:54:03,152] [INFO] Validating script: validate_scripts.py
[2025-05-14 12:54:03,236] [INFO] Validation passed for /home/emilio/Documents/ai/pizza/scripts/ci/validate_scripts.py
[2025-05-14 12:54:03,236] [INFO] Validating script: generate_pipeline_report.py
[2025-05-14 12:54:03,557] [INFO] Validation passed for /home/emilio/Documents/ai/pizza/scripts/ci/generate_pipeline_report.py
[2025-05-14 12:54:03,557] [INFO] Validating script: generate_optimization_summary.py
[2025-05-14 12:54:03,873] [INFO] Validation passed for /home/emilio/Documents/ai/pizza/scripts/ci/generate_optimization_summary.py
[2025-05-14 12:54:03,873] [INFO] Validating script: weight_pruning.py
[2025-05-14 12:54:03,882] [WARNING] Missing dependencies in /home/emilio/Documents/ai/pizza/scripts/model_optimization/weight_pruning.py: config
[2025-05-14 12:54:05,925] [WARNING] Validation passed with warnings for /home/emilio/Documents/ai/pizza/scripts/model_optimization/weight_pruning.py
[2025-05-14 12:54:05,925] [INFO] Validating script: micropizzanet_early_exit.py
[2025-05-14 12:54:07,985] [INFO] Validation passed for /home/emilio/Documents/ai/pizza/scripts/early_exit/micropizzanet_early_exit.py
[2025-05-14 12:54:07,985] [INFO] Validating script: verify_model.py
[2025-05-14 12:54:09,707] [WARNING] Missing or incomplete docstring in /home/emilio/Documents/ai/pizza/models/rp2040_export/verify_model.py
[2025-05-14 12:54:09,707] [WARNING] Validation passed with warnings for /home/emilio/Documents/ai/pizza/models/rp2040_export/verify_model.py
[2025-05-14 12:54:09,707] [INFO] Validating script: pizza-baking-detection-final.py
[2025-05-14 12:54:10,823] [WARNING] Missing dependencies in /home/emilio/Documents/ai/pizza/src/pizza-baking-detection-final.py: onnx_tf
[2025-05-14 12:54:15,530] [WARNING] Missing or incomplete docstring in /home/emilio/Documents/ai/pizza/src/pizza-baking-detection-final.py
[2025-05-14 12:54:15,531] [WARNING] Validation passed with warnings for /home/emilio/Documents/ai/pizza/src/pizza-baking-detection-final.py
[2025-05-14 12:54:15,531] [INFO] Validating script: metrics.py
[2025-05-14 12:54:16,744] [INFO] Validation passed for /home/emilio/Documents/ai/pizza/src/metrics.py
[2025-05-14 12:54:16,744] [INFO] Validating script: __init__.py
[2025-05-14 12:54:16,753] [WARNING] Missing or incomplete docstring in /home/emilio/Documents/ai/pizza/src/__init__.py
[2025-05-14 12:54:16,753] [WARNING] Validation passed with warnings for /home/emilio/Documents/ai/pizza/src/__init__.py
[2025-05-14 12:54:16,753] [INFO] Validating script: pizza_detector.py
[2025-05-14 12:54:16,776] [WARNING] Missing dependencies in /home/emilio/Documents/ai/pizza/src/pizza_detector.py: onnx_tf
[2025-05-14 12:54:21,743] [WARNING] Missing or incomplete docstring in /home/emilio/Documents/ai/pizza/src/pizza_detector.py
[2025-05-14 12:54:21,743] [WARNING] Validation passed with warnings for /home/emilio/Documents/ai/pizza/src/pizza_detector.py
[2025-05-14 12:54:21,743] [INFO] Validating script: constants.py
[2025-05-14 12:54:21,765] [INFO] Validation passed for /home/emilio/Documents/ai/pizza/src/constants.py
[2025-05-14 12:54:21,765] [INFO] Validating script: test_frame_buffer.py
[2025-05-14 12:54:21,770] [WARNING] Missing dependencies in /home/emilio/Documents/ai/pizza/src/emulation/test_frame_buffer.py: frame_buffer
[2025-05-14 12:54:21,864] [WARNING] Validation passed with warnings for /home/emilio/Documents/ai/pizza/src/emulation/test_frame_buffer.py
[2025-05-14 12:54:21,864] [INFO] Validating script: emulator-test.py
[2025-05-14 12:54:21,988] [WARNING] Missing or incomplete docstring in /home/emilio/Documents/ai/pizza/src/emulation/emulator-test.py
[2025-05-14 12:54:21,988] [WARNING] Validation passed with warnings for /home/emilio/Documents/ai/pizza/src/emulation/emulator-test.py
[2025-05-14 12:54:21,988] [INFO] Validating script: emulator.py
[2025-05-14 12:54:21,993] [WARNING] Missing dependencies in /home/emilio/Documents/ai/pizza/src/emulation/emulator.py: exceptions, power_manager, constants, frame_buffer
[2025-05-14 12:54:22,091] [WARNING] Execution test issue in /home/emilio/Documents/ai/pizza/src/emulation/emulator.py: Execution failed with error: Traceback (most recent call last):
  File "/home/emilio/Documents/ai/pizza/src/emulation/emulator.py", line 12, in <module>
    from .constants import (
ImportError: attempted relative import with no known parent package

[2025-05-14 12:54:22,093] [WARNING] Validation passed with warnings for /home/emilio/Documents/ai/pizza/src/emulation/emulator.py
[2025-05-14 12:54:22,093] [INFO] Validating script: frame_buffer.py
[2025-05-14 12:54:22,166] [INFO] Validation passed for /home/emilio/Documents/ai/pizza/src/emulation/frame_buffer.py
[2025-05-14 12:54:22,166] [INFO] Validating script: metrics.py
[2025-05-14 12:54:22,171] [WARNING] Missing dependencies in /home/emilio/Documents/ai/pizza/src/analysis/metrics.py: exceptions, constants
[2025-05-14 12:54:23,634] [WARNING] Execution test issue in /home/emilio/Documents/ai/pizza/src/analysis/metrics.py: Execution failed with error: Traceback (most recent call last):
  File "/home/emilio/Documents/ai/pizza/src/analysis/metrics.py", line 16, in <module>
    from .types import (
ImportError: attempted relative import with no known parent package

[2025-05-14 12:54:23,636] [WARNING] Validation passed with warnings for /home/emilio/Documents/ai/pizza/src/analysis/metrics.py
[2025-05-14 12:54:23,639] [INFO] Validating script: models.py
[2025-05-14 12:54:23,876] [WARNING] Missing or incomplete docstring in /home/emilio/Documents/ai/pizza/src/chatlist_ki/models.py
[2025-05-14 12:54:23,876] [WARNING] Validation passed with warnings for /home/emilio/Documents/ai/pizza/src/chatlist_ki/models.py
[2025-05-14 12:54:23,876] [INFO] Validating script: __main__.py
[2025-05-14 12:54:23,877] [WARNING] Missing dependencies in /home/emilio/Documents/ai/pizza/src/chatlist_ki/__main__.py: chat_interface, models, database
[2025-05-14 12:54:23,885] [WARNING] Execution test issue in /home/emilio/Documents/ai/pizza/src/chatlist_ki/__main__.py: Execution failed with error: Traceback (most recent call last):
  File "/home/emilio/Documents/ai/pizza/src/chatlist_ki/__main__.py", line 1, in <module>
    from .chat_interface import ChatInterface
ImportError: attempted relative import with no known parent package

[2025-05-14 12:54:23,885] [WARNING] Missing or incomplete docstring in /home/emilio/Documents/ai/pizza/src/chatlist_ki/__main__.py
[2025-05-14 12:54:23,885] [WARNING] Validation passed with warnings for /home/emilio/Documents/ai/pizza/src/chatlist_ki/__main__.py
[2025-05-14 12:54:23,885] [INFO] Validating script: __init__.py
[2025-05-14 12:54:23,885] [WARNING] Missing dependencies in /home/emilio/Documents/ai/pizza/src/chatlist_ki/__init__.py: database, models, chat_interface
[2025-05-14 12:54:23,894] [WARNING] Execution test issue in /home/emilio/Documents/ai/pizza/src/chatlist_ki/__init__.py: Execution failed with error: Traceback (most recent call last):
  File "/home/emilio/Documents/ai/pizza/src/chatlist_ki/__init__.py", line 1, in <module>
    from .models import Task, TaskStatus
ImportError: attempted relative import with no known parent package

[2025-05-14 12:54:23,895] [WARNING] Missing or incomplete docstring in /home/emilio/Documents/ai/pizza/src/chatlist_ki/__init__.py
[2025-05-14 12:54:23,895] [WARNING] Validation passed with warnings for /home/emilio/Documents/ai/pizza/src/chatlist_ki/__init__.py
[2025-05-14 12:54:23,895] [INFO] Validating script: api.py
[2025-05-14 12:54:24,018] [WARNING] Missing dependencies in /home/emilio/Documents/ai/pizza/src/chatlist_ki/api.py: models, database
[2025-05-14 12:54:24,215] [WARNING] Execution test issue in /home/emilio/Documents/ai/pizza/src/chatlist_ki/api.py: Execution failed with error: Traceback (most recent call last):
  File "/home/emilio/Documents/ai/pizza/src/chatlist_ki/api.py", line 5, in <module>
    from .database import Database, TaskManager
ImportError: attempted relative import with no known parent package

[2025-05-14 12:54:24,216] [WARNING] Missing or incomplete docstring in /home/emilio/Documents/ai/pizza/src/chatlist_ki/api.py
[2025-05-14 12:54:24,216] [WARNING] Validation passed with warnings for /home/emilio/Documents/ai/pizza/src/chatlist_ki/api.py
[2025-05-14 12:54:24,216] [INFO] Validating script: database.py
[2025-05-14 12:54:24,219] [WARNING] Missing dependencies in /home/emilio/Documents/ai/pizza/src/chatlist_ki/database.py: models
[2025-05-14 12:54:24,395] [WARNING] Execution test issue in /home/emilio/Documents/ai/pizza/src/chatlist_ki/database.py: Execution failed with error: Traceback (most recent call last):
  File "/home/emilio/Documents/ai/pizza/src/chatlist_ki/database.py", line 4, in <module>
    from .models import Base, Task, TaskStatus
ImportError: attempted relative import with no known parent package

[2025-05-14 12:54:24,396] [WARNING] Missing or incomplete docstring in /home/emilio/Documents/ai/pizza/src/chatlist_ki/database.py
[2025-05-14 12:54:24,396] [WARNING] Validation passed with warnings for /home/emilio/Documents/ai/pizza/src/chatlist_ki/database.py
[2025-05-14 12:54:24,396] [INFO] Validating script: chat_interface.py
[2025-05-14 12:54:24,399] [WARNING] Missing dependencies in /home/emilio/Documents/ai/pizza/src/chatlist_ki/chat_interface.py: models, database
[2025-05-14 12:54:24,416] [WARNING] Execution test issue in /home/emilio/Documents/ai/pizza/src/chatlist_ki/chat_interface.py: Execution failed with error: Traceback (most recent call last):
  File "/home/emilio/Documents/ai/pizza/src/chatlist_ki/chat_interface.py", line 2, in <module>
    from .database import TaskManager, Database
ImportError: attempted relative import with no known parent package

[2025-05-14 12:54:24,417] [WARNING] Missing or incomplete docstring in /home/emilio/Documents/ai/pizza/src/chatlist_ki/chat_interface.py
[2025-05-14 12:54:24,417] [WARNING] Validation passed with warnings for /home/emilio/Documents/ai/pizza/src/chatlist_ki/chat_interface.py
[2025-05-14 12:54:24,417] [INFO] Validating script: status_display.py
[2025-05-14 12:54:24,424] [WARNING] Missing dependencies in /home/emilio/Documents/ai/pizza/src/visualization/status_display.py: ssd1306, machine
[2025-05-14 12:54:24,454] [WARNING] Execution test issue in /home/emilio/Documents/ai/pizza/src/visualization/status_display.py: Execution failed with error: Traceback (most recent call last):
  File "/home/emilio/Documents/ai/pizza/src/visualization/status_display.py", line 22, in <module>
    from src.types import InferenceResult
ModuleNotFoundError: No module named 'src'

[2025-05-14 12:54:24,456] [WARNING] Validation passed with warnings for /home/emilio/Documents/ai/pizza/src/visualization/status_display.py
[2025-05-14 12:54:24,456] [INFO] Validating script: visualization.py
[2025-05-14 12:54:24,466] [WARNING] Missing dependencies in /home/emilio/Documents/ai/pizza/src/visualization/visualization.py: constants
[2025-05-14 12:54:26,187] [WARNING] Execution test issue in /home/emilio/Documents/ai/pizza/src/visualization/visualization.py: Execution failed with error: Traceback (most recent call last):
  File "/home/emilio/Documents/ai/pizza/src/visualization/visualization.py", line 15, in <module>
    from .types import (
ImportError: attempted relative import with no known parent package

[2025-05-14 12:54:26,189] [WARNING] Validation passed with warnings for /home/emilio/Documents/ai/pizza/src/visualization/visualization.py
[2025-05-14 12:54:26,189] [INFO] Validating script: exceptions.py
[2025-05-14 12:54:26,206] [INFO] Validation passed for /home/emilio/Documents/ai/pizza/src/utils/exceptions.py
[2025-05-14 12:54:26,206] [INFO] Validating script: types.py
[2025-05-14 12:54:26,230] [WARNING] Execution test issue in /home/emilio/Documents/ai/pizza/src/utils/types.py: Execution failed with error: Traceback (most recent call last):
  File "/home/emilio/Documents/ai/pizza/src/utils/types.py", line 6, in <module>
    from typing import Dict as Dict
  File "/usr/lib/python3.12/typing.py", line 27, in <module>
    import contextlib
  File "/usr/lib/python3.12/contextlib.py", line 7, in <module>
    from functools import wraps
  File "/usr/lib/python3.12/functools.py", line 22, in <module>
    from types import GenericAlias
  File "/home/emilio/Documents/ai/pizza/src/utils/types.py", line 6, in <module>
    from typing import Dict as Dict
ImportError: cannot import name 'Dict' from partially initialized module 'typing' (most likely due to a circular import) (/usr/lib/python3.12/typing.py)

[2025-05-14 12:54:26,231] [WARNING] Validation passed with warnings for /home/emilio/Documents/ai/pizza/src/utils/types.py
[2025-05-14 12:54:26,231] [INFO] Validating script: power_manager.py
[2025-05-14 12:54:26,238] [WARNING] Missing dependencies in /home/emilio/Documents/ai/pizza/src/utils/power_manager.py: devices, constants, metrics
[2025-05-14 12:54:26,258] [WARNING] Execution test issue in /home/emilio/Documents/ai/pizza/src/utils/power_manager.py: Execution failed with error: Traceback (most recent call last):
  File "/home/emilio/Documents/ai/pizza/src/utils/power_manager.py", line 7, in <module>
    import logging
  File "/usr/lib/python3.12/logging/__init__.py", line 26, in <module>
    import sys, os, time, io, re, traceback, warnings, weakref, collections.abc
  File "/usr/lib/python3.12/re/__init__.py", line 124, in <module>
    import enum
  File "/usr/lib/python3.12/enum.py", line 3, in <module>
    from types import MappingProxyType, DynamicClassAttribute
  File "/home/emilio/Documents/ai/pizza/src/utils/types.py", line 6, in <module>
    from typing import Dict as Dict
  File "/usr/lib/python3.12/typing.py", line 27, in <module>
    import contextlib
  File "/usr/lib/python3.12/contextlib.py", line 7, in <module>
    from functools import wraps
  File "/usr/lib/python3.12/functools.py", line 22, in <module>
    from types import GenericAlias
ImportError: cannot import name 'GenericAlias' from partially initialized module 'types' (most likely due to a circular import) (/home/emilio/Documents/ai/pizza/src/utils/types.py)

[2025-05-14 12:54:26,260] [WARNING] Validation passed with warnings for /home/emilio/Documents/ai/pizza/src/utils/power_manager.py
[2025-05-14 12:54:26,260] [INFO] Validating script: devices.py
[2025-05-14 12:54:26,262] [WARNING] Missing dependencies in /home/emilio/Documents/ai/pizza/src/utils/devices.py: exceptions, constants
[2025-05-14 12:54:26,278] [WARNING] Execution test issue in /home/emilio/Documents/ai/pizza/src/utils/devices.py: Execution failed with error: Traceback (most recent call last):
  File "/home/emilio/Documents/ai/pizza/src/utils/devices.py", line 6, in <module>
    import logging
  File "/usr/lib/python3.12/logging/__init__.py", line 26, in <module>
    import sys, os, time, io, re, traceback, warnings, weakref, collections.abc
  File "/usr/lib/python3.12/re/__init__.py", line 124, in <module>
    import enum
  File "/usr/lib/python3.12/enum.py", line 3, in <module>
    from types import MappingProxyType, DynamicClassAttribute
  File "/home/emilio/Documents/ai/pizza/src/utils/types.py", line 6, in <module>
    from typing import Dict as Dict
  File "/usr/lib/python3.12/typing.py", line 27, in <module>
    import contextlib
  File "/usr/lib/python3.12/contextlib.py", line 7, in <module>
    from functools import wraps
  File "/usr/lib/python3.12/functools.py", line 22, in <module>
    from types import GenericAlias
ImportError: cannot import name 'GenericAlias' from partially initialized module 'types' (most likely due to a circular import) (/home/emilio/Documents/ai/pizza/src/utils/types.py)

[2025-05-14 12:54:26,279] [WARNING] Validation passed with warnings for /home/emilio/Documents/ai/pizza/src/utils/devices.py
[2025-05-14 12:54:26,279] [INFO] Validating script: validation.py
[2025-05-14 12:54:26,282] [WARNING] Missing dependencies in /home/emilio/Documents/ai/pizza/src/utils/validation.py: exceptions, constants
[2025-05-14 12:54:26,302] [WARNING] Execution test issue in /home/emilio/Documents/ai/pizza/src/utils/validation.py: Execution failed with error: Traceback (most recent call last):
  File "/home/emilio/Documents/ai/pizza/src/utils/validation.py", line 6, in <module>
    import json
  File "/usr/lib/python3.12/json/__init__.py", line 106, in <module>
    from .decoder import JSONDecoder, JSONDecodeError
  File "/usr/lib/python3.12/json/decoder.py", line 3, in <module>
    import re
  File "/usr/lib/python3.12/re/__init__.py", line 124, in <module>
    import enum
  File "/usr/lib/python3.12/enum.py", line 3, in <module>
    from types import MappingProxyType, DynamicClassAttribute
  File "/home/emilio/Documents/ai/pizza/src/utils/types.py", line 6, in <module>
    from typing import Dict as Dict
  File "/usr/lib/python3.12/typing.py", line 27, in <module>
    import contextlib
  File "/usr/lib/python3.12/contextlib.py", line 7, in <module>
    from functools import wraps
  File "/usr/lib/python3.12/functools.py", line 22, in <module>
    from types import GenericAlias
ImportError: cannot import name 'GenericAlias' from partially initialized module 'types' (most likely due to a circular import) (/home/emilio/Documents/ai/pizza/src/utils/types.py)

[2025-05-14 12:54:26,303] [WARNING] Validation passed with warnings for /home/emilio/Documents/ai/pizza/src/utils/validation.py
[2025-05-14 12:54:26,304] [INFO] Validating script: memory.py
[2025-05-14 12:54:26,306] [WARNING] Missing dependencies in /home/emilio/Documents/ai/pizza/src/utils/memory.py: exceptions, constants
[2025-05-14 12:54:26,321] [WARNING] Execution test issue in /home/emilio/Documents/ai/pizza/src/utils/memory.py: Execution failed with error: Traceback (most recent call last):
  File "/home/emilio/Documents/ai/pizza/src/utils/memory.py", line 5, in <module>
    import torch
  File "/home/emilio/Documents/ai/pizza/.venv/lib/python3.12/site-packages/torch/__init__.py", line 14, in <module>
    import ctypes
  File "/usr/lib/python3.12/ctypes/__init__.py", line 4, in <module>
    import types as _types
  File "/home/emilio/Documents/ai/pizza/src/utils/types.py", line 6, in <module>
    from typing import Dict as Dict
  File "/usr/lib/python3.12/typing.py", line 27, in <module>
    import contextlib
  File "/usr/lib/python3.12/contextlib.py", line 7, in <module>
    from functools import wraps
  File "/usr/lib/python3.12/functools.py", line 22, in <module>
    from types import GenericAlias
ImportError: cannot import name 'GenericAlias' from partially initialized module 'types' (most likely due to a circular import) (/home/emilio/Documents/ai/pizza/src/utils/types.py)

[2025-05-14 12:54:26,322] [WARNING] Validation passed with warnings for /home/emilio/Documents/ai/pizza/src/utils/memory.py
[2025-05-14 12:54:26,322] [INFO] Validating script: temporal_smoother.py
[2025-05-14 12:54:26,342] [WARNING] Execution test issue in /home/emilio/Documents/ai/pizza/src/utils/temporal_smoother.py: Execution failed with error: Traceback (most recent call last):
  File "/home/emilio/Documents/ai/pizza/src/utils/temporal_smoother.py", line 9, in <module>
    import numpy as np
  File "/home/emilio/Documents/ai/pizza/.venv/lib/python3.12/site-packages/numpy/__init__.py", line 92, in <module>
    from ._globals import _NoValue, _CopyMode
  File "/home/emilio/Documents/ai/pizza/.venv/lib/python3.12/site-packages/numpy/_globals.py", line 18, in <module>
    import enum
  File "/usr/lib/python3.12/enum.py", line 3, in <module>
    from types import MappingProxyType, DynamicClassAttribute
  File "/home/emilio/Documents/ai/pizza/src/utils/types.py", line 6, in <module>
    from typing import Dict as Dict
  File "/usr/lib/python3.12/typing.py", line 27, in <module>
    import contextlib
  File "/usr/lib/python3.12/contextlib.py", line 7, in <module>
    from functools import wraps
  File "/usr/lib/python3.12/functools.py", line 22, in <module>
    from types import GenericAlias
ImportError: cannot import name 'GenericAlias' from partially initialized module 'types' (most likely due to a circular import) (/home/emilio/Documents/ai/pizza/src/utils/types.py)

[2025-05-14 12:54:26,344] [WARNING] Validation passed with warnings for /home/emilio/Documents/ai/pizza/src/utils/temporal_smoother.py
[2025-05-14 12:54:26,344] [INFO] Validating script: utils.py
[2025-05-14 12:54:26,361] [WARNING] Execution test issue in /home/emilio/Documents/ai/pizza/src/utils/utils.py: Execution failed with error: Traceback (most recent call last):
  File "/home/emilio/Documents/ai/pizza/src/utils/utils.py", line 6, in <module>
    import logging
  File "/usr/lib/python3.12/logging/__init__.py", line 26, in <module>
    import sys, os, time, io, re, traceback, warnings, weakref, collections.abc
  File "/usr/lib/python3.12/re/__init__.py", line 124, in <module>
    import enum
  File "/usr/lib/python3.12/enum.py", line 3, in <module>
    from types import MappingProxyType, DynamicClassAttribute
  File "/home/emilio/Documents/ai/pizza/src/utils/types.py", line 6, in <module>
    from typing import Dict as Dict
  File "/usr/lib/python3.12/typing.py", line 27, in <module>
    import contextlib
  File "/usr/lib/python3.12/contextlib.py", line 7, in <module>
    from functools import wraps
  File "/usr/lib/python3.12/functools.py", line 22, in <module>
    from types import GenericAlias
ImportError: cannot import name 'GenericAlias' from partially initialized module 'types' (most likely due to a circular import) (/home/emilio/Documents/ai/pizza/src/utils/types.py)

[2025-05-14 12:54:26,361] [WARNING] Validation passed with warnings for /home/emilio/Documents/ai/pizza/src/utils/utils.py
[2025-05-14 12:54:26,362] [INFO] Validating script: constants.py
[2025-05-14 12:54:26,377] [WARNING] Execution test issue in /home/emilio/Documents/ai/pizza/src/utils/constants.py: Execution failed with error: Traceback (most recent call last):
  File "/home/emilio/Documents/ai/pizza/src/utils/constants.py", line 5, in <module>
    from pathlib import Path
  File "/usr/lib/python3.12/pathlib.py", line 8, in <module>
    import fnmatch
  File "/usr/lib/python3.12/fnmatch.py", line 14, in <module>
    import re
  File "/usr/lib/python3.12/re/__init__.py", line 124, in <module>
    import enum
  File "/usr/lib/python3.12/enum.py", line 3, in <module>
    from types import MappingProxyType, DynamicClassAttribute
  File "/home/emilio/Documents/ai/pizza/src/utils/types.py", line 6, in <module>
    from typing import Dict as Dict
  File "/usr/lib/python3.12/typing.py", line 27, in <module>
    import contextlib
  File "/usr/lib/python3.12/contextlib.py", line 7, in <module>
    from functools import wraps
  File "/usr/lib/python3.12/functools.py", line 22, in <module>
    from types import GenericAlias
ImportError: cannot import name 'GenericAlias' from partially initialized module 'types' (most likely due to a circular import) (/home/emilio/Documents/ai/pizza/src/utils/types.py)

[2025-05-14 12:54:26,378] [WARNING] Validation passed with warnings for /home/emilio/Documents/ai/pizza/src/utils/constants.py
[2025-05-14 12:54:26,378] [INFO] Validating script: enhanced_pizza_augmentation.py
[2025-05-14 12:54:28,485] [WARNING] Execution test issue in /home/emilio/Documents/ai/pizza/src/augmentation/enhanced_pizza_augmentation.py: Execution failed with error: 
[2025-05-14 12:54:28,495] [WARNING] Missing or incomplete docstring in /home/emilio/Documents/ai/pizza/src/augmentation/enhanced_pizza_augmentation.py
[2025-05-14 12:54:28,495] [WARNING] Validation passed with warnings for /home/emilio/Documents/ai/pizza/src/augmentation/enhanced_pizza_augmentation.py
[2025-05-14 12:54:28,495] [INFO] Validating script: augmentation_optimized.py
[2025-05-14 12:54:31,395] [WARNING] Missing or incomplete docstring in /home/emilio/Documents/ai/pizza/src/augmentation/augmentation_optimized.py
[2025-05-14 12:54:31,396] [WARNING] Validation passed with warnings for /home/emilio/Documents/ai/pizza/src/augmentation/augmentation_optimized.py
[2025-05-14 12:54:31,396] [INFO] Validating script: diffusion_pizza_generator.py
[2025-05-14 12:54:35,854] [INFO] Validation passed for /home/emilio/Documents/ai/pizza/src/augmentation/diffusion_pizza_generator.py
[2025-05-14 12:54:35,854] [INFO] Validating script: augmentation.py
[2025-05-14 12:54:37,984] [WARNING] Execution test issue in /home/emilio/Documents/ai/pizza/src/augmentation/augmentation.py: Execution failed with error: 
[2025-05-14 12:54:37,993] [WARNING] Missing or incomplete docstring in /home/emilio/Documents/ai/pizza/src/augmentation/augmentation.py
[2025-05-14 12:54:37,993] [WARNING] Validation passed with warnings for /home/emilio/Documents/ai/pizza/src/augmentation/augmentation.py
[2025-05-14 12:54:37,993] [INFO] Validating script: advanced_pizza_diffusion_control.py
[2025-05-14 12:54:39,745] [WARNING] Execution test issue in /home/emilio/Documents/ai/pizza/src/augmentation/advanced_pizza_diffusion_control.py: Execution failed with error: Traceback (most recent call last):
  File "/home/emilio/Documents/ai/pizza/src/augmentation/advanced_pizza_diffusion_control.py", line 36, in <module>
    from src.augmentation.diffusion_pizza_generator import PizzaDiffusionGenerator, PIZZA_STAGES
ModuleNotFoundError: No module named 'src'

[2025-05-14 12:54:39,749] [WARNING] Validation passed with warnings for /home/emilio/Documents/ai/pizza/src/augmentation/advanced_pizza_diffusion_control.py
[2025-05-14 12:54:39,749] [INFO] Validating script: optimized-pizza-augmentation.py
[2025-05-14 12:54:41,985] [WARNING] Execution test issue in /home/emilio/Documents/ai/pizza/src/augmentation/optimized-pizza-augmentation.py: Execution failed with error: Traceback (most recent call last):
  File "/home/emilio/Documents/ai/pizza/src/augmentation/optimized-pizza-augmentation.py", line 698, in <module>
    main()
  File "/home/emilio/Documents/ai/pizza/src/augmentation/optimized-pizza-augmentation.py", line 688, in main
    augment_pizza_dataset(input_dir, output_dir, img_per_original=img_per_original, batch_size=batch_size)
  File "/home/emilio/Documents/ai/pizza/src/augmentation/optimized-pizza-augmentation.py", line 512, in augment_pizza_dataset
    image_files = [os.path.join(input_dir, f) for f in os.listdir(input_dir) 
                                                       ^^^^^^^^^^^^^^^^^^^^^
FileNotFoundError: [Errno 2] No such file or directory: '/home/emilio/Documents/ai/pizza/img-pizza/'

[2025-05-14 12:54:41,988] [WARNING] Missing or incomplete docstring in /home/emilio/Documents/ai/pizza/src/augmentation/optimized-pizza-augmentation.py
[2025-05-14 12:54:41,988] [WARNING] Validation passed with warnings for /home/emilio/Documents/ai/pizza/src/augmentation/optimized-pizza-augmentation.py
[2025-05-14 12:54:41,988] [INFO] Validating script: augment_legacy.py
[2025-05-14 12:54:47,052] [WARNING] Execution test issue in /home/emilio/Documents/ai/pizza/src/legacy/augment_legacy.py: Execution timed out (> 5 seconds)
[2025-05-14 12:54:47,054] [WARNING] Missing or incomplete docstring in /home/emilio/Documents/ai/pizza/src/legacy/augment_legacy.py
[2025-05-14 12:54:47,054] [WARNING] Validation passed with warnings for /home/emilio/Documents/ai/pizza/src/legacy/augment_legacy.py
[2025-05-14 12:54:47,054] [INFO] Validating script: diffusion_data_agent.py
[2025-05-14 12:54:47,061] [WARNING] Missing dependencies in /home/emilio/Documents/ai/pizza/src/integration/diffusion_data_agent.py: cleanfid
[2025-05-14 12:54:48,778] [WARNING] Validation passed with warnings for /home/emilio/Documents/ai/pizza/src/integration/diffusion_data_agent.py
[2025-05-14 12:54:48,778] [INFO] Validating script: pizza_diffusion_integration.py
[2025-05-14 12:54:48,784] [WARNING] Missing dependencies in /home/emilio/Documents/ai/pizza/src/integration/pizza_diffusion_integration.py: optimized_pizza_augmentation, diffusion_data_agent, enhanced_pizza_augmentation
[2025-05-14 12:54:50,477] [WARNING] Execution test issue in /home/emilio/Documents/ai/pizza/src/integration/pizza_diffusion_integration.py: Execution failed with error: Traceback (most recent call last):
  File "/home/emilio/Documents/ai/pizza/src/integration/pizza_diffusion_integration.py", line 29, in <module>
    from enhanced_pizza_augmentation import (
ModuleNotFoundError: No module named 'enhanced_pizza_augmentation'

During handling of the above exception, another exception occurred:

Traceback (most recent call last):
  File "/home/emilio/Documents/ai/pizza/src/integration/pizza_diffusion_integration.py", line 40, in <module>
    from optimized_pizza_augmentation import (
ModuleNotFoundError: No module named 'optimized_pizza_augmentation'

During handling of the above exception, another exception occurred:

Traceback (most recent call last):
  File "/home/emilio/Documents/ai/pizza/src/integration/pizza_diffusion_integration.py", line 49, in <module>
    from test import (
ImportError: cannot import name 'PizzaBurningEffect' from 'test' (/usr/lib/python3.12/test/__init__.py)

[2025-05-14 12:54:50,479] [WARNING] Validation passed with warnings for /home/emilio/Documents/ai/pizza/src/integration/pizza_diffusion_integration.py
[2025-05-14 12:54:50,481] [INFO] Validating script: diffusion_training_integration.py
[2025-05-14 12:54:54,986] [INFO] Validation passed for /home/emilio/Documents/ai/pizza/src/integration/diffusion_training_integration.py
[2025-05-14 12:54:54,987] [INFO] Validation complete. Summary: 28 passed, 47 with warnings, 0 failed
[2025-05-14 12:54:54,988] [INFO] Report written to /home/emilio/Documents/ai/pizza/output/pipeline_runs/20250514_125320/reports/validation_report.json
