[2025-05-14 12:48:16,947] [INFO] Found 75 Python scripts to validate
[2025-05-14 12:48:16,947] [INFO] Validating script: cleanup.py
[2025-05-14 12:48:17,125] [INFO] Validation passed for /home/emilio/Documents/ai/pizza/scripts/cleanup.py
[2025-05-14 12:48:17,125] [INFO] Validating script: filter_dataset.py
[2025-05-14 12:48:17,135] [WARNING] Missing or incomplete docstring in /home/emilio/Documents/ai/pizza/scripts/filter_dataset.py
[2025-05-14 12:48:17,135] [WARNING] Validation passed with warnings for /home/emilio/Documents/ai/pizza/scripts/filter_dataset.py
[2025-05-14 12:48:17,135] [INFO] Validating script: label_tool.py
[2025-05-14 12:48:19,248] [INFO] Validation passed for /home/emilio/Documents/ai/pizza/scripts/label_tool.py
[2025-05-14 12:48:19,248] [INFO] Validating script: framebuffer_demo.py
[2025-05-14 12:48:19,358] [WARNING] Execution test issue in /home/emilio/Documents/ai/pizza/scripts/framebuffer_demo.py: Execution failed with error: 
[2025-05-14 12:48:19,359] [WARNING] Validation passed with warnings for /home/emilio/Documents/ai/pizza/scripts/framebuffer_demo.py
[2025-05-14 12:48:19,359] [INFO] Validating script: compare_inverted_residual.py
[2025-05-14 12:48:23,004] [INFO] Validation passed for /home/emilio/Documents/ai/pizza/scripts/compare_inverted_residual.py
[2025-05-14 12:48:23,004] [INFO] Validating script: test_temporal_smoothing.py
[2025-05-14 12:48:23,313] [INFO] Validation passed for /home/emilio/Documents/ai/pizza/scripts/test_temporal_smoothing.py
[2025-05-14 12:48:23,313] [INFO] Validating script: knowledge_distillation.py
[2025-05-14 12:48:25,202] [INFO] Validation passed for /home/emilio/Documents/ai/pizza/scripts/knowledge_distillation.py
[2025-05-14 12:48:25,202] [INFO] Validating script: visualize_gradcam.py
[2025-05-14 12:48:25,789] [WARNING] Missing dependencies in /home/emilio/Documents/ai/pizza/scripts/visualize_gradcam.py: scripts
[2025-05-14 12:48:28,165] [WARNING] Validation passed with warnings for /home/emilio/Documents/ai/pizza/scripts/visualize_gradcam.py
[2025-05-14 12:48:28,165] [INFO] Validating script: classify_images.py
[2025-05-14 12:48:28,176] [WARNING] Missing or incomplete docstring in /home/emilio/Documents/ai/pizza/scripts/classify_images.py
[2025-05-14 12:48:28,176] [WARNING] Validation passed with warnings for /home/emilio/Documents/ai/pizza/scripts/classify_images.py
[2025-05-14 12:48:28,177] [INFO] Validating script: visualize_pruning.py
[2025-05-14 12:48:30,512] [INFO] Validation passed for /home/emilio/Documents/ai/pizza/scripts/visualize_pruning.py
[2025-05-14 12:48:30,512] [INFO] Validating script: compare_tiny_cnns.py
[2025-05-14 12:48:30,542] [WARNING] Missing dependencies in /home/emilio/Documents/ai/pizza/scripts/compare_tiny_cnns.py: scripts
[2025-05-14 12:48:33,091] [WARNING] Validation passed with warnings for /home/emilio/Documents/ai/pizza/scripts/compare_tiny_cnns.py
[2025-05-14 12:48:33,092] [INFO] Validating script: compare_se_models.py
[2025-05-14 12:48:35,753] [INFO] Validation passed for /home/emilio/Documents/ai/pizza/scripts/compare_se_models.py
[2025-05-14 12:48:35,753] [INFO] Validating script: automated_test_suite.py
[2025-05-14 12:48:38,388] [WARNING] Execution test issue in /home/emilio/Documents/ai/pizza/scripts/automated_test_suite.py: Execution failed with error: Traceback (most recent call last):
  File "/home/emilio/Documents/ai/pizza/scripts/automated_test_suite.py", line 53, in <module>
    from src.pizza_detector import (
ImportError: cannot import name 'load_model' from 'src.pizza_detector' (/home/emilio/Documents/ai/pizza/src/pizza_detector.py)

[2025-05-14 12:48:38,392] [WARNING] Validation passed with warnings for /home/emilio/Documents/ai/pizza/scripts/automated_test_suite.py
[2025-05-14 12:48:38,392] [INFO] Validating script: compare_hard_swish.py
[2025-05-14 12:48:40,984] [INFO] Validation passed for /home/emilio/Documents/ai/pizza/scripts/compare_hard_swish.py
[2025-05-14 12:48:40,984] [INFO] Validating script: demo_status_display.py
[2025-05-14 12:48:41,016] [WARNING] Execution test issue in /home/emilio/Documents/ai/pizza/scripts/demo_status_display.py: Execution failed with error: Traceback (most recent call last):
  File "/home/emilio/Documents/ai/pizza/scripts/demo_status_display.py", line 38, in <module>
    from src.status_display import (
ModuleNotFoundError: No module named 'src.status_display'

[2025-05-14 12:48:41,017] [WARNING] Validation passed with warnings for /home/emilio/Documents/ai/pizza/scripts/demo_status_display.py
[2025-05-14 12:48:41,017] [INFO] Validating script: test_image_preprocessing.py
[2025-05-14 12:48:41,334] [INFO] Validation passed for /home/emilio/Documents/ai/pizza/scripts/test_image_preprocessing.py
[2025-05-14 12:48:41,334] [INFO] Validating script: test_pizza_detection.py
[2025-05-14 12:48:43,337] [WARNING] Execution test issue in /home/emilio/Documents/ai/pizza/scripts/test_pizza_detection.py: Execution failed with error: Traceback (most recent call last):
  File "/home/emilio/Documents/ai/pizza/scripts/test_pizza_detection.py", line 27, in <module>
    from src.types import InferenceResult
ModuleNotFoundError: No module named 'src.types'

[2025-05-14 12:48:43,338] [WARNING] Validation passed with warnings for /home/emilio/Documents/ai/pizza/scripts/test_pizza_detection.py
[2025-05-14 12:48:43,339] [INFO] Validating script: demo_power_management.py
[2025-05-14 12:48:43,657] [WARNING] Execution test issue in /home/emilio/Documents/ai/pizza/scripts/demo_power_management.py: Execution failed with error: Traceback (most recent call last):
  File "/home/emilio/Documents/ai/pizza/scripts/demo_power_management.py", line 19, in <module>
    from src.emulator import RP2040Emulator
ModuleNotFoundError: No module named 'src.emulator'

[2025-05-14 12:48:43,659] [WARNING] Validation passed with warnings for /home/emilio/Documents/ai/pizza/scripts/demo_power_management.py
[2025-05-14 12:48:43,659] [INFO] Validating script: analyze_performance_logs.py
[2025-05-14 12:48:44,411] [INFO] Validation passed for /home/emilio/Documents/ai/pizza/scripts/analyze_performance_logs.py
[2025-05-14 12:48:44,411] [INFO] Validating script: simulate_memory_constraints.py
[2025-05-14 12:48:44,705] [WARNING] Execution test issue in /home/emilio/Documents/ai/pizza/scripts/simulate_memory_constraints.py: Execution failed with error: Traceback (most recent call last):
  File "/home/emilio/Documents/ai/pizza/scripts/simulate_memory_constraints.py", line 17, in <module>
    from src.constants import (
ImportError: cannot import name 'RP2040_CLOCK_SPEED_MHZ' from 'src.constants' (/home/emilio/Documents/ai/pizza/src/constants.py). Did you mean: 'RP2040_CLOCK_SPEED'?

[2025-05-14 12:48:44,707] [WARNING] Validation passed with warnings for /home/emilio/Documents/ai/pizza/scripts/simulate_memory_constraints.py
[2025-05-14 12:48:44,707] [INFO] Validating script: simulate_clahe_resources.py
[2025-05-14 12:48:45,024] [INFO] Validation passed for /home/emilio/Documents/ai/pizza/scripts/simulate_clahe_resources.py
[2025-05-14 12:48:45,024] [INFO] Validating script: run_pizza_tests.py
[2025-05-14 12:48:45,053] [INFO] Validation passed for /home/emilio/Documents/ai/pizza/scripts/run_pizza_tests.py
[2025-05-14 12:48:45,053] [INFO] Validating script: run_pruning_clustering.py
[2025-05-14 12:48:45,055] [WARNING] Missing dependencies in /home/emilio/Documents/ai/pizza/scripts/run_pruning_clustering.py: config, scripts
[2025-05-14 12:48:47,066] [WARNING] Validation passed with warnings for /home/emilio/Documents/ai/pizza/scripts/run_pruning_clustering.py
[2025-05-14 12:48:47,067] [INFO] Validating script: augment_dataset.py
[2025-05-14 12:48:47,160] [INFO] Validation passed for /home/emilio/Documents/ai/pizza/scripts/augment_dataset.py
[2025-05-14 12:48:47,160] [INFO] Validating script: train_pizza_model.py
[2025-05-14 12:48:49,172] [INFO] Validation passed for /home/emilio/Documents/ai/pizza/scripts/train_pizza_model.py
[2025-05-14 12:48:49,173] [INFO] Validating script: simulate_lighting_conditions.py
[2025-05-14 12:48:49,510] [WARNING] Execution test issue in /home/emilio/Documents/ai/pizza/scripts/simulate_lighting_conditions.py: Execution failed with error: Traceback (most recent call last):
  File "/home/emilio/Documents/ai/pizza/scripts/simulate_lighting_conditions.py", line 17, in <module>
    from src.emulator import RP2040Emulator
ModuleNotFoundError: No module named 'src.emulator'

[2025-05-14 12:48:49,511] [WARNING] Validation passed with warnings for /home/emilio/Documents/ai/pizza/scripts/simulate_lighting_conditions.py
[2025-05-14 12:48:49,512] [INFO] Validating script: quantization_aware_training.py
[2025-05-14 12:48:51,574] [INFO] Validation passed for /home/emilio/Documents/ai/pizza/scripts/quantization_aware_training.py
[2025-05-14 12:48:51,574] [INFO] Validating script: simulate_power_consumption.py
[2025-05-14 12:48:51,904] [WARNING] Execution test issue in /home/emilio/Documents/ai/pizza/scripts/simulate_power_consumption.py: Execution failed with error: Traceback (most recent call last):
  File "/home/emilio/Documents/ai/pizza/scripts/simulate_power_consumption.py", line 18, in <module>
    from src.constants import (
ImportError: cannot import name 'RP2040_CLOCK_SPEED_MHZ' from 'src.constants' (/home/emilio/Documents/ai/pizza/src/constants.py). Did you mean: 'RP2040_CLOCK_SPEED'?

[2025-05-14 12:48:51,905] [WARNING] Validation passed with warnings for /home/emilio/Documents/ai/pizza/scripts/simulate_power_consumption.py
[2025-05-14 12:48:51,905] [INFO] Validating script: generate_pizza_dataset.py
[2025-05-14 12:48:56,636] [INFO] Validation passed for /home/emilio/Documents/ai/pizza/scripts/generate_pizza_dataset.py
[2025-05-14 12:48:56,636] [INFO] Validating script: hyperparameter_search.py
[2025-05-14 12:48:59,222] [INFO] Validation passed for /home/emilio/Documents/ai/pizza/scripts/hyperparameter_search.py
[2025-05-14 12:48:59,222] [INFO] Validating script: extract_frames.py
[2025-05-14 12:48:59,235] [WARNING] Missing or incomplete docstring in /home/emilio/Documents/ai/pizza/scripts/extract_frames.py
[2025-05-14 12:48:59,236] [WARNING] Validation passed with warnings for /home/emilio/Documents/ai/pizza/scripts/extract_frames.py
[2025-05-14 12:48:59,236] [INFO] Validating script: validate_integration.py
[2025-05-14 12:48:59,276] [INFO] Validation passed for /home/emilio/Documents/ai/pizza/scripts/ci/validate_integration.py
[2025-05-14 12:48:59,276] [INFO] Validating script: validate_scripts.py
[2025-05-14 12:48:59,363] [INFO] Validation passed for /home/emilio/Documents/ai/pizza/scripts/ci/validate_scripts.py
[2025-05-14 12:48:59,363] [INFO] Validating script: generate_pipeline_report.py
[2025-05-14 12:48:59,671] [INFO] Validation passed for /home/emilio/Documents/ai/pizza/scripts/ci/generate_pipeline_report.py
[2025-05-14 12:48:59,671] [INFO] Validating script: generate_optimization_summary.py
[2025-05-14 12:48:59,977] [INFO] Validation passed for /home/emilio/Documents/ai/pizza/scripts/ci/generate_optimization_summary.py
[2025-05-14 12:48:59,977] [INFO] Validating script: weight_pruning.py
[2025-05-14 12:48:59,986] [WARNING] Missing dependencies in /home/emilio/Documents/ai/pizza/scripts/model_optimization/weight_pruning.py: config
[2025-05-14 12:49:02,006] [WARNING] Validation passed with warnings for /home/emilio/Documents/ai/pizza/scripts/model_optimization/weight_pruning.py
[2025-05-14 12:49:02,006] [INFO] Validating script: micropizzanet_early_exit.py
[2025-05-14 12:49:04,028] [INFO] Validation passed for /home/emilio/Documents/ai/pizza/scripts/early_exit/micropizzanet_early_exit.py
[2025-05-14 12:49:04,028] [INFO] Validating script: verify_model.py
[2025-05-14 12:49:05,776] [WARNING] Missing or incomplete docstring in /home/emilio/Documents/ai/pizza/models/rp2040_export/verify_model.py
[2025-05-14 12:49:05,776] [WARNING] Validation passed with warnings for /home/emilio/Documents/ai/pizza/models/rp2040_export/verify_model.py
[2025-05-14 12:49:05,776] [INFO] Validating script: pizza-baking-detection-final.py
[2025-05-14 12:49:06,888] [WARNING] Missing dependencies in /home/emilio/Documents/ai/pizza/src/pizza-baking-detection-final.py: onnx_tf
[2025-05-14 12:49:11,438] [WARNING] Missing or incomplete docstring in /home/emilio/Documents/ai/pizza/src/pizza-baking-detection-final.py
[2025-05-14 12:49:11,438] [WARNING] Validation passed with warnings for /home/emilio/Documents/ai/pizza/src/pizza-baking-detection-final.py
[2025-05-14 12:49:11,438] [INFO] Validating script: metrics.py
[2025-05-14 12:49:12,681] [INFO] Validation passed for /home/emilio/Documents/ai/pizza/src/metrics.py
[2025-05-14 12:49:12,681] [INFO] Validating script: __init__.py
[2025-05-14 12:49:12,690] [WARNING] Missing or incomplete docstring in /home/emilio/Documents/ai/pizza/src/__init__.py
[2025-05-14 12:49:12,690] [WARNING] Validation passed with warnings for /home/emilio/Documents/ai/pizza/src/__init__.py
[2025-05-14 12:49:12,690] [INFO] Validating script: pizza_detector.py
[2025-05-14 12:49:12,714] [WARNING] Missing dependencies in /home/emilio/Documents/ai/pizza/src/pizza_detector.py: onnx_tf
[2025-05-14 12:49:17,307] [WARNING] Missing or incomplete docstring in /home/emilio/Documents/ai/pizza/src/pizza_detector.py
[2025-05-14 12:49:17,307] [WARNING] Validation passed with warnings for /home/emilio/Documents/ai/pizza/src/pizza_detector.py
[2025-05-14 12:49:17,307] [INFO] Validating script: constants.py
[2025-05-14 12:49:17,331] [INFO] Validation passed for /home/emilio/Documents/ai/pizza/src/constants.py
[2025-05-14 12:49:17,331] [INFO] Validating script: test_frame_buffer.py
[2025-05-14 12:49:17,334] [WARNING] Missing dependencies in /home/emilio/Documents/ai/pizza/src/emulation/test_frame_buffer.py: frame_buffer
[2025-05-14 12:49:17,433] [WARNING] Validation passed with warnings for /home/emilio/Documents/ai/pizza/src/emulation/test_frame_buffer.py
[2025-05-14 12:49:17,433] [INFO] Validating script: emulator-test.py
[2025-05-14 12:49:17,531] [WARNING] Missing or incomplete docstring in /home/emilio/Documents/ai/pizza/src/emulation/emulator-test.py
[2025-05-14 12:49:17,531] [WARNING] Validation passed with warnings for /home/emilio/Documents/ai/pizza/src/emulation/emulator-test.py
[2025-05-14 12:49:17,531] [INFO] Validating script: emulator.py
[2025-05-14 12:49:17,536] [WARNING] Missing dependencies in /home/emilio/Documents/ai/pizza/src/emulation/emulator.py: power_manager, frame_buffer, exceptions, constants
[2025-05-14 12:49:17,604] [WARNING] Execution test issue in /home/emilio/Documents/ai/pizza/src/emulation/emulator.py: Execution failed with error: Traceback (most recent call last):
  File "/home/emilio/Documents/ai/pizza/src/emulation/emulator.py", line 12, in <module>
    from .constants import (
ImportError: attempted relative import with no known parent package

[2025-05-14 12:49:17,606] [WARNING] Validation passed with warnings for /home/emilio/Documents/ai/pizza/src/emulation/emulator.py
[2025-05-14 12:49:17,606] [INFO] Validating script: frame_buffer.py
[2025-05-14 12:49:17,694] [INFO] Validation passed for /home/emilio/Documents/ai/pizza/src/emulation/frame_buffer.py
[2025-05-14 12:49:17,694] [INFO] Validating script: metrics.py
[2025-05-14 12:49:17,703] [WARNING] Missing dependencies in /home/emilio/Documents/ai/pizza/src/analysis/metrics.py: exceptions, constants
[2025-05-14 12:49:19,201] [WARNING] Execution test issue in /home/emilio/Documents/ai/pizza/src/analysis/metrics.py: Execution failed with error: Traceback (most recent call last):
  File "/home/emilio/Documents/ai/pizza/src/analysis/metrics.py", line 16, in <module>
    from .types import (
ImportError: attempted relative import with no known parent package

[2025-05-14 12:49:19,203] [WARNING] Validation passed with warnings for /home/emilio/Documents/ai/pizza/src/analysis/metrics.py
[2025-05-14 12:49:19,203] [INFO] Validating script: models.py
[2025-05-14 12:49:19,447] [WARNING] Missing or incomplete docstring in /home/emilio/Documents/ai/pizza/src/chatlist_ki/models.py
[2025-05-14 12:49:19,447] [WARNING] Validation passed with warnings for /home/emilio/Documents/ai/pizza/src/chatlist_ki/models.py
[2025-05-14 12:49:19,447] [INFO] Validating script: __main__.py
[2025-05-14 12:49:19,448] [WARNING] Missing dependencies in /home/emilio/Documents/ai/pizza/src/chatlist_ki/__main__.py: models, database, chat_interface
[2025-05-14 12:49:19,460] [WARNING] Execution test issue in /home/emilio/Documents/ai/pizza/src/chatlist_ki/__main__.py: Execution failed with error: Traceback (most recent call last):
  File "/home/emilio/Documents/ai/pizza/src/chatlist_ki/__main__.py", line 1, in <module>
    from .chat_interface import ChatInterface
ImportError: attempted relative import with no known parent package

[2025-05-14 12:49:19,460] [WARNING] Missing or incomplete docstring in /home/emilio/Documents/ai/pizza/src/chatlist_ki/__main__.py
[2025-05-14 12:49:19,460] [WARNING] Validation passed with warnings for /home/emilio/Documents/ai/pizza/src/chatlist_ki/__main__.py
[2025-05-14 12:49:19,460] [INFO] Validating script: __init__.py
[2025-05-14 12:49:19,460] [WARNING] Missing dependencies in /home/emilio/Documents/ai/pizza/src/chatlist_ki/__init__.py: models, database, chat_interface
[2025-05-14 12:49:19,476] [WARNING] Execution test issue in /home/emilio/Documents/ai/pizza/src/chatlist_ki/__init__.py: Execution failed with error: Traceback (most recent call last):
  File "/home/emilio/Documents/ai/pizza/src/chatlist_ki/__init__.py", line 1, in <module>
    from .models import Task, TaskStatus
ImportError: attempted relative import with no known parent package

[2025-05-14 12:49:19,476] [WARNING] Missing or incomplete docstring in /home/emilio/Documents/ai/pizza/src/chatlist_ki/__init__.py
[2025-05-14 12:49:19,476] [WARNING] Validation passed with warnings for /home/emilio/Documents/ai/pizza/src/chatlist_ki/__init__.py
[2025-05-14 12:49:19,476] [INFO] Validating script: api.py
[2025-05-14 12:49:19,603] [WARNING] Missing dependencies in /home/emilio/Documents/ai/pizza/src/chatlist_ki/api.py: models, database
[2025-05-14 12:49:19,807] [WARNING] Execution test issue in /home/emilio/Documents/ai/pizza/src/chatlist_ki/api.py: Execution failed with error: Traceback (most recent call last):
  File "/home/emilio/Documents/ai/pizza/src/chatlist_ki/api.py", line 5, in <module>
    from .database import Database, TaskManager
ImportError: attempted relative import with no known parent package

[2025-05-14 12:49:19,808] [WARNING] Missing or incomplete docstring in /home/emilio/Documents/ai/pizza/src/chatlist_ki/api.py
[2025-05-14 12:49:19,808] [WARNING] Validation passed with warnings for /home/emilio/Documents/ai/pizza/src/chatlist_ki/api.py
[2025-05-14 12:49:19,808] [INFO] Validating script: database.py
[2025-05-14 12:49:19,811] [WARNING] Missing dependencies in /home/emilio/Documents/ai/pizza/src/chatlist_ki/database.py: models
[2025-05-14 12:49:20,000] [WARNING] Execution test issue in /home/emilio/Documents/ai/pizza/src/chatlist_ki/database.py: Execution failed with error: Traceback (most recent call last):
  File "/home/emilio/Documents/ai/pizza/src/chatlist_ki/database.py", line 4, in <module>
    from .models import Base, Task, TaskStatus
ImportError: attempted relative import with no known parent package

[2025-05-14 12:49:20,000] [WARNING] Missing or incomplete docstring in /home/emilio/Documents/ai/pizza/src/chatlist_ki/database.py
[2025-05-14 12:49:20,001] [WARNING] Validation passed with warnings for /home/emilio/Documents/ai/pizza/src/chatlist_ki/database.py
[2025-05-14 12:49:20,001] [INFO] Validating script: chat_interface.py
[2025-05-14 12:49:20,003] [WARNING] Missing dependencies in /home/emilio/Documents/ai/pizza/src/chatlist_ki/chat_interface.py: models, database
[2025-05-14 12:49:20,020] [WARNING] Execution test issue in /home/emilio/Documents/ai/pizza/src/chatlist_ki/chat_interface.py: Execution failed with error: Traceback (most recent call last):
  File "/home/emilio/Documents/ai/pizza/src/chatlist_ki/chat_interface.py", line 2, in <module>
    from .database import TaskManager, Database
ImportError: attempted relative import with no known parent package

[2025-05-14 12:49:20,020] [WARNING] Missing or incomplete docstring in /home/emilio/Documents/ai/pizza/src/chatlist_ki/chat_interface.py
[2025-05-14 12:49:20,021] [WARNING] Validation passed with warnings for /home/emilio/Documents/ai/pizza/src/chatlist_ki/chat_interface.py
[2025-05-14 12:49:20,021] [INFO] Validating script: status_display.py
[2025-05-14 12:49:20,027] [WARNING] Missing dependencies in /home/emilio/Documents/ai/pizza/src/visualization/status_display.py: ssd1306, machine
[2025-05-14 12:49:20,055] [WARNING] Execution test issue in /home/emilio/Documents/ai/pizza/src/visualization/status_display.py: Execution failed with error: Traceback (most recent call last):
  File "/home/emilio/Documents/ai/pizza/src/visualization/status_display.py", line 22, in <module>
    from src.types import InferenceResult
ModuleNotFoundError: No module named 'src'

[2025-05-14 12:49:20,057] [WARNING] Validation passed with warnings for /home/emilio/Documents/ai/pizza/src/visualization/status_display.py
[2025-05-14 12:49:20,058] [INFO] Validating script: visualization.py
[2025-05-14 12:49:20,067] [WARNING] Missing dependencies in /home/emilio/Documents/ai/pizza/src/visualization/visualization.py: constants
[2025-05-14 12:49:21,794] [WARNING] Execution test issue in /home/emilio/Documents/ai/pizza/src/visualization/visualization.py: Execution failed with error: Traceback (most recent call last):
  File "/home/emilio/Documents/ai/pizza/src/visualization/visualization.py", line 15, in <module>
    from .types import (
ImportError: attempted relative import with no known parent package

[2025-05-14 12:49:21,796] [WARNING] Validation passed with warnings for /home/emilio/Documents/ai/pizza/src/visualization/visualization.py
[2025-05-14 12:49:21,796] [INFO] Validating script: exceptions.py
[2025-05-14 12:49:21,809] [INFO] Validation passed for /home/emilio/Documents/ai/pizza/src/utils/exceptions.py
[2025-05-14 12:49:21,809] [INFO] Validating script: types.py
[2025-05-14 12:49:21,826] [WARNING] Execution test issue in /home/emilio/Documents/ai/pizza/src/utils/types.py: Execution failed with error: Traceback (most recent call last):
  File "/home/emilio/Documents/ai/pizza/src/utils/types.py", line 6, in <module>
    from typing import Dict as Dict
  File "/usr/lib/python3.12/typing.py", line 27, in <module>
    import contextlib
  File "/usr/lib/python3.12/contextlib.py", line 7, in <module>
    from functools import wraps
  File "/usr/lib/python3.12/functools.py", line 22, in <module>
    from types import GenericAlias
  File "/home/emilio/Documents/ai/pizza/src/utils/types.py", line 6, in <module>
    from typing import Dict as Dict
ImportError: cannot import name 'Dict' from partially initialized module 'typing' (most likely due to a circular import) (/usr/lib/python3.12/typing.py)

[2025-05-14 12:49:21,827] [WARNING] Validation passed with warnings for /home/emilio/Documents/ai/pizza/src/utils/types.py
[2025-05-14 12:49:21,827] [INFO] Validating script: power_manager.py
[2025-05-14 12:49:21,831] [WARNING] Missing dependencies in /home/emilio/Documents/ai/pizza/src/utils/power_manager.py: metrics, devices, constants
[2025-05-14 12:49:21,847] [WARNING] Execution test issue in /home/emilio/Documents/ai/pizza/src/utils/power_manager.py: Execution failed with error: Traceback (most recent call last):
  File "/home/emilio/Documents/ai/pizza/src/utils/power_manager.py", line 7, in <module>
    import logging
  File "/usr/lib/python3.12/logging/__init__.py", line 26, in <module>
    import sys, os, time, io, re, traceback, warnings, weakref, collections.abc
  File "/usr/lib/python3.12/re/__init__.py", line 124, in <module>
    import enum
  File "/usr/lib/python3.12/enum.py", line 3, in <module>
    from types import MappingProxyType, DynamicClassAttribute
  File "/home/emilio/Documents/ai/pizza/src/utils/types.py", line 6, in <module>
    from typing import Dict as Dict
  File "/usr/lib/python3.12/typing.py", line 27, in <module>
    import contextlib
  File "/usr/lib/python3.12/contextlib.py", line 7, in <module>
    from functools import wraps
  File "/usr/lib/python3.12/functools.py", line 22, in <module>
    from types import GenericAlias
ImportError: cannot import name 'GenericAlias' from partially initialized module 'types' (most likely due to a circular import) (/home/emilio/Documents/ai/pizza/src/utils/types.py)

[2025-05-14 12:49:21,849] [WARNING] Validation passed with warnings for /home/emilio/Documents/ai/pizza/src/utils/power_manager.py
[2025-05-14 12:49:21,849] [INFO] Validating script: devices.py
[2025-05-14 12:49:21,850] [WARNING] Missing dependencies in /home/emilio/Documents/ai/pizza/src/utils/devices.py: constants, exceptions
[2025-05-14 12:49:21,864] [WARNING] Execution test issue in /home/emilio/Documents/ai/pizza/src/utils/devices.py: Execution failed with error: Traceback (most recent call last):
  File "/home/emilio/Documents/ai/pizza/src/utils/devices.py", line 6, in <module>
    import logging
  File "/usr/lib/python3.12/logging/__init__.py", line 26, in <module>
    import sys, os, time, io, re, traceback, warnings, weakref, collections.abc
  File "/usr/lib/python3.12/re/__init__.py", line 124, in <module>
    import enum
  File "/usr/lib/python3.12/enum.py", line 3, in <module>
    from types import MappingProxyType, DynamicClassAttribute
  File "/home/emilio/Documents/ai/pizza/src/utils/types.py", line 6, in <module>
    from typing import Dict as Dict
  File "/usr/lib/python3.12/typing.py", line 27, in <module>
    import contextlib
  File "/usr/lib/python3.12/contextlib.py", line 7, in <module>
    from functools import wraps
  File "/usr/lib/python3.12/functools.py", line 22, in <module>
    from types import GenericAlias
ImportError: cannot import name 'GenericAlias' from partially initialized module 'types' (most likely due to a circular import) (/home/emilio/Documents/ai/pizza/src/utils/types.py)

[2025-05-14 12:49:21,864] [WARNING] Validation passed with warnings for /home/emilio/Documents/ai/pizza/src/utils/devices.py
[2025-05-14 12:49:21,865] [INFO] Validating script: validation.py
[2025-05-14 12:49:21,867] [WARNING] Missing dependencies in /home/emilio/Documents/ai/pizza/src/utils/validation.py: exceptions, constants
[2025-05-14 12:49:21,880] [WARNING] Execution test issue in /home/emilio/Documents/ai/pizza/src/utils/validation.py: Execution failed with error: Traceback (most recent call last):
  File "/home/emilio/Documents/ai/pizza/src/utils/validation.py", line 6, in <module>
    import json
  File "/usr/lib/python3.12/json/__init__.py", line 106, in <module>
    from .decoder import JSONDecoder, JSONDecodeError
  File "/usr/lib/python3.12/json/decoder.py", line 3, in <module>
    import re
  File "/usr/lib/python3.12/re/__init__.py", line 124, in <module>
    import enum
  File "/usr/lib/python3.12/enum.py", line 3, in <module>
    from types import MappingProxyType, DynamicClassAttribute
  File "/home/emilio/Documents/ai/pizza/src/utils/types.py", line 6, in <module>
    from typing import Dict as Dict
  File "/usr/lib/python3.12/typing.py", line 27, in <module>
    import contextlib
  File "/usr/lib/python3.12/contextlib.py", line 7, in <module>
    from functools import wraps
  File "/usr/lib/python3.12/functools.py", line 22, in <module>
    from types import GenericAlias
ImportError: cannot import name 'GenericAlias' from partially initialized module 'types' (most likely due to a circular import) (/home/emilio/Documents/ai/pizza/src/utils/types.py)

[2025-05-14 12:49:21,881] [WARNING] Validation passed with warnings for /home/emilio/Documents/ai/pizza/src/utils/validation.py
[2025-05-14 12:49:21,881] [INFO] Validating script: memory.py
[2025-05-14 12:49:21,882] [WARNING] Missing dependencies in /home/emilio/Documents/ai/pizza/src/utils/memory.py: constants, exceptions
[2025-05-14 12:49:21,896] [WARNING] Execution test issue in /home/emilio/Documents/ai/pizza/src/utils/memory.py: Execution failed with error: Traceback (most recent call last):
  File "/home/emilio/Documents/ai/pizza/src/utils/memory.py", line 5, in <module>
    import torch
  File "/home/emilio/Documents/ai/pizza/.venv/lib/python3.12/site-packages/torch/__init__.py", line 14, in <module>
    import ctypes
  File "/usr/lib/python3.12/ctypes/__init__.py", line 4, in <module>
    import types as _types
  File "/home/emilio/Documents/ai/pizza/src/utils/types.py", line 6, in <module>
    from typing import Dict as Dict
  File "/usr/lib/python3.12/typing.py", line 27, in <module>
    import contextlib
  File "/usr/lib/python3.12/contextlib.py", line 7, in <module>
    from functools import wraps
  File "/usr/lib/python3.12/functools.py", line 22, in <module>
    from types import GenericAlias
ImportError: cannot import name 'GenericAlias' from partially initialized module 'types' (most likely due to a circular import) (/home/emilio/Documents/ai/pizza/src/utils/types.py)

[2025-05-14 12:49:21,897] [WARNING] Validation passed with warnings for /home/emilio/Documents/ai/pizza/src/utils/memory.py
[2025-05-14 12:49:21,897] [INFO] Validating script: temporal_smoother.py
[2025-05-14 12:49:21,918] [WARNING] Execution test issue in /home/emilio/Documents/ai/pizza/src/utils/temporal_smoother.py: Execution failed with error: Traceback (most recent call last):
  File "/home/emilio/Documents/ai/pizza/src/utils/temporal_smoother.py", line 9, in <module>
    import numpy as np
  File "/home/emilio/Documents/ai/pizza/.venv/lib/python3.12/site-packages/numpy/__init__.py", line 92, in <module>
    from ._globals import _NoValue, _CopyMode
  File "/home/emilio/Documents/ai/pizza/.venv/lib/python3.12/site-packages/numpy/_globals.py", line 18, in <module>
    import enum
  File "/usr/lib/python3.12/enum.py", line 3, in <module>
    from types import MappingProxyType, DynamicClassAttribute
  File "/home/emilio/Documents/ai/pizza/src/utils/types.py", line 6, in <module>
    from typing import Dict as Dict
  File "/usr/lib/python3.12/typing.py", line 27, in <module>
    import contextlib
  File "/usr/lib/python3.12/contextlib.py", line 7, in <module>
    from functools import wraps
  File "/usr/lib/python3.12/functools.py", line 22, in <module>
    from types import GenericAlias
ImportError: cannot import name 'GenericAlias' from partially initialized module 'types' (most likely due to a circular import) (/home/emilio/Documents/ai/pizza/src/utils/types.py)

[2025-05-14 12:49:21,920] [WARNING] Validation passed with warnings for /home/emilio/Documents/ai/pizza/src/utils/temporal_smoother.py
[2025-05-14 12:49:21,920] [INFO] Validating script: utils.py
[2025-05-14 12:49:21,936] [WARNING] Execution test issue in /home/emilio/Documents/ai/pizza/src/utils/utils.py: Execution failed with error: Traceback (most recent call last):
  File "/home/emilio/Documents/ai/pizza/src/utils/utils.py", line 6, in <module>
    import logging
  File "/usr/lib/python3.12/logging/__init__.py", line 26, in <module>
    import sys, os, time, io, re, traceback, warnings, weakref, collections.abc
  File "/usr/lib/python3.12/re/__init__.py", line 124, in <module>
    import enum
  File "/usr/lib/python3.12/enum.py", line 3, in <module>
    from types import MappingProxyType, DynamicClassAttribute
  File "/home/emilio/Documents/ai/pizza/src/utils/types.py", line 6, in <module>
    from typing import Dict as Dict
  File "/usr/lib/python3.12/typing.py", line 27, in <module>
    import contextlib
  File "/usr/lib/python3.12/contextlib.py", line 7, in <module>
    from functools import wraps
  File "/usr/lib/python3.12/functools.py", line 22, in <module>
    from types import GenericAlias
ImportError: cannot import name 'GenericAlias' from partially initialized module 'types' (most likely due to a circular import) (/home/emilio/Documents/ai/pizza/src/utils/types.py)

[2025-05-14 12:49:21,937] [WARNING] Validation passed with warnings for /home/emilio/Documents/ai/pizza/src/utils/utils.py
[2025-05-14 12:49:21,937] [INFO] Validating script: constants.py
[2025-05-14 12:49:21,954] [WARNING] Execution test issue in /home/emilio/Documents/ai/pizza/src/utils/constants.py: Execution failed with error: Traceback (most recent call last):
  File "/home/emilio/Documents/ai/pizza/src/utils/constants.py", line 5, in <module>
    from pathlib import Path
  File "/usr/lib/python3.12/pathlib.py", line 8, in <module>
    import fnmatch
  File "/usr/lib/python3.12/fnmatch.py", line 14, in <module>
    import re
  File "/usr/lib/python3.12/re/__init__.py", line 124, in <module>
    import enum
  File "/usr/lib/python3.12/enum.py", line 3, in <module>
    from types import MappingProxyType, DynamicClassAttribute
  File "/home/emilio/Documents/ai/pizza/src/utils/types.py", line 6, in <module>
    from typing import Dict as Dict
  File "/usr/lib/python3.12/typing.py", line 27, in <module>
    import contextlib
  File "/usr/lib/python3.12/contextlib.py", line 7, in <module>
    from functools import wraps
  File "/usr/lib/python3.12/functools.py", line 22, in <module>
    from types import GenericAlias
ImportError: cannot import name 'GenericAlias' from partially initialized module 'types' (most likely due to a circular import) (/home/emilio/Documents/ai/pizza/src/utils/types.py)

[2025-05-14 12:49:21,954] [WARNING] Validation passed with warnings for /home/emilio/Documents/ai/pizza/src/utils/constants.py
[2025-05-14 12:49:21,954] [INFO] Validating script: enhanced_pizza_augmentation.py
[2025-05-14 12:49:24,151] [WARNING] Execution test issue in /home/emilio/Documents/ai/pizza/src/augmentation/enhanced_pizza_augmentation.py: Execution failed with error: 
[2025-05-14 12:49:24,162] [WARNING] Missing or incomplete docstring in /home/emilio/Documents/ai/pizza/src/augmentation/enhanced_pizza_augmentation.py
[2025-05-14 12:49:24,162] [WARNING] Validation passed with warnings for /home/emilio/Documents/ai/pizza/src/augmentation/enhanced_pizza_augmentation.py
[2025-05-14 12:49:24,162] [INFO] Validating script: augmentation_optimized.py
[2025-05-14 12:49:27,230] [WARNING] Missing or incomplete docstring in /home/emilio/Documents/ai/pizza/src/augmentation/augmentation_optimized.py
[2025-05-14 12:49:27,230] [WARNING] Validation passed with warnings for /home/emilio/Documents/ai/pizza/src/augmentation/augmentation_optimized.py
[2025-05-14 12:49:27,230] [INFO] Validating script: diffusion_pizza_generator.py
[2025-05-14 12:49:31,868] [INFO] Validation passed for /home/emilio/Documents/ai/pizza/src/augmentation/diffusion_pizza_generator.py
[2025-05-14 12:49:31,868] [INFO] Validating script: augmentation.py
[2025-05-14 12:49:34,044] [WARNING] Execution test issue in /home/emilio/Documents/ai/pizza/src/augmentation/augmentation.py: Execution failed with error: 
[2025-05-14 12:49:34,058] [WARNING] Missing or incomplete docstring in /home/emilio/Documents/ai/pizza/src/augmentation/augmentation.py
[2025-05-14 12:49:34,058] [WARNING] Validation passed with warnings for /home/emilio/Documents/ai/pizza/src/augmentation/augmentation.py
[2025-05-14 12:49:34,058] [INFO] Validating script: advanced_pizza_diffusion_control.py
[2025-05-14 12:49:35,850] [WARNING] Execution test issue in /home/emilio/Documents/ai/pizza/src/augmentation/advanced_pizza_diffusion_control.py: Execution failed with error: Traceback (most recent call last):
  File "/home/emilio/Documents/ai/pizza/src/augmentation/advanced_pizza_diffusion_control.py", line 36, in <module>
    from src.augmentation.diffusion_pizza_generator import PizzaDiffusionGenerator, PIZZA_STAGES
ModuleNotFoundError: No module named 'src'

[2025-05-14 12:49:35,853] [WARNING] Validation passed with warnings for /home/emilio/Documents/ai/pizza/src/augmentation/advanced_pizza_diffusion_control.py
[2025-05-14 12:49:35,853] [INFO] Validating script: optimized-pizza-augmentation.py
[2025-05-14 12:49:38,103] [WARNING] Execution test issue in /home/emilio/Documents/ai/pizza/src/augmentation/optimized-pizza-augmentation.py: Execution failed with error: Traceback (most recent call last):
  File "/home/emilio/Documents/ai/pizza/src/augmentation/optimized-pizza-augmentation.py", line 698, in <module>
    main()
  File "/home/emilio/Documents/ai/pizza/src/augmentation/optimized-pizza-augmentation.py", line 688, in main
    augment_pizza_dataset(input_dir, output_dir, img_per_original=img_per_original, batch_size=batch_size)
  File "/home/emilio/Documents/ai/pizza/src/augmentation/optimized-pizza-augmentation.py", line 512, in augment_pizza_dataset
    image_files = [os.path.join(input_dir, f) for f in os.listdir(input_dir) 
                                                       ^^^^^^^^^^^^^^^^^^^^^
FileNotFoundError: [Errno 2] No such file or directory: '/home/emilio/Documents/ai/pizza/img-pizza/'

[2025-05-14 12:49:38,106] [WARNING] Missing or incomplete docstring in /home/emilio/Documents/ai/pizza/src/augmentation/optimized-pizza-augmentation.py
[2025-05-14 12:49:38,106] [WARNING] Validation passed with warnings for /home/emilio/Documents/ai/pizza/src/augmentation/optimized-pizza-augmentation.py
[2025-05-14 12:49:38,107] [INFO] Validating script: augment_legacy.py
[2025-05-14 12:49:43,177] [WARNING] Execution test issue in /home/emilio/Documents/ai/pizza/src/legacy/augment_legacy.py: Execution timed out (> 5 seconds)
[2025-05-14 12:49:43,178] [WARNING] Missing or incomplete docstring in /home/emilio/Documents/ai/pizza/src/legacy/augment_legacy.py
[2025-05-14 12:49:43,178] [WARNING] Validation passed with warnings for /home/emilio/Documents/ai/pizza/src/legacy/augment_legacy.py
[2025-05-14 12:49:43,178] [INFO] Validating script: diffusion_data_agent.py
[2025-05-14 12:49:43,185] [WARNING] Missing dependencies in /home/emilio/Documents/ai/pizza/src/integration/diffusion_data_agent.py: cleanfid
[2025-05-14 12:49:44,923] [WARNING] Validation passed with warnings for /home/emilio/Documents/ai/pizza/src/integration/diffusion_data_agent.py
[2025-05-14 12:49:44,923] [INFO] Validating script: pizza_diffusion_integration.py
[2025-05-14 12:49:44,929] [WARNING] Missing dependencies in /home/emilio/Documents/ai/pizza/src/integration/pizza_diffusion_integration.py: diffusion_data_agent, enhanced_pizza_augmentation, optimized_pizza_augmentation
[2025-05-14 12:49:46,661] [WARNING] Execution test issue in /home/emilio/Documents/ai/pizza/src/integration/pizza_diffusion_integration.py: Execution failed with error: Traceback (most recent call last):
  File "/home/emilio/Documents/ai/pizza/src/integration/pizza_diffusion_integration.py", line 29, in <module>
    from enhanced_pizza_augmentation import (
ModuleNotFoundError: No module named 'enhanced_pizza_augmentation'

During handling of the above exception, another exception occurred:

Traceback (most recent call last):
  File "/home/emilio/Documents/ai/pizza/src/integration/pizza_diffusion_integration.py", line 40, in <module>
    from optimized_pizza_augmentation import (
ModuleNotFoundError: No module named 'optimized_pizza_augmentation'

During handling of the above exception, another exception occurred:

Traceback (most recent call last):
  File "/home/emilio/Documents/ai/pizza/src/integration/pizza_diffusion_integration.py", line 49, in <module>
    from test import (
ImportError: cannot import name 'PizzaBurningEffect' from 'test' (/usr/lib/python3.12/test/__init__.py)

[2025-05-14 12:49:46,663] [WARNING] Validation passed with warnings for /home/emilio/Documents/ai/pizza/src/integration/pizza_diffusion_integration.py
[2025-05-14 12:49:46,663] [INFO] Validating script: diffusion_training_integration.py
[2025-05-14 12:49:51,198] [INFO] Validation passed for /home/emilio/Documents/ai/pizza/src/integration/diffusion_training_integration.py
[2025-05-14 12:49:51,199] [INFO] Validation complete. Summary: 28 passed, 47 with warnings, 0 failed
[2025-05-14 12:49:51,199] [INFO] Report written to /home/emilio/Documents/ai/pizza/output/pipeline_runs/20250514_124816/reports/validation_report.json
