[2025-05-14 01:27:30,341] [INFO] Found 74 Python scripts to validate
[2025-05-14 01:27:30,341] [INFO] Validating script: cleanup.py
[2025-05-14 01:27:30,393] [INFO] Validation passed for /home/emilio/Documents/ai/pizza/scripts/cleanup.py
[2025-05-14 01:27:30,393] [INFO] Validating script: filter_dataset.py
[2025-05-14 01:27:30,405] [WARNING] Missing or incomplete docstring in /home/emilio/Documents/ai/pizza/scripts/filter_dataset.py
[2025-05-14 01:27:30,405] [WARNING] Validation passed with warnings for /home/emilio/Documents/ai/pizza/scripts/filter_dataset.py
[2025-05-14 01:27:30,405] [INFO] Validating script: label_tool.py
[2025-05-14 01:27:32,526] [INFO] Validation passed for /home/emilio/Documents/ai/pizza/scripts/label_tool.py
[2025-05-14 01:27:32,527] [INFO] Validating script: framebuffer_demo.py
[2025-05-14 01:27:32,613] [WARNING] Execution test issue in /home/emilio/Documents/ai/pizza/scripts/framebuffer_demo.py: Execution failed with error: 
[2025-05-14 01:27:32,614] [WARNING] Validation passed with warnings for /home/emilio/Documents/ai/pizza/scripts/framebuffer_demo.py
[2025-05-14 01:27:32,614] [INFO] Validating script: compare_inverted_residual.py
[2025-05-14 01:27:36,276] [INFO] Validation passed for /home/emilio/Documents/ai/pizza/scripts/compare_inverted_residual.py
[2025-05-14 01:27:36,276] [INFO] Validating script: test_temporal_smoothing.py
[2025-05-14 01:27:36,597] [INFO] Validation passed for /home/emilio/Documents/ai/pizza/scripts/test_temporal_smoothing.py
[2025-05-14 01:27:36,597] [INFO] Validating script: knowledge_distillation.py
[2025-05-14 01:27:38,555] [INFO] Validation passed for /home/emilio/Documents/ai/pizza/scripts/knowledge_distillation.py
[2025-05-14 01:27:38,555] [INFO] Validating script: visualize_gradcam.py
[2025-05-14 01:27:39,143] [WARNING] Missing dependencies in /home/emilio/Documents/ai/pizza/scripts/visualize_gradcam.py: scripts
[2025-05-14 01:27:41,635] [WARNING] Execution test issue in /home/emilio/Documents/ai/pizza/scripts/visualize_gradcam.py: Execution failed with error: Traceback (most recent call last):
  File "/home/emilio/Documents/ai/pizza/scripts/visualize_gradcam.py", line 52, in <module>
    from scripts.compare_tiny_cnns import MCUNet, MobilePizzaNet
  File "/home/emilio/Documents/ai/pizza/scripts/compare_tiny_cnns.py", line 52, in <module>
    from src.metrics import ModelMetrics
ImportError: cannot import name 'ModelMetrics' from 'src.metrics' (/home/emilio/Documents/ai/pizza/src/metrics.py)

[2025-05-14 01:27:41,639] [WARNING] Validation passed with warnings for /home/emilio/Documents/ai/pizza/scripts/visualize_gradcam.py
[2025-05-14 01:27:41,639] [INFO] Validating script: classify_images.py
[2025-05-14 01:27:41,648] [WARNING] Missing or incomplete docstring in /home/emilio/Documents/ai/pizza/scripts/classify_images.py
[2025-05-14 01:27:41,648] [WARNING] Validation passed with warnings for /home/emilio/Documents/ai/pizza/scripts/classify_images.py
[2025-05-14 01:27:41,648] [INFO] Validating script: visualize_pruning.py
[2025-05-14 01:27:44,056] [INFO] Validation passed for /home/emilio/Documents/ai/pizza/scripts/visualize_pruning.py
[2025-05-14 01:27:44,057] [INFO] Validating script: compare_tiny_cnns.py
[2025-05-14 01:27:44,086] [WARNING] Missing dependencies in /home/emilio/Documents/ai/pizza/scripts/compare_tiny_cnns.py: scripts
[2025-05-14 01:27:46,538] [WARNING] Execution test issue in /home/emilio/Documents/ai/pizza/scripts/compare_tiny_cnns.py: Execution failed with error: Traceback (most recent call last):
  File "/home/emilio/Documents/ai/pizza/scripts/compare_tiny_cnns.py", line 52, in <module>
    from src.metrics import ModelMetrics
ImportError: cannot import name 'ModelMetrics' from 'src.metrics' (/home/emilio/Documents/ai/pizza/src/metrics.py)

[2025-05-14 01:27:46,541] [WARNING] Validation passed with warnings for /home/emilio/Documents/ai/pizza/scripts/compare_tiny_cnns.py
[2025-05-14 01:27:46,542] [INFO] Validating script: compare_se_models.py
[2025-05-14 01:27:49,101] [INFO] Validation passed for /home/emilio/Documents/ai/pizza/scripts/compare_se_models.py
[2025-05-14 01:27:49,101] [INFO] Validating script: automated_test_suite.py
[2025-05-14 01:27:51,588] [WARNING] Execution test issue in /home/emilio/Documents/ai/pizza/scripts/automated_test_suite.py: Execution failed with error: Traceback (most recent call last):
  File "/home/emilio/Documents/ai/pizza/scripts/automated_test_suite.py", line 53, in <module>
    from src.pizza_detector import (
ImportError: cannot import name 'load_model' from 'src.pizza_detector' (/home/emilio/Documents/ai/pizza/src/pizza_detector.py)

[2025-05-14 01:27:51,593] [WARNING] Validation passed with warnings for /home/emilio/Documents/ai/pizza/scripts/automated_test_suite.py
[2025-05-14 01:27:51,593] [INFO] Validating script: compare_hard_swish.py
[2025-05-14 01:27:54,122] [INFO] Validation passed for /home/emilio/Documents/ai/pizza/scripts/compare_hard_swish.py
[2025-05-14 01:27:54,122] [INFO] Validating script: demo_status_display.py
[2025-05-14 01:27:54,150] [WARNING] Execution test issue in /home/emilio/Documents/ai/pizza/scripts/demo_status_display.py: Execution failed with error: Traceback (most recent call last):
  File "/home/emilio/Documents/ai/pizza/scripts/demo_status_display.py", line 38, in <module>
    from src.status_display import (
ModuleNotFoundError: No module named 'src.status_display'

[2025-05-14 01:27:54,151] [WARNING] Validation passed with warnings for /home/emilio/Documents/ai/pizza/scripts/demo_status_display.py
[2025-05-14 01:27:54,151] [INFO] Validating script: test_image_preprocessing.py
[2025-05-14 01:27:54,483] [WARNING] Execution test issue in /home/emilio/Documents/ai/pizza/scripts/test_image_preprocessing.py: Execution failed with error: Traceback (most recent call last):
  File "/home/emilio/Documents/ai/pizza/scripts/test_image_preprocessing.py", line 22, in <module>
    from src.constants import INPUT_SIZE
ImportError: cannot import name 'INPUT_SIZE' from 'src.constants' (/home/emilio/Documents/ai/pizza/src/constants.py)

[2025-05-14 01:27:54,484] [WARNING] Validation passed with warnings for /home/emilio/Documents/ai/pizza/scripts/test_image_preprocessing.py
[2025-05-14 01:27:54,484] [INFO] Validating script: test_pizza_detection.py
[2025-05-14 01:27:56,417] [WARNING] Execution test issue in /home/emilio/Documents/ai/pizza/scripts/test_pizza_detection.py: Execution failed with error: Traceback (most recent call last):
  File "/home/emilio/Documents/ai/pizza/scripts/test_pizza_detection.py", line 26, in <module>
    from src.constants import INPUT_SIZE, IMAGE_MEAN, IMAGE_STD
ImportError: cannot import name 'INPUT_SIZE' from 'src.constants' (/home/emilio/Documents/ai/pizza/src/constants.py)

[2025-05-14 01:27:56,419] [WARNING] Validation passed with warnings for /home/emilio/Documents/ai/pizza/scripts/test_pizza_detection.py
[2025-05-14 01:27:56,419] [INFO] Validating script: demo_power_management.py
[2025-05-14 01:27:56,702] [WARNING] Execution test issue in /home/emilio/Documents/ai/pizza/scripts/demo_power_management.py: Execution failed with error: Traceback (most recent call last):
  File "/home/emilio/Documents/ai/pizza/scripts/demo_power_management.py", line 19, in <module>
    from src.emulator import RP2040Emulator
ModuleNotFoundError: No module named 'src.emulator'

[2025-05-14 01:27:56,704] [WARNING] Validation passed with warnings for /home/emilio/Documents/ai/pizza/scripts/demo_power_management.py
[2025-05-14 01:27:56,704] [INFO] Validating script: analyze_performance_logs.py
[2025-05-14 01:27:57,435] [INFO] Validation passed for /home/emilio/Documents/ai/pizza/scripts/analyze_performance_logs.py
[2025-05-14 01:27:57,435] [INFO] Validating script: simulate_memory_constraints.py
[2025-05-14 01:27:57,711] [WARNING] Execution test issue in /home/emilio/Documents/ai/pizza/scripts/simulate_memory_constraints.py: Execution failed with error: Traceback (most recent call last):
  File "/home/emilio/Documents/ai/pizza/scripts/simulate_memory_constraints.py", line 17, in <module>
    from src.constants import (
ImportError: cannot import name 'RP2040_FLASH_SIZE_KB' from 'src.constants' (/home/emilio/Documents/ai/pizza/src/constants.py)

[2025-05-14 01:27:57,713] [WARNING] Validation passed with warnings for /home/emilio/Documents/ai/pizza/scripts/simulate_memory_constraints.py
[2025-05-14 01:27:57,713] [INFO] Validating script: simulate_clahe_resources.py
[2025-05-14 01:27:57,994] [WARNING] Execution test issue in /home/emilio/Documents/ai/pizza/scripts/simulate_clahe_resources.py: Execution failed with error: Traceback (most recent call last):
  File "/home/emilio/Documents/ai/pizza/scripts/simulate_clahe_resources.py", line 22, in <module>
    from src.constants import INPUT_SIZE
ImportError: cannot import name 'INPUT_SIZE' from 'src.constants' (/home/emilio/Documents/ai/pizza/src/constants.py)

[2025-05-14 01:27:57,996] [WARNING] Validation passed with warnings for /home/emilio/Documents/ai/pizza/scripts/simulate_clahe_resources.py
[2025-05-14 01:27:57,996] [INFO] Validating script: run_pizza_tests.py
[2025-05-14 01:27:58,021] [INFO] Validation passed for /home/emilio/Documents/ai/pizza/scripts/run_pizza_tests.py
[2025-05-14 01:27:58,021] [INFO] Validating script: run_pruning_clustering.py
[2025-05-14 01:27:58,023] [WARNING] Missing dependencies in /home/emilio/Documents/ai/pizza/scripts/run_pruning_clustering.py: scripts, config
[2025-05-14 01:27:59,936] [WARNING] Validation passed with warnings for /home/emilio/Documents/ai/pizza/scripts/run_pruning_clustering.py
[2025-05-14 01:27:59,936] [INFO] Validating script: augment_dataset.py
[2025-05-14 01:28:00,034] [INFO] Validation passed for /home/emilio/Documents/ai/pizza/scripts/augment_dataset.py
[2025-05-14 01:28:00,034] [INFO] Validating script: train_pizza_model.py
[2025-05-14 01:28:01,962] [WARNING] Execution test issue in /home/emilio/Documents/ai/pizza/scripts/train_pizza_model.py: Execution failed with error: Traceback (most recent call last):
  File "/home/emilio/Documents/ai/pizza/scripts/train_pizza_model.py", line 28, in <module>
    from src.constants import INPUT_SIZE, IMAGE_MEAN, IMAGE_STD
ImportError: cannot import name 'INPUT_SIZE' from 'src.constants' (/home/emilio/Documents/ai/pizza/src/constants.py)

[2025-05-14 01:28:01,965] [WARNING] Validation passed with warnings for /home/emilio/Documents/ai/pizza/scripts/train_pizza_model.py
[2025-05-14 01:28:01,965] [INFO] Validating script: simulate_lighting_conditions.py
[2025-05-14 01:28:02,242] [WARNING] Execution test issue in /home/emilio/Documents/ai/pizza/scripts/simulate_lighting_conditions.py: Execution failed with error: Traceback (most recent call last):
  File "/home/emilio/Documents/ai/pizza/scripts/simulate_lighting_conditions.py", line 17, in <module>
    from src.emulator import RP2040Emulator
ModuleNotFoundError: No module named 'src.emulator'

[2025-05-14 01:28:02,243] [WARNING] Validation passed with warnings for /home/emilio/Documents/ai/pizza/scripts/simulate_lighting_conditions.py
[2025-05-14 01:28:02,243] [INFO] Validating script: quantization_aware_training.py
[2025-05-14 01:28:04,219] [INFO] Validation passed for /home/emilio/Documents/ai/pizza/scripts/quantization_aware_training.py
[2025-05-14 01:28:04,219] [INFO] Validating script: simulate_power_consumption.py
[2025-05-14 01:28:04,496] [WARNING] Execution test issue in /home/emilio/Documents/ai/pizza/scripts/simulate_power_consumption.py: Execution failed with error: Traceback (most recent call last):
  File "/home/emilio/Documents/ai/pizza/scripts/simulate_power_consumption.py", line 18, in <module>
    from src.constants import (
ImportError: cannot import name 'RP2040_FLASH_SIZE_KB' from 'src.constants' (/home/emilio/Documents/ai/pizza/src/constants.py)

[2025-05-14 01:28:04,497] [WARNING] Validation passed with warnings for /home/emilio/Documents/ai/pizza/scripts/simulate_power_consumption.py
[2025-05-14 01:28:04,497] [INFO] Validating script: generate_pizza_dataset.py
[2025-05-14 01:28:09,025] [WARNING] Execution test issue in /home/emilio/Documents/ai/pizza/scripts/generate_pizza_dataset.py: Execution failed with error: 2025-05-14 01:28:06.490156: I tensorflow/core/util/port.cc:153] oneDNN custom operations are on. You may see slightly different numerical results due to floating-point round-off errors from different computation orders. To turn them off, set the environment variable `TF_ENABLE_ONEDNN_OPTS=0`.
2025-05-14 01:28:06.498765: E external/local_xla/xla/stream_executor/cuda/cuda_fft.cc:467] Unable to register cuFFT factory: Attempting to register factory for plugin cuFFT when one has already been registered
WARNING: All log messages before absl::InitializeLog() is called are written to STDERR
E0000 00:00:1747178886.509166  168003 cuda_dnn.cc:8579] Unable to register cuDNN factory: Attempting to register factory for plugin cuDNN when one has already been registered
E0000 00:00:1747178886.512154  168003 cuda_blas.cc:1407] Unable to register cuBLAS factory: Attempting to register factory for plugin cuBLAS when one has already been registered
W0000 00:00:1747178886.520187  168003 computation_placer.cc:177] computation placer already registered. Please check linkage and avoid linking the same target more than once.
W0000 00:00:1747178886.520199  168003 computation_placer.cc:177] computation placer already registered. Please check linkage and avoid linking the same target more than once.
W0000 00:00:1747178886.520201  168003 computation_placer.cc:177] computation placer already registered. Please check linkage and avoid linking the same target more than once.
W0000 00:00:1747178886.520202  168003 computation_placer.cc:177] computation placer already registered. Please check linkage and avoid linking the same target more than once.
2025-05-14 01:28:06.522670: I tensorflow/core/platform/cpu_feature_guard.cc:210] This TensorFlow binary is optimized to use available CPU instructions in performance-critical operations.
To enable the following instructions: AVX2 AVX_VNNI FMA, in other operations, rebuild TensorFlow with the appropriate compiler flags.
Traceback (most recent call last):
  File "/home/emilio/Documents/ai/pizza/scripts/generate_pizza_dataset.py", line 28, in <module>
    from src.augmentation.advanced_pizza_diffusion_control import (
  File "/home/emilio/Documents/ai/pizza/src/augmentation/advanced_pizza_diffusion_control.py", line 293
    image_size=image_size,
    ^^^^^^^^^^^^^^^^^^^^^
SyntaxError: keyword argument repeated: image_size

[2025-05-14 01:28:09,027] [WARNING] Validation passed with warnings for /home/emilio/Documents/ai/pizza/scripts/generate_pizza_dataset.py
[2025-05-14 01:28:09,027] [INFO] Validating script: hyperparameter_search.py
[2025-05-14 01:28:11,551] [WARNING] Execution test issue in /home/emilio/Documents/ai/pizza/scripts/hyperparameter_search.py: Execution failed with error: Traceback (most recent call last):
  File "/home/emilio/Documents/ai/pizza/scripts/hyperparameter_search.py", line 45, in <module>
    from src.metrics import ModelMetrics
ImportError: cannot import name 'ModelMetrics' from 'src.metrics' (/home/emilio/Documents/ai/pizza/src/metrics.py)

[2025-05-14 01:28:11,556] [WARNING] Validation passed with warnings for /home/emilio/Documents/ai/pizza/scripts/hyperparameter_search.py
[2025-05-14 01:28:11,556] [INFO] Validating script: extract_frames.py
[2025-05-14 01:28:11,577] [WARNING] Missing or incomplete docstring in /home/emilio/Documents/ai/pizza/scripts/extract_frames.py
[2025-05-14 01:28:11,577] [WARNING] Validation passed with warnings for /home/emilio/Documents/ai/pizza/scripts/extract_frames.py
[2025-05-14 01:28:11,577] [INFO] Validating script: validate_integration.py
[2025-05-14 01:28:11,616] [INFO] Validation passed for /home/emilio/Documents/ai/pizza/scripts/ci/validate_integration.py
[2025-05-14 01:28:11,617] [INFO] Validating script: validate_scripts.py
[2025-05-14 01:28:11,699] [INFO] Validation passed for /home/emilio/Documents/ai/pizza/scripts/ci/validate_scripts.py
[2025-05-14 01:28:11,699] [INFO] Validating script: generate_pipeline_report.py
[2025-05-14 01:28:12,011] [INFO] Validation passed for /home/emilio/Documents/ai/pizza/scripts/ci/generate_pipeline_report.py
[2025-05-14 01:28:12,011] [INFO] Validating script: weight_pruning.py
[2025-05-14 01:28:12,020] [WARNING] Missing dependencies in /home/emilio/Documents/ai/pizza/scripts/model_optimization/weight_pruning.py: config
[2025-05-14 01:28:13,950] [WARNING] Validation passed with warnings for /home/emilio/Documents/ai/pizza/scripts/model_optimization/weight_pruning.py
[2025-05-14 01:28:13,950] [INFO] Validating script: micropizzanet_early_exit.py
[2025-05-14 01:28:15,901] [INFO] Validation passed for /home/emilio/Documents/ai/pizza/scripts/early_exit/micropizzanet_early_exit.py
[2025-05-14 01:28:15,902] [INFO] Validating script: verify_model.py
[2025-05-14 01:28:17,566] [WARNING] Missing or incomplete docstring in /home/emilio/Documents/ai/pizza/models/rp2040_export/verify_model.py
[2025-05-14 01:28:17,566] [WARNING] Validation passed with warnings for /home/emilio/Documents/ai/pizza/models/rp2040_export/verify_model.py
[2025-05-14 01:28:17,566] [INFO] Validating script: pizza-baking-detection-final.py
[2025-05-14 01:28:18,639] [WARNING] Missing dependencies in /home/emilio/Documents/ai/pizza/src/pizza-baking-detection-final.py: onnx_tf
[2025-05-14 01:28:20,587] [WARNING] Execution test issue in /home/emilio/Documents/ai/pizza/src/pizza-baking-detection-final.py: Execution failed with error: 2025-05-14 01:28:20,212 - INFO - ================================================================================
2025-05-14 01:28:20,212 - INFO - RP2040 PIZZA-ERKENNUNGSSYSTEM - DETAILLIERTE KONFIGURATION
2025-05-14 01:28:20,212 - INFO - ================================================================================
2025-05-14 01:28:20,212 - INFO - Hardware: RP2040 - 133MHz, 264KB RAM, 2048KB Flash
2025-05-14 01:28:20,212 - INFO - Kamera: OV2640 - 320x240, 7 FPS
2025-05-14 01:28:20,212 - INFO - Stromversorgung: CR123A - 1500mAh, 8.33h aktiv, 3000.00h standby
2025-05-14 01:28:20,212 - INFO - Modellparameter: 48x48 Eingabegröße, 8-Bit Quantisierung
2025-05-14 01:28:20,213 - INFO - Speicherbeschränkungen: Max. 180KB Modellgröße, 100KB Laufzeit-RAM
2025-05-14 01:28:20,213 - INFO - ================================================================================
2025-05-14 01:28:20,213 - ERROR - Fehler im Optimierungsprozess: [Errno 2] No such file or directory: 'augmented_pizza'
Traceback (most recent call last):
  File "/home/emilio/Documents/ai/pizza/src/pizza-baking-detection-final.py", line 2230, in main
    analyzer = PizzaDatasetAnalysis(config.DATA_DIR)
               ^^^^^^^^^^^^^^^^^^^^^^^^^^^^^^^^^^^^^
  File "/home/emilio/Documents/ai/pizza/src/pizza-baking-detection-final.py", line 107, in __init__
    self.class_dirs = [d for d in os.listdir(data_dir)
                                 ^^^^^^^^^^^^^^^^^^^^
FileNotFoundError: [Errno 2] No such file or directory: 'augmented_pizza'
Traceback (most recent call last):
  File "/home/emilio/Documents/ai/pizza/src/pizza-baking-detection-final.py", line 2302, in <module>
    main()
  File "/home/emilio/Documents/ai/pizza/src/pizza-baking-detection-final.py", line 2230, in main
    analyzer = PizzaDatasetAnalysis(config.DATA_DIR)
               ^^^^^^^^^^^^^^^^^^^^^^^^^^^^^^^^^^^^^
  File "/home/emilio/Documents/ai/pizza/src/pizza-baking-detection-final.py", line 107, in __init__
    self.class_dirs = [d for d in os.listdir(data_dir) 
                                  ^^^^^^^^^^^^^^^^^^^^
FileNotFoundError: [Errno 2] No such file or directory: 'augmented_pizza'

[2025-05-14 01:28:20,597] [WARNING] Missing or incomplete docstring in /home/emilio/Documents/ai/pizza/src/pizza-baking-detection-final.py
[2025-05-14 01:28:20,597] [WARNING] Validation passed with warnings for /home/emilio/Documents/ai/pizza/src/pizza-baking-detection-final.py
[2025-05-14 01:28:20,597] [INFO] Validating script: metrics.py
[2025-05-14 01:28:20,610] [WARNING] Missing or incomplete docstring in /home/emilio/Documents/ai/pizza/src/metrics.py
[2025-05-14 01:28:20,610] [WARNING] Validation passed with warnings for /home/emilio/Documents/ai/pizza/src/metrics.py
[2025-05-14 01:28:20,610] [INFO] Validating script: __init__.py
[2025-05-14 01:28:20,623] [WARNING] Missing or incomplete docstring in /home/emilio/Documents/ai/pizza/src/__init__.py
[2025-05-14 01:28:20,623] [WARNING] Validation passed with warnings for /home/emilio/Documents/ai/pizza/src/__init__.py
[2025-05-14 01:28:20,623] [INFO] Validating script: pizza_detector.py
[2025-05-14 01:28:20,648] [WARNING] Missing dependencies in /home/emilio/Documents/ai/pizza/src/pizza_detector.py: onnx_tf
[2025-05-14 01:28:22,563] [WARNING] Execution test issue in /home/emilio/Documents/ai/pizza/src/pizza_detector.py: Execution failed with error: 2025-05-14 01:28:22,194 - INFO - ================================================================================
2025-05-14 01:28:22,194 - INFO - RP2040 PIZZA-ERKENNUNGSSYSTEM - DETAILLIERTE KONFIGURATION
2025-05-14 01:28:22,194 - INFO - ================================================================================
2025-05-14 01:28:22,194 - INFO - Hardware: RP2040 - 133MHz, 264KB RAM, 2048KB Flash
2025-05-14 01:28:22,194 - INFO - Kamera: OV2640 - 320x240, 7 FPS
2025-05-14 01:28:22,194 - INFO - Stromversorgung: CR123A - 1500mAh, 8.33h aktiv, 3000.00h standby
2025-05-14 01:28:22,194 - INFO - Modellparameter: 48x48 Eingabegröße, 8-Bit Quantisierung
2025-05-14 01:28:22,194 - INFO - Speicherbeschränkungen: Max. 180KB Modellgröße, 100KB Laufzeit-RAM
2025-05-14 01:28:22,194 - INFO - ================================================================================
2025-05-14 01:28:22,194 - ERROR - Fehler im Optimierungsprozess: [Errno 2] No such file or directory: 'augmented_pizza'
Traceback (most recent call last):
  File "/home/emilio/Documents/ai/pizza/src/pizza_detector.py", line 2475, in main
    analyzer = PizzaDatasetAnalysis(config.DATA_DIR)
               ^^^^^^^^^^^^^^^^^^^^^^^^^^^^^^^^^^^^^
  File "/home/emilio/Documents/ai/pizza/src/pizza_detector.py", line 107, in __init__
    self.class_dirs = [d for d in os.listdir(data_dir)
                                 ^^^^^^^^^^^^^^^^^^^^
FileNotFoundError: [Errno 2] No such file or directory: 'augmented_pizza'
Traceback (most recent call last):
  File "/home/emilio/Documents/ai/pizza/src/pizza_detector.py", line 2547, in <module>
    main()
  File "/home/emilio/Documents/ai/pizza/src/pizza_detector.py", line 2475, in main
    analyzer = PizzaDatasetAnalysis(config.DATA_DIR)
               ^^^^^^^^^^^^^^^^^^^^^^^^^^^^^^^^^^^^^
  File "/home/emilio/Documents/ai/pizza/src/pizza_detector.py", line 107, in __init__
    self.class_dirs = [d for d in os.listdir(data_dir) 
                                  ^^^^^^^^^^^^^^^^^^^^
FileNotFoundError: [Errno 2] No such file or directory: 'augmented_pizza'

[2025-05-14 01:28:22,572] [WARNING] Missing or incomplete docstring in /home/emilio/Documents/ai/pizza/src/pizza_detector.py
[2025-05-14 01:28:22,572] [WARNING] Validation passed with warnings for /home/emilio/Documents/ai/pizza/src/pizza_detector.py
[2025-05-14 01:28:22,572] [INFO] Validating script: constants.py
[2025-05-14 01:28:22,581] [WARNING] Missing or incomplete docstring in /home/emilio/Documents/ai/pizza/src/constants.py
[2025-05-14 01:28:22,581] [WARNING] Validation passed with warnings for /home/emilio/Documents/ai/pizza/src/constants.py
[2025-05-14 01:28:22,581] [INFO] Validating script: test_frame_buffer.py
[2025-05-14 01:28:22,584] [WARNING] Missing dependencies in /home/emilio/Documents/ai/pizza/src/emulation/test_frame_buffer.py: frame_buffer
[2025-05-14 01:28:22,686] [WARNING] Validation passed with warnings for /home/emilio/Documents/ai/pizza/src/emulation/test_frame_buffer.py
[2025-05-14 01:28:22,686] [INFO] Validating script: emulator-test.py
[2025-05-14 01:28:22,774] [WARNING] Missing or incomplete docstring in /home/emilio/Documents/ai/pizza/src/emulation/emulator-test.py
[2025-05-14 01:28:22,774] [WARNING] Validation passed with warnings for /home/emilio/Documents/ai/pizza/src/emulation/emulator-test.py
[2025-05-14 01:28:22,774] [INFO] Validating script: emulator.py
[2025-05-14 01:28:22,778] [WARNING] Missing dependencies in /home/emilio/Documents/ai/pizza/src/emulation/emulator.py: power_manager, exceptions, frame_buffer, constants
[2025-05-14 01:28:22,844] [WARNING] Execution test issue in /home/emilio/Documents/ai/pizza/src/emulation/emulator.py: Execution failed with error: Traceback (most recent call last):
  File "/home/emilio/Documents/ai/pizza/src/emulation/emulator.py", line 12, in <module>
    from .constants import (
ImportError: attempted relative import with no known parent package

[2025-05-14 01:28:22,846] [WARNING] Validation passed with warnings for /home/emilio/Documents/ai/pizza/src/emulation/emulator.py
[2025-05-14 01:28:22,846] [INFO] Validating script: frame_buffer.py
[2025-05-14 01:28:22,912] [INFO] Validation passed for /home/emilio/Documents/ai/pizza/src/emulation/frame_buffer.py
[2025-05-14 01:28:22,912] [INFO] Validating script: metrics.py
[2025-05-14 01:28:22,916] [WARNING] Missing dependencies in /home/emilio/Documents/ai/pizza/src/analysis/metrics.py: exceptions, constants
[2025-05-14 01:28:24,339] [WARNING] Execution test issue in /home/emilio/Documents/ai/pizza/src/analysis/metrics.py: Execution failed with error: Traceback (most recent call last):
  File "/home/emilio/Documents/ai/pizza/src/analysis/metrics.py", line 16, in <module>
    from .types import (
ImportError: attempted relative import with no known parent package

[2025-05-14 01:28:24,341] [WARNING] Validation passed with warnings for /home/emilio/Documents/ai/pizza/src/analysis/metrics.py
[2025-05-14 01:28:24,341] [INFO] Validating script: models.py
[2025-05-14 01:28:24,575] [WARNING] Missing or incomplete docstring in /home/emilio/Documents/ai/pizza/src/chatlist_ki/models.py
[2025-05-14 01:28:24,575] [WARNING] Validation passed with warnings for /home/emilio/Documents/ai/pizza/src/chatlist_ki/models.py
[2025-05-14 01:28:24,575] [INFO] Validating script: __main__.py
[2025-05-14 01:28:24,576] [WARNING] Missing dependencies in /home/emilio/Documents/ai/pizza/src/chatlist_ki/__main__.py: models, chat_interface, database
[2025-05-14 01:28:24,587] [WARNING] Execution test issue in /home/emilio/Documents/ai/pizza/src/chatlist_ki/__main__.py: Execution failed with error: Traceback (most recent call last):
  File "/home/emilio/Documents/ai/pizza/src/chatlist_ki/__main__.py", line 1, in <module>
    from .chat_interface import ChatInterface
ImportError: attempted relative import with no known parent package

[2025-05-14 01:28:24,587] [WARNING] Missing or incomplete docstring in /home/emilio/Documents/ai/pizza/src/chatlist_ki/__main__.py
[2025-05-14 01:28:24,587] [WARNING] Validation passed with warnings for /home/emilio/Documents/ai/pizza/src/chatlist_ki/__main__.py
[2025-05-14 01:28:24,588] [INFO] Validating script: __init__.py
[2025-05-14 01:28:24,588] [WARNING] Missing dependencies in /home/emilio/Documents/ai/pizza/src/chatlist_ki/__init__.py: models, chat_interface, database
[2025-05-14 01:28:24,599] [WARNING] Execution test issue in /home/emilio/Documents/ai/pizza/src/chatlist_ki/__init__.py: Execution failed with error: Traceback (most recent call last):
  File "/home/emilio/Documents/ai/pizza/src/chatlist_ki/__init__.py", line 1, in <module>
    from .models import Task, TaskStatus
ImportError: attempted relative import with no known parent package

[2025-05-14 01:28:24,600] [WARNING] Missing or incomplete docstring in /home/emilio/Documents/ai/pizza/src/chatlist_ki/__init__.py
[2025-05-14 01:28:24,600] [WARNING] Validation passed with warnings for /home/emilio/Documents/ai/pizza/src/chatlist_ki/__init__.py
[2025-05-14 01:28:24,600] [INFO] Validating script: api.py
[2025-05-14 01:28:24,727] [WARNING] Missing dependencies in /home/emilio/Documents/ai/pizza/src/chatlist_ki/api.py: models, database
[2025-05-14 01:28:24,916] [WARNING] Execution test issue in /home/emilio/Documents/ai/pizza/src/chatlist_ki/api.py: Execution failed with error: Traceback (most recent call last):
  File "/home/emilio/Documents/ai/pizza/src/chatlist_ki/api.py", line 5, in <module>
    from .database import Database, TaskManager
ImportError: attempted relative import with no known parent package

[2025-05-14 01:28:24,917] [WARNING] Missing or incomplete docstring in /home/emilio/Documents/ai/pizza/src/chatlist_ki/api.py
[2025-05-14 01:28:24,917] [WARNING] Validation passed with warnings for /home/emilio/Documents/ai/pizza/src/chatlist_ki/api.py
[2025-05-14 01:28:24,917] [INFO] Validating script: database.py
[2025-05-14 01:28:24,921] [WARNING] Missing dependencies in /home/emilio/Documents/ai/pizza/src/chatlist_ki/database.py: models
[2025-05-14 01:28:25,099] [WARNING] Execution test issue in /home/emilio/Documents/ai/pizza/src/chatlist_ki/database.py: Execution failed with error: Traceback (most recent call last):
  File "/home/emilio/Documents/ai/pizza/src/chatlist_ki/database.py", line 4, in <module>
    from .models import Base, Task, TaskStatus
ImportError: attempted relative import with no known parent package

[2025-05-14 01:28:25,100] [WARNING] Missing or incomplete docstring in /home/emilio/Documents/ai/pizza/src/chatlist_ki/database.py
[2025-05-14 01:28:25,100] [WARNING] Validation passed with warnings for /home/emilio/Documents/ai/pizza/src/chatlist_ki/database.py
[2025-05-14 01:28:25,100] [INFO] Validating script: chat_interface.py
[2025-05-14 01:28:25,101] [WARNING] Missing dependencies in /home/emilio/Documents/ai/pizza/src/chatlist_ki/chat_interface.py: models, database
[2025-05-14 01:28:25,117] [WARNING] Execution test issue in /home/emilio/Documents/ai/pizza/src/chatlist_ki/chat_interface.py: Execution failed with error: Traceback (most recent call last):
  File "/home/emilio/Documents/ai/pizza/src/chatlist_ki/chat_interface.py", line 2, in <module>
    from .database import TaskManager, Database
ImportError: attempted relative import with no known parent package

[2025-05-14 01:28:25,118] [WARNING] Missing or incomplete docstring in /home/emilio/Documents/ai/pizza/src/chatlist_ki/chat_interface.py
[2025-05-14 01:28:25,118] [WARNING] Validation passed with warnings for /home/emilio/Documents/ai/pizza/src/chatlist_ki/chat_interface.py
[2025-05-14 01:28:25,118] [INFO] Validating script: status_display.py
[2025-05-14 01:28:25,125] [WARNING] Missing dependencies in /home/emilio/Documents/ai/pizza/src/visualization/status_display.py: ssd1306, machine
[2025-05-14 01:28:25,160] [WARNING] Execution test issue in /home/emilio/Documents/ai/pizza/src/visualization/status_display.py: Execution failed with error: Traceback (most recent call last):
  File "/home/emilio/Documents/ai/pizza/src/visualization/status_display.py", line 22, in <module>
    from src.types import InferenceResult
ModuleNotFoundError: No module named 'src'

[2025-05-14 01:28:25,163] [WARNING] Validation passed with warnings for /home/emilio/Documents/ai/pizza/src/visualization/status_display.py
[2025-05-14 01:28:25,163] [INFO] Validating script: visualization.py
[2025-05-14 01:28:25,171] [WARNING] Missing dependencies in /home/emilio/Documents/ai/pizza/src/visualization/visualization.py: constants
[2025-05-14 01:28:26,859] [WARNING] Execution test issue in /home/emilio/Documents/ai/pizza/src/visualization/visualization.py: Execution failed with error: Traceback (most recent call last):
  File "/home/emilio/Documents/ai/pizza/src/visualization/visualization.py", line 15, in <module>
    from .types import (
ImportError: attempted relative import with no known parent package

[2025-05-14 01:28:26,861] [WARNING] Validation passed with warnings for /home/emilio/Documents/ai/pizza/src/visualization/visualization.py
[2025-05-14 01:28:26,861] [INFO] Validating script: exceptions.py
[2025-05-14 01:28:26,870] [INFO] Validation passed for /home/emilio/Documents/ai/pizza/src/utils/exceptions.py
[2025-05-14 01:28:26,871] [INFO] Validating script: types.py
[2025-05-14 01:28:26,886] [WARNING] Execution test issue in /home/emilio/Documents/ai/pizza/src/utils/types.py: Execution failed with error: Traceback (most recent call last):
  File "/home/emilio/Documents/ai/pizza/src/utils/types.py", line 5, in <module>
    from typing import Dict, List, Tuple, Optional, Union, NamedTuple, Callable
  File "/usr/lib/python3.12/typing.py", line 27, in <module>
    import contextlib
  File "/usr/lib/python3.12/contextlib.py", line 7, in <module>
    from functools import wraps
  File "/usr/lib/python3.12/functools.py", line 22, in <module>
    from types import GenericAlias
  File "/home/emilio/Documents/ai/pizza/src/utils/types.py", line 5, in <module>
    from typing import Dict, List, Tuple, Optional, Union, NamedTuple, Callable
ImportError: cannot import name 'Dict' from partially initialized module 'typing' (most likely due to a circular import) (/usr/lib/python3.12/typing.py)

[2025-05-14 01:28:26,886] [WARNING] Validation passed with warnings for /home/emilio/Documents/ai/pizza/src/utils/types.py
[2025-05-14 01:28:26,886] [INFO] Validating script: power_manager.py
[2025-05-14 01:28:26,893] [WARNING] Missing dependencies in /home/emilio/Documents/ai/pizza/src/utils/power_manager.py: devices, constants, metrics
[2025-05-14 01:28:26,916] [WARNING] Execution test issue in /home/emilio/Documents/ai/pizza/src/utils/power_manager.py: Execution failed with error: Traceback (most recent call last):
  File "/home/emilio/Documents/ai/pizza/src/utils/power_manager.py", line 7, in <module>
    import logging
  File "/usr/lib/python3.12/logging/__init__.py", line 26, in <module>
    import sys, os, time, io, re, traceback, warnings, weakref, collections.abc
  File "/usr/lib/python3.12/re/__init__.py", line 124, in <module>
    import enum
  File "/usr/lib/python3.12/enum.py", line 3, in <module>
    from types import MappingProxyType, DynamicClassAttribute
  File "/home/emilio/Documents/ai/pizza/src/utils/types.py", line 5, in <module>
    from typing import Dict, List, Tuple, Optional, Union, NamedTuple, Callable
  File "/usr/lib/python3.12/typing.py", line 27, in <module>
    import contextlib
  File "/usr/lib/python3.12/contextlib.py", line 7, in <module>
    from functools import wraps
  File "/usr/lib/python3.12/functools.py", line 22, in <module>
    from types import GenericAlias
ImportError: cannot import name 'GenericAlias' from partially initialized module 'types' (most likely due to a circular import) (/home/emilio/Documents/ai/pizza/src/utils/types.py)

[2025-05-14 01:28:26,917] [WARNING] Validation passed with warnings for /home/emilio/Documents/ai/pizza/src/utils/power_manager.py
[2025-05-14 01:28:26,918] [INFO] Validating script: devices.py
[2025-05-14 01:28:26,919] [WARNING] Missing dependencies in /home/emilio/Documents/ai/pizza/src/utils/devices.py: constants, exceptions
[2025-05-14 01:28:26,938] [WARNING] Execution test issue in /home/emilio/Documents/ai/pizza/src/utils/devices.py: Execution failed with error: Traceback (most recent call last):
  File "/home/emilio/Documents/ai/pizza/src/utils/devices.py", line 6, in <module>
    import logging
  File "/usr/lib/python3.12/logging/__init__.py", line 26, in <module>
    import sys, os, time, io, re, traceback, warnings, weakref, collections.abc
  File "/usr/lib/python3.12/re/__init__.py", line 124, in <module>
    import enum
  File "/usr/lib/python3.12/enum.py", line 3, in <module>
    from types import MappingProxyType, DynamicClassAttribute
  File "/home/emilio/Documents/ai/pizza/src/utils/types.py", line 5, in <module>
    from typing import Dict, List, Tuple, Optional, Union, NamedTuple, Callable
  File "/usr/lib/python3.12/typing.py", line 27, in <module>
    import contextlib
  File "/usr/lib/python3.12/contextlib.py", line 7, in <module>
    from functools import wraps
  File "/usr/lib/python3.12/functools.py", line 22, in <module>
    from types import GenericAlias
ImportError: cannot import name 'GenericAlias' from partially initialized module 'types' (most likely due to a circular import) (/home/emilio/Documents/ai/pizza/src/utils/types.py)

[2025-05-14 01:28:26,939] [WARNING] Validation passed with warnings for /home/emilio/Documents/ai/pizza/src/utils/devices.py
[2025-05-14 01:28:26,939] [INFO] Validating script: validation.py
[2025-05-14 01:28:26,942] [WARNING] Missing dependencies in /home/emilio/Documents/ai/pizza/src/utils/validation.py: exceptions, constants
[2025-05-14 01:28:26,955] [WARNING] Execution test issue in /home/emilio/Documents/ai/pizza/src/utils/validation.py: Execution failed with error: Traceback (most recent call last):
  File "/home/emilio/Documents/ai/pizza/src/utils/validation.py", line 6, in <module>
    import json
  File "/usr/lib/python3.12/json/__init__.py", line 106, in <module>
    from .decoder import JSONDecoder, JSONDecodeError
  File "/usr/lib/python3.12/json/decoder.py", line 3, in <module>
    import re
  File "/usr/lib/python3.12/re/__init__.py", line 124, in <module>
    import enum
  File "/usr/lib/python3.12/enum.py", line 3, in <module>
    from types import MappingProxyType, DynamicClassAttribute
  File "/home/emilio/Documents/ai/pizza/src/utils/types.py", line 5, in <module>
    from typing import Dict, List, Tuple, Optional, Union, NamedTuple, Callable
  File "/usr/lib/python3.12/typing.py", line 27, in <module>
    import contextlib
  File "/usr/lib/python3.12/contextlib.py", line 7, in <module>
    from functools import wraps
  File "/usr/lib/python3.12/functools.py", line 22, in <module>
    from types import GenericAlias
ImportError: cannot import name 'GenericAlias' from partially initialized module 'types' (most likely due to a circular import) (/home/emilio/Documents/ai/pizza/src/utils/types.py)

[2025-05-14 01:28:26,956] [WARNING] Validation passed with warnings for /home/emilio/Documents/ai/pizza/src/utils/validation.py
[2025-05-14 01:28:26,956] [INFO] Validating script: memory.py
[2025-05-14 01:28:26,958] [WARNING] Missing dependencies in /home/emilio/Documents/ai/pizza/src/utils/memory.py: constants, exceptions
[2025-05-14 01:28:26,970] [WARNING] Execution test issue in /home/emilio/Documents/ai/pizza/src/utils/memory.py: Execution failed with error: Traceback (most recent call last):
  File "/home/emilio/Documents/ai/pizza/src/utils/memory.py", line 5, in <module>
    import torch
  File "/home/emilio/Documents/ai/pizza/.venv/lib/python3.12/site-packages/torch/__init__.py", line 14, in <module>
    import ctypes
  File "/usr/lib/python3.12/ctypes/__init__.py", line 4, in <module>
    import types as _types
  File "/home/emilio/Documents/ai/pizza/src/utils/types.py", line 5, in <module>
    from typing import Dict, List, Tuple, Optional, Union, NamedTuple, Callable
  File "/usr/lib/python3.12/typing.py", line 27, in <module>
    import contextlib
  File "/usr/lib/python3.12/contextlib.py", line 7, in <module>
    from functools import wraps
  File "/usr/lib/python3.12/functools.py", line 22, in <module>
    from types import GenericAlias
ImportError: cannot import name 'GenericAlias' from partially initialized module 'types' (most likely due to a circular import) (/home/emilio/Documents/ai/pizza/src/utils/types.py)

[2025-05-14 01:28:26,971] [WARNING] Validation passed with warnings for /home/emilio/Documents/ai/pizza/src/utils/memory.py
[2025-05-14 01:28:26,971] [INFO] Validating script: temporal_smoother.py
[2025-05-14 01:28:26,986] [WARNING] Execution test issue in /home/emilio/Documents/ai/pizza/src/utils/temporal_smoother.py: Execution failed with error: Traceback (most recent call last):
  File "/home/emilio/Documents/ai/pizza/src/utils/temporal_smoother.py", line 9, in <module>
    import numpy as np
  File "/home/emilio/Documents/ai/pizza/.venv/lib/python3.12/site-packages/numpy/__init__.py", line 92, in <module>
    from ._globals import _NoValue, _CopyMode
  File "/home/emilio/Documents/ai/pizza/.venv/lib/python3.12/site-packages/numpy/_globals.py", line 18, in <module>
    import enum
  File "/usr/lib/python3.12/enum.py", line 3, in <module>
    from types import MappingProxyType, DynamicClassAttribute
  File "/home/emilio/Documents/ai/pizza/src/utils/types.py", line 5, in <module>
    from typing import Dict, List, Tuple, Optional, Union, NamedTuple, Callable
  File "/usr/lib/python3.12/typing.py", line 27, in <module>
    import contextlib
  File "/usr/lib/python3.12/contextlib.py", line 7, in <module>
    from functools import wraps
  File "/usr/lib/python3.12/functools.py", line 22, in <module>
    from types import GenericAlias
ImportError: cannot import name 'GenericAlias' from partially initialized module 'types' (most likely due to a circular import) (/home/emilio/Documents/ai/pizza/src/utils/types.py)

[2025-05-14 01:28:26,988] [WARNING] Validation passed with warnings for /home/emilio/Documents/ai/pizza/src/utils/temporal_smoother.py
[2025-05-14 01:28:26,988] [INFO] Validating script: utils.py
[2025-05-14 01:28:27,002] [WARNING] Execution test issue in /home/emilio/Documents/ai/pizza/src/utils/utils.py: Execution failed with error: Traceback (most recent call last):
  File "/home/emilio/Documents/ai/pizza/src/utils/utils.py", line 6, in <module>
    import logging
  File "/usr/lib/python3.12/logging/__init__.py", line 26, in <module>
    import sys, os, time, io, re, traceback, warnings, weakref, collections.abc
  File "/usr/lib/python3.12/re/__init__.py", line 124, in <module>
    import enum
  File "/usr/lib/python3.12/enum.py", line 3, in <module>
    from types import MappingProxyType, DynamicClassAttribute
  File "/home/emilio/Documents/ai/pizza/src/utils/types.py", line 5, in <module>
    from typing import Dict, List, Tuple, Optional, Union, NamedTuple, Callable
  File "/usr/lib/python3.12/typing.py", line 27, in <module>
    import contextlib
  File "/usr/lib/python3.12/contextlib.py", line 7, in <module>
    from functools import wraps
  File "/usr/lib/python3.12/functools.py", line 22, in <module>
    from types import GenericAlias
ImportError: cannot import name 'GenericAlias' from partially initialized module 'types' (most likely due to a circular import) (/home/emilio/Documents/ai/pizza/src/utils/types.py)

[2025-05-14 01:28:27,003] [WARNING] Validation passed with warnings for /home/emilio/Documents/ai/pizza/src/utils/utils.py
[2025-05-14 01:28:27,003] [INFO] Validating script: constants.py
[2025-05-14 01:28:27,018] [WARNING] Execution test issue in /home/emilio/Documents/ai/pizza/src/utils/constants.py: Execution failed with error: Traceback (most recent call last):
  File "/home/emilio/Documents/ai/pizza/src/utils/constants.py", line 5, in <module>
    from pathlib import Path
  File "/usr/lib/python3.12/pathlib.py", line 8, in <module>
    import fnmatch
  File "/usr/lib/python3.12/fnmatch.py", line 14, in <module>
    import re
  File "/usr/lib/python3.12/re/__init__.py", line 124, in <module>
    import enum
  File "/usr/lib/python3.12/enum.py", line 3, in <module>
    from types import MappingProxyType, DynamicClassAttribute
  File "/home/emilio/Documents/ai/pizza/src/utils/types.py", line 5, in <module>
    from typing import Dict, List, Tuple, Optional, Union, NamedTuple, Callable
  File "/usr/lib/python3.12/typing.py", line 27, in <module>
    import contextlib
  File "/usr/lib/python3.12/contextlib.py", line 7, in <module>
    from functools import wraps
  File "/usr/lib/python3.12/functools.py", line 22, in <module>
    from types import GenericAlias
ImportError: cannot import name 'GenericAlias' from partially initialized module 'types' (most likely due to a circular import) (/home/emilio/Documents/ai/pizza/src/utils/types.py)

[2025-05-14 01:28:27,018] [WARNING] Validation passed with warnings for /home/emilio/Documents/ai/pizza/src/utils/constants.py
[2025-05-14 01:28:27,018] [INFO] Validating script: enhanced_pizza_augmentation.py
[2025-05-14 01:28:29,094] [WARNING] Execution test issue in /home/emilio/Documents/ai/pizza/src/augmentation/enhanced_pizza_augmentation.py: Execution failed with error: 
[2025-05-14 01:28:29,102] [WARNING] Missing or incomplete docstring in /home/emilio/Documents/ai/pizza/src/augmentation/enhanced_pizza_augmentation.py
[2025-05-14 01:28:29,103] [WARNING] Validation passed with warnings for /home/emilio/Documents/ai/pizza/src/augmentation/enhanced_pizza_augmentation.py
[2025-05-14 01:28:29,103] [INFO] Validating script: augmentation_optimized.py
[2025-05-14 01:28:31,304] [WARNING] Execution test issue in /home/emilio/Documents/ai/pizza/src/augmentation/augmentation_optimized.py: Execution failed with error: Traceback (most recent call last):
  File "/home/emilio/Documents/ai/pizza/src/augmentation/augmentation_optimized.py", line 698, in <module>
    main()
  File "/home/emilio/Documents/ai/pizza/src/augmentation/augmentation_optimized.py", line 688, in main
    augment_pizza_dataset(input_dir, output_dir, img_per_original=img_per_original, batch_size=batch_size)
  File "/home/emilio/Documents/ai/pizza/src/augmentation/augmentation_optimized.py", line 512, in augment_pizza_dataset
    image_files = [os.path.join(input_dir, f) for f in os.listdir(input_dir) 
                                                       ^^^^^^^^^^^^^^^^^^^^^
FileNotFoundError: [Errno 2] No such file or directory: '/home/emilio/Documents/ai/pizza/img-pizza/'

[2025-05-14 01:28:31,307] [WARNING] Missing or incomplete docstring in /home/emilio/Documents/ai/pizza/src/augmentation/augmentation_optimized.py
[2025-05-14 01:28:31,307] [WARNING] Validation passed with warnings for /home/emilio/Documents/ai/pizza/src/augmentation/augmentation_optimized.py
[2025-05-14 01:28:31,307] [INFO] Validating script: diffusion_pizza_generator.py
[2025-05-14 01:28:35,662] [INFO] Validation passed for /home/emilio/Documents/ai/pizza/src/augmentation/diffusion_pizza_generator.py
[2025-05-14 01:28:35,662] [INFO] Validating script: augmentation.py
[2025-05-14 01:28:37,860] [WARNING] Execution test issue in /home/emilio/Documents/ai/pizza/src/augmentation/augmentation.py: Execution failed with error: 
[2025-05-14 01:28:37,869] [WARNING] Missing or incomplete docstring in /home/emilio/Documents/ai/pizza/src/augmentation/augmentation.py
[2025-05-14 01:28:37,869] [WARNING] Validation passed with warnings for /home/emilio/Documents/ai/pizza/src/augmentation/augmentation.py
[2025-05-14 01:28:37,869] [INFO] Validating script: advanced_pizza_diffusion_control.py
[2025-05-14 01:28:37,891] [WARNING] Execution test issue in /home/emilio/Documents/ai/pizza/src/augmentation/advanced_pizza_diffusion_control.py: Execution failed with error:   File "/home/emilio/Documents/ai/pizza/src/augmentation/advanced_pizza_diffusion_control.py", line 293
    image_size=image_size,
    ^^^^^^^^^^^^^^^^^^^^^
SyntaxError: keyword argument repeated: image_size

[2025-05-14 01:28:37,895] [WARNING] Validation passed with warnings for /home/emilio/Documents/ai/pizza/src/augmentation/advanced_pizza_diffusion_control.py
[2025-05-14 01:28:37,895] [INFO] Validating script: optimized-pizza-augmentation.py
[2025-05-14 01:28:40,083] [WARNING] Execution test issue in /home/emilio/Documents/ai/pizza/src/augmentation/optimized-pizza-augmentation.py: Execution failed with error: Traceback (most recent call last):
  File "/home/emilio/Documents/ai/pizza/src/augmentation/optimized-pizza-augmentation.py", line 698, in <module>
    main()
  File "/home/emilio/Documents/ai/pizza/src/augmentation/optimized-pizza-augmentation.py", line 688, in main
    augment_pizza_dataset(input_dir, output_dir, img_per_original=img_per_original, batch_size=batch_size)
  File "/home/emilio/Documents/ai/pizza/src/augmentation/optimized-pizza-augmentation.py", line 512, in augment_pizza_dataset
    image_files = [os.path.join(input_dir, f) for f in os.listdir(input_dir) 
                                                       ^^^^^^^^^^^^^^^^^^^^^
FileNotFoundError: [Errno 2] No such file or directory: '/home/emilio/Documents/ai/pizza/img-pizza/'

[2025-05-14 01:28:40,087] [WARNING] Missing or incomplete docstring in /home/emilio/Documents/ai/pizza/src/augmentation/optimized-pizza-augmentation.py
[2025-05-14 01:28:40,088] [WARNING] Validation passed with warnings for /home/emilio/Documents/ai/pizza/src/augmentation/optimized-pizza-augmentation.py
[2025-05-14 01:28:40,088] [INFO] Validating script: augment_legacy.py
[2025-05-14 01:28:41,993] [WARNING] Execution test issue in /home/emilio/Documents/ai/pizza/src/legacy/augment_legacy.py: Execution failed with error: Traceback (most recent call last):
  File "/home/emilio/Documents/ai/pizza/src/legacy/augment_legacy.py", line 176, in <module>
    augment_pizza(input_dir, output_dir, num_images, batch_size) 
    ^^^^^^^^^^^^^^^^^^^^^^^^^^^^^^^^^^^^^^^^^^^^^^^^^^^^^^^^^^^^
  File "/home/emilio/Documents/ai/pizza/src/legacy/augment_legacy.py", line 131, in augment_pizza
    image_files = [os.path.join(input_dir, f) for f in os.listdir(input_dir) 
                                                       ^^^^^^^^^^^^^^^^^^^^^
FileNotFoundError: [Errno 2] No such file or directory: 'img-pizza'

[2025-05-14 01:28:41,994] [WARNING] Missing or incomplete docstring in /home/emilio/Documents/ai/pizza/src/legacy/augment_legacy.py
[2025-05-14 01:28:41,994] [WARNING] Validation passed with warnings for /home/emilio/Documents/ai/pizza/src/legacy/augment_legacy.py
[2025-05-14 01:28:41,994] [INFO] Validating script: diffusion_data_agent.py
[2025-05-14 01:28:42,001] [WARNING] Missing dependencies in /home/emilio/Documents/ai/pizza/src/integration/diffusion_data_agent.py: cleanfid
[2025-05-14 01:28:43,680] [WARNING] Validation passed with warnings for /home/emilio/Documents/ai/pizza/src/integration/diffusion_data_agent.py
[2025-05-14 01:28:43,680] [INFO] Validating script: pizza_diffusion_integration.py
[2025-05-14 01:28:43,685] [WARNING] Missing dependencies in /home/emilio/Documents/ai/pizza/src/integration/pizza_diffusion_integration.py: enhanced_pizza_augmentation, diffusion_data_agent, optimized_pizza_augmentation
[2025-05-14 01:28:45,358] [WARNING] Execution test issue in /home/emilio/Documents/ai/pizza/src/integration/pizza_diffusion_integration.py: Execution failed with error: Traceback (most recent call last):
  File "/home/emilio/Documents/ai/pizza/src/integration/pizza_diffusion_integration.py", line 29, in <module>
    from enhanced_pizza_augmentation import (
ModuleNotFoundError: No module named 'enhanced_pizza_augmentation'

During handling of the above exception, another exception occurred:

Traceback (most recent call last):
  File "/home/emilio/Documents/ai/pizza/src/integration/pizza_diffusion_integration.py", line 40, in <module>
    from optimized_pizza_augmentation import (
ModuleNotFoundError: No module named 'optimized_pizza_augmentation'

During handling of the above exception, another exception occurred:

Traceback (most recent call last):
  File "/home/emilio/Documents/ai/pizza/src/integration/pizza_diffusion_integration.py", line 49, in <module>
    from test import (
ImportError: cannot import name 'PizzaBurningEffect' from 'test' (/usr/lib/python3.12/test/__init__.py)

[2025-05-14 01:28:45,360] [WARNING] Validation passed with warnings for /home/emilio/Documents/ai/pizza/src/integration/pizza_diffusion_integration.py
[2025-05-14 01:28:45,360] [INFO] Validating script: diffusion_training_integration.py
[2025-05-14 01:28:49,722] [WARNING] Execution test issue in /home/emilio/Documents/ai/pizza/src/integration/diffusion_training_integration.py: Execution failed with error: 2025-05-14 01:28:47.402270: I tensorflow/core/util/port.cc:153] oneDNN custom operations are on. You may see slightly different numerical results due to floating-point round-off errors from different computation orders. To turn them off, set the environment variable `TF_ENABLE_ONEDNN_OPTS=0`.
2025-05-14 01:28:47.410425: E external/local_xla/xla/stream_executor/cuda/cuda_fft.cc:467] Unable to register cuFFT factory: Attempting to register factory for plugin cuFFT when one has already been registered
WARNING: All log messages before absl::InitializeLog() is called are written to STDERR
E0000 00:00:1747178927.420314  168874 cuda_dnn.cc:8579] Unable to register cuDNN factory: Attempting to register factory for plugin cuDNN when one has already been registered
E0000 00:00:1747178927.423223  168874 cuda_blas.cc:1407] Unable to register cuBLAS factory: Attempting to register factory for plugin cuBLAS when one has already been registered
W0000 00:00:1747178927.430600  168874 computation_placer.cc:177] computation placer already registered. Please check linkage and avoid linking the same target more than once.
W0000 00:00:1747178927.430610  168874 computation_placer.cc:177] computation placer already registered. Please check linkage and avoid linking the same target more than once.
W0000 00:00:1747178927.430611  168874 computation_placer.cc:177] computation placer already registered. Please check linkage and avoid linking the same target more than once.
W0000 00:00:1747178927.430612  168874 computation_placer.cc:177] computation placer already registered. Please check linkage and avoid linking the same target more than once.
2025-05-14 01:28:47.433134: I tensorflow/core/platform/cpu_feature_guard.cc:210] This TensorFlow binary is optimized to use available CPU instructions in performance-critical operations.
To enable the following instructions: AVX2 AVX_VNNI FMA, in other operations, rebuild TensorFlow with the appropriate compiler flags.
Traceback (most recent call last):
  File "/home/emilio/Documents/ai/pizza/src/integration/diffusion_training_integration.py", line 42, in <module>
    from src.augmentation.advanced_pizza_diffusion_control import AdvancedPizzaDiffusionControl
  File "/home/emilio/Documents/ai/pizza/src/augmentation/advanced_pizza_diffusion_control.py", line 293
    image_size=image_size,
    ^^^^^^^^^^^^^^^^^^^^^
SyntaxError: keyword argument repeated: image_size

[2025-05-14 01:28:49,726] [WARNING] Validation passed with warnings for /home/emilio/Documents/ai/pizza/src/integration/diffusion_training_integration.py
[2025-05-14 01:28:49,727] [INFO] Validation complete. Summary: 19 passed, 55 with warnings, 0 failed
[2025-05-14 01:28:49,728] [INFO] Report written to /home/emilio/Documents/ai/pizza/output/pipeline_runs/20250514_012730/reports/validation_report.json
