[2025-05-14 01:50:22,571] [INFO] Found 75 Python scripts to validate
[2025-05-14 01:50:22,571] [INFO] Validating script: cleanup.py
[2025-05-14 01:50:22,643] [INFO] Validation passed for /home/emilio/Documents/ai/pizza/scripts/cleanup.py
[2025-05-14 01:50:22,643] [INFO] Validating script: filter_dataset.py
[2025-05-14 01:50:22,654] [WARNING] Missing or incomplete docstring in /home/emilio/Documents/ai/pizza/scripts/filter_dataset.py
[2025-05-14 01:50:22,654] [WARNING] Validation passed with warnings for /home/emilio/Documents/ai/pizza/scripts/filter_dataset.py
[2025-05-14 01:50:22,654] [INFO] Validating script: label_tool.py
[2025-05-14 01:50:25,724] [INFO] Validation passed for /home/emilio/Documents/ai/pizza/scripts/label_tool.py
[2025-05-14 01:50:25,724] [INFO] Validating script: framebuffer_demo.py
[2025-05-14 01:50:25,848] [WARNING] Execution test issue in /home/emilio/Documents/ai/pizza/scripts/framebuffer_demo.py: Execution failed with error: 
[2025-05-14 01:50:25,850] [WARNING] Validation passed with warnings for /home/emilio/Documents/ai/pizza/scripts/framebuffer_demo.py
[2025-05-14 01:50:25,850] [INFO] Validating script: compare_inverted_residual.py
[2025-05-14 01:50:31,345] [INFO] Validation passed for /home/emilio/Documents/ai/pizza/scripts/compare_inverted_residual.py
[2025-05-14 01:50:31,346] [INFO] Validating script: test_temporal_smoothing.py
[2025-05-14 01:50:31,834] [INFO] Validation passed for /home/emilio/Documents/ai/pizza/scripts/test_temporal_smoothing.py
[2025-05-14 01:50:31,834] [INFO] Validating script: knowledge_distillation.py
[2025-05-14 01:50:34,804] [INFO] Validation passed for /home/emilio/Documents/ai/pizza/scripts/knowledge_distillation.py
[2025-05-14 01:50:34,804] [INFO] Validating script: visualize_gradcam.py
[2025-05-14 01:50:35,696] [WARNING] Missing dependencies in /home/emilio/Documents/ai/pizza/scripts/visualize_gradcam.py: scripts
[2025-05-14 01:50:39,456] [WARNING] Validation passed with warnings for /home/emilio/Documents/ai/pizza/scripts/visualize_gradcam.py
[2025-05-14 01:50:39,456] [INFO] Validating script: classify_images.py
[2025-05-14 01:50:39,468] [WARNING] Missing or incomplete docstring in /home/emilio/Documents/ai/pizza/scripts/classify_images.py
[2025-05-14 01:50:39,468] [WARNING] Validation passed with warnings for /home/emilio/Documents/ai/pizza/scripts/classify_images.py
[2025-05-14 01:50:39,468] [INFO] Validating script: visualize_pruning.py
[2025-05-14 01:50:42,964] [INFO] Validation passed for /home/emilio/Documents/ai/pizza/scripts/visualize_pruning.py
[2025-05-14 01:50:42,965] [INFO] Validating script: compare_tiny_cnns.py
[2025-05-14 01:50:43,005] [WARNING] Missing dependencies in /home/emilio/Documents/ai/pizza/scripts/compare_tiny_cnns.py: scripts
[2025-05-14 01:50:46,508] [WARNING] Validation passed with warnings for /home/emilio/Documents/ai/pizza/scripts/compare_tiny_cnns.py
[2025-05-14 01:50:46,508] [INFO] Validating script: compare_se_models.py
[2025-05-14 01:50:49,936] [INFO] Validation passed for /home/emilio/Documents/ai/pizza/scripts/compare_se_models.py
[2025-05-14 01:50:49,936] [INFO] Validating script: automated_test_suite.py
[2025-05-14 01:50:52,782] [WARNING] Execution test issue in /home/emilio/Documents/ai/pizza/scripts/automated_test_suite.py: Execution failed with error: Traceback (most recent call last):
  File "/home/emilio/Documents/ai/pizza/scripts/automated_test_suite.py", line 53, in <module>
    from src.pizza_detector import (
ImportError: cannot import name 'load_model' from 'src.pizza_detector' (/home/emilio/Documents/ai/pizza/src/pizza_detector.py)

[2025-05-14 01:50:52,787] [WARNING] Validation passed with warnings for /home/emilio/Documents/ai/pizza/scripts/automated_test_suite.py
[2025-05-14 01:50:52,787] [INFO] Validating script: compare_hard_swish.py
[2025-05-14 01:50:55,279] [INFO] Validation passed for /home/emilio/Documents/ai/pizza/scripts/compare_hard_swish.py
[2025-05-14 01:50:55,279] [INFO] Validating script: demo_status_display.py
[2025-05-14 01:50:55,306] [WARNING] Execution test issue in /home/emilio/Documents/ai/pizza/scripts/demo_status_display.py: Execution failed with error: Traceback (most recent call last):
  File "/home/emilio/Documents/ai/pizza/scripts/demo_status_display.py", line 38, in <module>
    from src.status_display import (
ModuleNotFoundError: No module named 'src.status_display'

[2025-05-14 01:50:55,307] [WARNING] Validation passed with warnings for /home/emilio/Documents/ai/pizza/scripts/demo_status_display.py
[2025-05-14 01:50:55,307] [INFO] Validating script: test_image_preprocessing.py
[2025-05-14 01:50:55,625] [INFO] Validation passed for /home/emilio/Documents/ai/pizza/scripts/test_image_preprocessing.py
[2025-05-14 01:50:55,625] [INFO] Validating script: test_pizza_detection.py
[2025-05-14 01:50:57,597] [WARNING] Execution test issue in /home/emilio/Documents/ai/pizza/scripts/test_pizza_detection.py: Execution failed with error: Traceback (most recent call last):
  File "/home/emilio/Documents/ai/pizza/scripts/test_pizza_detection.py", line 27, in <module>
    from src.types import InferenceResult
ModuleNotFoundError: No module named 'src.types'

[2025-05-14 01:50:57,598] [WARNING] Validation passed with warnings for /home/emilio/Documents/ai/pizza/scripts/test_pizza_detection.py
[2025-05-14 01:50:57,598] [INFO] Validating script: demo_power_management.py
[2025-05-14 01:50:57,897] [WARNING] Execution test issue in /home/emilio/Documents/ai/pizza/scripts/demo_power_management.py: Execution failed with error: Traceback (most recent call last):
  File "/home/emilio/Documents/ai/pizza/scripts/demo_power_management.py", line 19, in <module>
    from src.emulator import RP2040Emulator
ModuleNotFoundError: No module named 'src.emulator'

[2025-05-14 01:50:57,899] [WARNING] Validation passed with warnings for /home/emilio/Documents/ai/pizza/scripts/demo_power_management.py
[2025-05-14 01:50:57,899] [INFO] Validating script: analyze_performance_logs.py
[2025-05-14 01:50:58,645] [INFO] Validation passed for /home/emilio/Documents/ai/pizza/scripts/analyze_performance_logs.py
[2025-05-14 01:50:58,645] [INFO] Validating script: simulate_memory_constraints.py
[2025-05-14 01:50:58,950] [WARNING] Execution test issue in /home/emilio/Documents/ai/pizza/scripts/simulate_memory_constraints.py: Execution failed with error: Traceback (most recent call last):
  File "/home/emilio/Documents/ai/pizza/scripts/simulate_memory_constraints.py", line 17, in <module>
    from src.constants import (
ImportError: cannot import name 'RP2040_CLOCK_SPEED_MHZ' from 'src.constants' (/home/emilio/Documents/ai/pizza/src/constants.py). Did you mean: 'RP2040_CLOCK_SPEED'?

[2025-05-14 01:50:58,953] [WARNING] Validation passed with warnings for /home/emilio/Documents/ai/pizza/scripts/simulate_memory_constraints.py
[2025-05-14 01:50:58,953] [INFO] Validating script: simulate_clahe_resources.py
[2025-05-14 01:50:59,265] [INFO] Validation passed for /home/emilio/Documents/ai/pizza/scripts/simulate_clahe_resources.py
[2025-05-14 01:50:59,266] [INFO] Validating script: run_pizza_tests.py
[2025-05-14 01:50:59,294] [INFO] Validation passed for /home/emilio/Documents/ai/pizza/scripts/run_pizza_tests.py
[2025-05-14 01:50:59,294] [INFO] Validating script: run_pruning_clustering.py
[2025-05-14 01:50:59,297] [WARNING] Missing dependencies in /home/emilio/Documents/ai/pizza/scripts/run_pruning_clustering.py: config, scripts
[2025-05-14 01:51:01,199] [WARNING] Validation passed with warnings for /home/emilio/Documents/ai/pizza/scripts/run_pruning_clustering.py
[2025-05-14 01:51:01,199] [INFO] Validating script: augment_dataset.py
[2025-05-14 01:51:01,293] [INFO] Validation passed for /home/emilio/Documents/ai/pizza/scripts/augment_dataset.py
[2025-05-14 01:51:01,293] [INFO] Validating script: train_pizza_model.py
[2025-05-14 01:51:03,181] [INFO] Validation passed for /home/emilio/Documents/ai/pizza/scripts/train_pizza_model.py
[2025-05-14 01:51:03,181] [INFO] Validating script: simulate_lighting_conditions.py
[2025-05-14 01:51:03,471] [WARNING] Execution test issue in /home/emilio/Documents/ai/pizza/scripts/simulate_lighting_conditions.py: Execution failed with error: Traceback (most recent call last):
  File "/home/emilio/Documents/ai/pizza/scripts/simulate_lighting_conditions.py", line 17, in <module>
    from src.emulator import RP2040Emulator
ModuleNotFoundError: No module named 'src.emulator'

[2025-05-14 01:51:03,472] [WARNING] Validation passed with warnings for /home/emilio/Documents/ai/pizza/scripts/simulate_lighting_conditions.py
[2025-05-14 01:51:03,472] [INFO] Validating script: quantization_aware_training.py
[2025-05-14 01:51:05,410] [INFO] Validation passed for /home/emilio/Documents/ai/pizza/scripts/quantization_aware_training.py
[2025-05-14 01:51:05,410] [INFO] Validating script: simulate_power_consumption.py
[2025-05-14 01:51:05,678] [WARNING] Execution test issue in /home/emilio/Documents/ai/pizza/scripts/simulate_power_consumption.py: Execution failed with error: Traceback (most recent call last):
  File "/home/emilio/Documents/ai/pizza/scripts/simulate_power_consumption.py", line 18, in <module>
    from src.constants import (
ImportError: cannot import name 'RP2040_CLOCK_SPEED_MHZ' from 'src.constants' (/home/emilio/Documents/ai/pizza/src/constants.py). Did you mean: 'RP2040_CLOCK_SPEED'?

[2025-05-14 01:51:05,680] [WARNING] Validation passed with warnings for /home/emilio/Documents/ai/pizza/scripts/simulate_power_consumption.py
[2025-05-14 01:51:05,680] [INFO] Validating script: generate_pizza_dataset.py
[2025-05-14 01:51:10,110] [INFO] Validation passed for /home/emilio/Documents/ai/pizza/scripts/generate_pizza_dataset.py
[2025-05-14 01:51:10,110] [INFO] Validating script: hyperparameter_search.py
[2025-05-14 01:51:12,551] [INFO] Validation passed for /home/emilio/Documents/ai/pizza/scripts/hyperparameter_search.py
[2025-05-14 01:51:12,551] [INFO] Validating script: extract_frames.py
[2025-05-14 01:51:12,565] [WARNING] Missing or incomplete docstring in /home/emilio/Documents/ai/pizza/scripts/extract_frames.py
[2025-05-14 01:51:12,565] [WARNING] Validation passed with warnings for /home/emilio/Documents/ai/pizza/scripts/extract_frames.py
[2025-05-14 01:51:12,565] [INFO] Validating script: validate_integration.py
[2025-05-14 01:51:12,600] [INFO] Validation passed for /home/emilio/Documents/ai/pizza/scripts/ci/validate_integration.py
[2025-05-14 01:51:12,600] [INFO] Validating script: validate_scripts.py
[2025-05-14 01:51:12,682] [INFO] Validation passed for /home/emilio/Documents/ai/pizza/scripts/ci/validate_scripts.py
[2025-05-14 01:51:12,682] [INFO] Validating script: generate_pipeline_report.py
[2025-05-14 01:51:12,970] [INFO] Validation passed for /home/emilio/Documents/ai/pizza/scripts/ci/generate_pipeline_report.py
[2025-05-14 01:51:12,970] [INFO] Validating script: generate_optimization_summary.py
[2025-05-14 01:51:13,254] [INFO] Validation passed for /home/emilio/Documents/ai/pizza/scripts/ci/generate_optimization_summary.py
[2025-05-14 01:51:13,254] [INFO] Validating script: weight_pruning.py
[2025-05-14 01:51:13,262] [WARNING] Missing dependencies in /home/emilio/Documents/ai/pizza/scripts/model_optimization/weight_pruning.py: config
[2025-05-14 01:51:15,185] [WARNING] Validation passed with warnings for /home/emilio/Documents/ai/pizza/scripts/model_optimization/weight_pruning.py
[2025-05-14 01:51:15,185] [INFO] Validating script: micropizzanet_early_exit.py
[2025-05-14 01:51:17,106] [INFO] Validation passed for /home/emilio/Documents/ai/pizza/scripts/early_exit/micropizzanet_early_exit.py
[2025-05-14 01:51:17,107] [INFO] Validating script: verify_model.py
[2025-05-14 01:51:18,743] [WARNING] Missing or incomplete docstring in /home/emilio/Documents/ai/pizza/models/rp2040_export/verify_model.py
[2025-05-14 01:51:18,744] [WARNING] Validation passed with warnings for /home/emilio/Documents/ai/pizza/models/rp2040_export/verify_model.py
[2025-05-14 01:51:18,744] [INFO] Validating script: pizza-baking-detection-final.py
[2025-05-14 01:51:19,795] [WARNING] Missing dependencies in /home/emilio/Documents/ai/pizza/src/pizza-baking-detection-final.py: onnx_tf
[2025-05-14 01:51:21,684] [WARNING] Execution test issue in /home/emilio/Documents/ai/pizza/src/pizza-baking-detection-final.py: Execution failed with error: 2025-05-14 01:51:21,295 - INFO - ================================================================================
2025-05-14 01:51:21,295 - INFO - RP2040 PIZZA-ERKENNUNGSSYSTEM - DETAILLIERTE KONFIGURATION
2025-05-14 01:51:21,295 - INFO - ================================================================================
2025-05-14 01:51:21,295 - INFO - Hardware: RP2040 - 133MHz, 264KB RAM, 2048KB Flash
2025-05-14 01:51:21,295 - INFO - Kamera: OV2640 - 320x240, 7 FPS
2025-05-14 01:51:21,295 - INFO - Stromversorgung: CR123A - 1500mAh, 8.33h aktiv, 3000.00h standby
2025-05-14 01:51:21,295 - INFO - Modellparameter: 48x48 Eingabegröße, 8-Bit Quantisierung
2025-05-14 01:51:21,295 - INFO - Speicherbeschränkungen: Max. 180KB Modellgröße, 100KB Laufzeit-RAM
2025-05-14 01:51:21,295 - INFO - ================================================================================
2025-05-14 01:51:21,295 - INFO - Analysiere Datensatz in augmented_pizza...

Analysiere Bilder:   0%|          | 0/1 [00:00<?, ?it/s]2025-05-14 01:51:21,317 - WARNING - Fehler beim Analysieren von augmented_pizza/raw/sample_pizza_image.jpg: cannot identify image file 'augmented_pizza/raw/sample_pizza_image.jpg'

Analysiere Bilder: 100%|██████████| 1/1 [00:00<00:00, 48.37it/s]
2025-05-14 01:51:21,317 - ERROR - Fehler im Optimierungsprozess: not enough values to unpack (expected 2, got 0)
Traceback (most recent call last):
  File "/home/emilio/Documents/ai/pizza/src/pizza-baking-detection-final.py", line 2231, in main
    preprocessing_params = analyzer.analyze(sample_size=50)
                           ^^^^^^^^^^^^^^^^^^^^^^^^^^^^^^^^
  File "/home/emilio/Documents/ai/pizza/src/pizza-baking-detection-final.py", line 175, in analyze
    widths, heights = zip(*self.stats['image_sizes'])
    ^^^^^^^^^^^^^^^
ValueError: not enough values to unpack (expected 2, got 0)
Traceback (most recent call last):
  File "/home/emilio/Documents/ai/pizza/src/pizza-baking-detection-final.py", line 2302, in <module>
    main()
  File "/home/emilio/Documents/ai/pizza/src/pizza-baking-detection-final.py", line 2231, in main
    preprocessing_params = analyzer.analyze(sample_size=50)
                           ^^^^^^^^^^^^^^^^^^^^^^^^^^^^^^^^
  File "/home/emilio/Documents/ai/pizza/src/pizza-baking-detection-final.py", line 175, in analyze
    widths, heights = zip(*self.stats['image_sizes'])
    ^^^^^^^^^^^^^^^
ValueError: not enough values to unpack (expected 2, got 0)

[2025-05-14 01:51:21,694] [WARNING] Missing or incomplete docstring in /home/emilio/Documents/ai/pizza/src/pizza-baking-detection-final.py
[2025-05-14 01:51:21,694] [WARNING] Validation passed with warnings for /home/emilio/Documents/ai/pizza/src/pizza-baking-detection-final.py
[2025-05-14 01:51:21,694] [INFO] Validating script: metrics.py
[2025-05-14 01:51:22,829] [INFO] Validation passed for /home/emilio/Documents/ai/pizza/src/metrics.py
[2025-05-14 01:51:22,829] [INFO] Validating script: __init__.py
[2025-05-14 01:51:22,838] [WARNING] Missing or incomplete docstring in /home/emilio/Documents/ai/pizza/src/__init__.py
[2025-05-14 01:51:22,838] [WARNING] Validation passed with warnings for /home/emilio/Documents/ai/pizza/src/__init__.py
[2025-05-14 01:51:22,838] [INFO] Validating script: pizza_detector.py
[2025-05-14 01:51:22,861] [WARNING] Missing dependencies in /home/emilio/Documents/ai/pizza/src/pizza_detector.py: onnx_tf
[2025-05-14 01:51:24,821] [WARNING] Execution test issue in /home/emilio/Documents/ai/pizza/src/pizza_detector.py: Execution failed with error: 2025-05-14 01:51:24,437 - INFO - ================================================================================
2025-05-14 01:51:24,437 - INFO - RP2040 PIZZA-ERKENNUNGSSYSTEM - DETAILLIERTE KONFIGURATION
2025-05-14 01:51:24,437 - INFO - ================================================================================
2025-05-14 01:51:24,437 - INFO - Hardware: RP2040 - 133MHz, 264KB RAM, 2048KB Flash
2025-05-14 01:51:24,437 - INFO - Kamera: OV2640 - 320x240, 7 FPS
2025-05-14 01:51:24,437 - INFO - Stromversorgung: CR123A - 1500mAh, 8.33h aktiv, 3000.00h standby
2025-05-14 01:51:24,437 - INFO - Modellparameter: 48x48 Eingabegröße, 8-Bit Quantisierung
2025-05-14 01:51:24,437 - INFO - Speicherbeschränkungen: Max. 180KB Modellgröße, 100KB Laufzeit-RAM
2025-05-14 01:51:24,437 - INFO - ================================================================================
2025-05-14 01:51:24,437 - INFO - Analysiere Datensatz in augmented_pizza...

Analysiere Bilder:   0%|          | 0/1 [00:00<?, ?it/s]2025-05-14 01:51:24,450 - WARNING - Fehler beim Analysieren von augmented_pizza/raw/sample_pizza_image.jpg: cannot identify image file 'augmented_pizza/raw/sample_pizza_image.jpg'

Analysiere Bilder: 100%|██████████| 1/1 [00:00<00:00, 80.57it/s]
2025-05-14 01:51:24,450 - ERROR - Fehler im Optimierungsprozess: not enough values to unpack (expected 2, got 0)
Traceback (most recent call last):
  File "/home/emilio/Documents/ai/pizza/src/pizza_detector.py", line 2476, in main
    preprocessing_params = analyzer.analyze(sample_size=50)
                           ^^^^^^^^^^^^^^^^^^^^^^^^^^^^^^^^
  File "/home/emilio/Documents/ai/pizza/src/pizza_detector.py", line 175, in analyze
    widths, heights = zip(*self.stats['image_sizes'])
    ^^^^^^^^^^^^^^^
ValueError: not enough values to unpack (expected 2, got 0)
Traceback (most recent call last):
  File "/home/emilio/Documents/ai/pizza/src/pizza_detector.py", line 2547, in <module>
    main()
  File "/home/emilio/Documents/ai/pizza/src/pizza_detector.py", line 2476, in main
    preprocessing_params = analyzer.analyze(sample_size=50)
                           ^^^^^^^^^^^^^^^^^^^^^^^^^^^^^^^^
  File "/home/emilio/Documents/ai/pizza/src/pizza_detector.py", line 175, in analyze
    widths, heights = zip(*self.stats['image_sizes'])
    ^^^^^^^^^^^^^^^
ValueError: not enough values to unpack (expected 2, got 0)

[2025-05-14 01:51:24,829] [WARNING] Missing or incomplete docstring in /home/emilio/Documents/ai/pizza/src/pizza_detector.py
[2025-05-14 01:51:24,830] [WARNING] Validation passed with warnings for /home/emilio/Documents/ai/pizza/src/pizza_detector.py
[2025-05-14 01:51:24,830] [INFO] Validating script: constants.py
[2025-05-14 01:51:24,851] [INFO] Validation passed for /home/emilio/Documents/ai/pizza/src/constants.py
[2025-05-14 01:51:24,851] [INFO] Validating script: test_frame_buffer.py
[2025-05-14 01:51:24,854] [WARNING] Missing dependencies in /home/emilio/Documents/ai/pizza/src/emulation/test_frame_buffer.py: frame_buffer
[2025-05-14 01:51:24,938] [WARNING] Validation passed with warnings for /home/emilio/Documents/ai/pizza/src/emulation/test_frame_buffer.py
[2025-05-14 01:51:24,938] [INFO] Validating script: emulator-test.py
[2025-05-14 01:51:25,050] [WARNING] Missing or incomplete docstring in /home/emilio/Documents/ai/pizza/src/emulation/emulator-test.py
[2025-05-14 01:51:25,050] [WARNING] Validation passed with warnings for /home/emilio/Documents/ai/pizza/src/emulation/emulator-test.py
[2025-05-14 01:51:25,051] [INFO] Validating script: emulator.py
[2025-05-14 01:51:25,055] [WARNING] Missing dependencies in /home/emilio/Documents/ai/pizza/src/emulation/emulator.py: power_manager, exceptions, frame_buffer, constants
[2025-05-14 01:51:25,126] [WARNING] Execution test issue in /home/emilio/Documents/ai/pizza/src/emulation/emulator.py: Execution failed with error: Traceback (most recent call last):
  File "/home/emilio/Documents/ai/pizza/src/emulation/emulator.py", line 12, in <module>
    from .constants import (
ImportError: attempted relative import with no known parent package

[2025-05-14 01:51:25,128] [WARNING] Validation passed with warnings for /home/emilio/Documents/ai/pizza/src/emulation/emulator.py
[2025-05-14 01:51:25,128] [INFO] Validating script: frame_buffer.py
[2025-05-14 01:51:25,205] [INFO] Validation passed for /home/emilio/Documents/ai/pizza/src/emulation/frame_buffer.py
[2025-05-14 01:51:25,205] [INFO] Validating script: metrics.py
[2025-05-14 01:51:25,209] [WARNING] Missing dependencies in /home/emilio/Documents/ai/pizza/src/analysis/metrics.py: exceptions, constants
[2025-05-14 01:51:26,617] [WARNING] Execution test issue in /home/emilio/Documents/ai/pizza/src/analysis/metrics.py: Execution failed with error: Traceback (most recent call last):
  File "/home/emilio/Documents/ai/pizza/src/analysis/metrics.py", line 16, in <module>
    from .types import (
ImportError: attempted relative import with no known parent package

[2025-05-14 01:51:26,619] [WARNING] Validation passed with warnings for /home/emilio/Documents/ai/pizza/src/analysis/metrics.py
[2025-05-14 01:51:26,619] [INFO] Validating script: models.py
[2025-05-14 01:51:26,848] [WARNING] Missing or incomplete docstring in /home/emilio/Documents/ai/pizza/src/chatlist_ki/models.py
[2025-05-14 01:51:26,849] [WARNING] Validation passed with warnings for /home/emilio/Documents/ai/pizza/src/chatlist_ki/models.py
[2025-05-14 01:51:26,849] [INFO] Validating script: __main__.py
[2025-05-14 01:51:26,849] [WARNING] Missing dependencies in /home/emilio/Documents/ai/pizza/src/chatlist_ki/__main__.py: chat_interface, database, models
[2025-05-14 01:51:26,859] [WARNING] Execution test issue in /home/emilio/Documents/ai/pizza/src/chatlist_ki/__main__.py: Execution failed with error: Traceback (most recent call last):
  File "/home/emilio/Documents/ai/pizza/src/chatlist_ki/__main__.py", line 1, in <module>
    from .chat_interface import ChatInterface
ImportError: attempted relative import with no known parent package

[2025-05-14 01:51:26,859] [WARNING] Missing or incomplete docstring in /home/emilio/Documents/ai/pizza/src/chatlist_ki/__main__.py
[2025-05-14 01:51:26,859] [WARNING] Validation passed with warnings for /home/emilio/Documents/ai/pizza/src/chatlist_ki/__main__.py
[2025-05-14 01:51:26,859] [INFO] Validating script: __init__.py
[2025-05-14 01:51:26,859] [WARNING] Missing dependencies in /home/emilio/Documents/ai/pizza/src/chatlist_ki/__init__.py: chat_interface, database, models
[2025-05-14 01:51:26,868] [WARNING] Execution test issue in /home/emilio/Documents/ai/pizza/src/chatlist_ki/__init__.py: Execution failed with error: Traceback (most recent call last):
  File "/home/emilio/Documents/ai/pizza/src/chatlist_ki/__init__.py", line 1, in <module>
    from .models import Task, TaskStatus
ImportError: attempted relative import with no known parent package

[2025-05-14 01:51:26,868] [WARNING] Missing or incomplete docstring in /home/emilio/Documents/ai/pizza/src/chatlist_ki/__init__.py
[2025-05-14 01:51:26,868] [WARNING] Validation passed with warnings for /home/emilio/Documents/ai/pizza/src/chatlist_ki/__init__.py
[2025-05-14 01:51:26,868] [INFO] Validating script: api.py
[2025-05-14 01:51:26,984] [WARNING] Missing dependencies in /home/emilio/Documents/ai/pizza/src/chatlist_ki/api.py: database, models
[2025-05-14 01:51:27,173] [WARNING] Execution test issue in /home/emilio/Documents/ai/pizza/src/chatlist_ki/api.py: Execution failed with error: Traceback (most recent call last):
  File "/home/emilio/Documents/ai/pizza/src/chatlist_ki/api.py", line 5, in <module>
    from .database import Database, TaskManager
ImportError: attempted relative import with no known parent package

[2025-05-14 01:51:27,173] [WARNING] Missing or incomplete docstring in /home/emilio/Documents/ai/pizza/src/chatlist_ki/api.py
[2025-05-14 01:51:27,173] [WARNING] Validation passed with warnings for /home/emilio/Documents/ai/pizza/src/chatlist_ki/api.py
[2025-05-14 01:51:27,173] [INFO] Validating script: database.py
[2025-05-14 01:51:27,176] [WARNING] Missing dependencies in /home/emilio/Documents/ai/pizza/src/chatlist_ki/database.py: models
[2025-05-14 01:51:27,342] [WARNING] Execution test issue in /home/emilio/Documents/ai/pizza/src/chatlist_ki/database.py: Execution failed with error: Traceback (most recent call last):
  File "/home/emilio/Documents/ai/pizza/src/chatlist_ki/database.py", line 4, in <module>
    from .models import Base, Task, TaskStatus
ImportError: attempted relative import with no known parent package

[2025-05-14 01:51:27,344] [WARNING] Missing or incomplete docstring in /home/emilio/Documents/ai/pizza/src/chatlist_ki/database.py
[2025-05-14 01:51:27,344] [WARNING] Validation passed with warnings for /home/emilio/Documents/ai/pizza/src/chatlist_ki/database.py
[2025-05-14 01:51:27,344] [INFO] Validating script: chat_interface.py
[2025-05-14 01:51:27,345] [WARNING] Missing dependencies in /home/emilio/Documents/ai/pizza/src/chatlist_ki/chat_interface.py: database, models
[2025-05-14 01:51:27,361] [WARNING] Execution test issue in /home/emilio/Documents/ai/pizza/src/chatlist_ki/chat_interface.py: Execution failed with error: Traceback (most recent call last):
  File "/home/emilio/Documents/ai/pizza/src/chatlist_ki/chat_interface.py", line 2, in <module>
    from .database import TaskManager, Database
ImportError: attempted relative import with no known parent package

[2025-05-14 01:51:27,362] [WARNING] Missing or incomplete docstring in /home/emilio/Documents/ai/pizza/src/chatlist_ki/chat_interface.py
[2025-05-14 01:51:27,362] [WARNING] Validation passed with warnings for /home/emilio/Documents/ai/pizza/src/chatlist_ki/chat_interface.py
[2025-05-14 01:51:27,362] [INFO] Validating script: status_display.py
[2025-05-14 01:51:27,369] [WARNING] Missing dependencies in /home/emilio/Documents/ai/pizza/src/visualization/status_display.py: ssd1306, machine
[2025-05-14 01:51:27,401] [WARNING] Execution test issue in /home/emilio/Documents/ai/pizza/src/visualization/status_display.py: Execution failed with error: Traceback (most recent call last):
  File "/home/emilio/Documents/ai/pizza/src/visualization/status_display.py", line 22, in <module>
    from src.types import InferenceResult
ModuleNotFoundError: No module named 'src'

[2025-05-14 01:51:27,403] [WARNING] Validation passed with warnings for /home/emilio/Documents/ai/pizza/src/visualization/status_display.py
[2025-05-14 01:51:27,403] [INFO] Validating script: visualization.py
[2025-05-14 01:51:27,412] [WARNING] Missing dependencies in /home/emilio/Documents/ai/pizza/src/visualization/visualization.py: constants
[2025-05-14 01:51:29,051] [WARNING] Execution test issue in /home/emilio/Documents/ai/pizza/src/visualization/visualization.py: Execution failed with error: Traceback (most recent call last):
  File "/home/emilio/Documents/ai/pizza/src/visualization/visualization.py", line 15, in <module>
    from .types import (
ImportError: attempted relative import with no known parent package

[2025-05-14 01:51:29,053] [WARNING] Validation passed with warnings for /home/emilio/Documents/ai/pizza/src/visualization/visualization.py
[2025-05-14 01:51:29,053] [INFO] Validating script: exceptions.py
[2025-05-14 01:51:29,065] [INFO] Validation passed for /home/emilio/Documents/ai/pizza/src/utils/exceptions.py
[2025-05-14 01:51:29,065] [INFO] Validating script: types.py
[2025-05-14 01:51:29,082] [WARNING] Execution test issue in /home/emilio/Documents/ai/pizza/src/utils/types.py: Execution failed with error: Traceback (most recent call last):
  File "/home/emilio/Documents/ai/pizza/src/utils/types.py", line 5, in <module>
    from typing import Dict, List, Tuple, Optional, Union, NamedTuple, Callable
  File "/usr/lib/python3.12/typing.py", line 27, in <module>
    import contextlib
  File "/usr/lib/python3.12/contextlib.py", line 7, in <module>
    from functools import wraps
  File "/usr/lib/python3.12/functools.py", line 22, in <module>
    from types import GenericAlias
  File "/home/emilio/Documents/ai/pizza/src/utils/types.py", line 5, in <module>
    from typing import Dict, List, Tuple, Optional, Union, NamedTuple, Callable
ImportError: cannot import name 'Dict' from partially initialized module 'typing' (most likely due to a circular import) (/usr/lib/python3.12/typing.py)

[2025-05-14 01:51:29,083] [WARNING] Validation passed with warnings for /home/emilio/Documents/ai/pizza/src/utils/types.py
[2025-05-14 01:51:29,083] [INFO] Validating script: power_manager.py
[2025-05-14 01:51:29,087] [WARNING] Missing dependencies in /home/emilio/Documents/ai/pizza/src/utils/power_manager.py: devices, metrics, constants
[2025-05-14 01:51:29,101] [WARNING] Execution test issue in /home/emilio/Documents/ai/pizza/src/utils/power_manager.py: Execution failed with error: Traceback (most recent call last):
  File "/home/emilio/Documents/ai/pizza/src/utils/power_manager.py", line 7, in <module>
    import logging
  File "/usr/lib/python3.12/logging/__init__.py", line 26, in <module>
    import sys, os, time, io, re, traceback, warnings, weakref, collections.abc
  File "/usr/lib/python3.12/re/__init__.py", line 124, in <module>
    import enum
  File "/usr/lib/python3.12/enum.py", line 3, in <module>
    from types import MappingProxyType, DynamicClassAttribute
  File "/home/emilio/Documents/ai/pizza/src/utils/types.py", line 5, in <module>
    from typing import Dict, List, Tuple, Optional, Union, NamedTuple, Callable
  File "/usr/lib/python3.12/typing.py", line 27, in <module>
    import contextlib
  File "/usr/lib/python3.12/contextlib.py", line 7, in <module>
    from functools import wraps
  File "/usr/lib/python3.12/functools.py", line 22, in <module>
    from types import GenericAlias
ImportError: cannot import name 'GenericAlias' from partially initialized module 'types' (most likely due to a circular import) (/home/emilio/Documents/ai/pizza/src/utils/types.py)

[2025-05-14 01:51:29,103] [WARNING] Validation passed with warnings for /home/emilio/Documents/ai/pizza/src/utils/power_manager.py
[2025-05-14 01:51:29,103] [INFO] Validating script: devices.py
[2025-05-14 01:51:29,104] [WARNING] Missing dependencies in /home/emilio/Documents/ai/pizza/src/utils/devices.py: exceptions, constants
[2025-05-14 01:51:29,118] [WARNING] Execution test issue in /home/emilio/Documents/ai/pizza/src/utils/devices.py: Execution failed with error: Traceback (most recent call last):
  File "/home/emilio/Documents/ai/pizza/src/utils/devices.py", line 6, in <module>
    import logging
  File "/usr/lib/python3.12/logging/__init__.py", line 26, in <module>
    import sys, os, time, io, re, traceback, warnings, weakref, collections.abc
  File "/usr/lib/python3.12/re/__init__.py", line 124, in <module>
    import enum
  File "/usr/lib/python3.12/enum.py", line 3, in <module>
    from types import MappingProxyType, DynamicClassAttribute
  File "/home/emilio/Documents/ai/pizza/src/utils/types.py", line 5, in <module>
    from typing import Dict, List, Tuple, Optional, Union, NamedTuple, Callable
  File "/usr/lib/python3.12/typing.py", line 27, in <module>
    import contextlib
  File "/usr/lib/python3.12/contextlib.py", line 7, in <module>
    from functools import wraps
  File "/usr/lib/python3.12/functools.py", line 22, in <module>
    from types import GenericAlias
ImportError: cannot import name 'GenericAlias' from partially initialized module 'types' (most likely due to a circular import) (/home/emilio/Documents/ai/pizza/src/utils/types.py)

[2025-05-14 01:51:29,119] [WARNING] Validation passed with warnings for /home/emilio/Documents/ai/pizza/src/utils/devices.py
[2025-05-14 01:51:29,119] [INFO] Validating script: validation.py
[2025-05-14 01:51:29,121] [WARNING] Missing dependencies in /home/emilio/Documents/ai/pizza/src/utils/validation.py: exceptions, constants
[2025-05-14 01:51:29,134] [WARNING] Execution test issue in /home/emilio/Documents/ai/pizza/src/utils/validation.py: Execution failed with error: Traceback (most recent call last):
  File "/home/emilio/Documents/ai/pizza/src/utils/validation.py", line 6, in <module>
    import json
  File "/usr/lib/python3.12/json/__init__.py", line 106, in <module>
    from .decoder import JSONDecoder, JSONDecodeError
  File "/usr/lib/python3.12/json/decoder.py", line 3, in <module>
    import re
  File "/usr/lib/python3.12/re/__init__.py", line 124, in <module>
    import enum
  File "/usr/lib/python3.12/enum.py", line 3, in <module>
    from types import MappingProxyType, DynamicClassAttribute
  File "/home/emilio/Documents/ai/pizza/src/utils/types.py", line 5, in <module>
    from typing import Dict, List, Tuple, Optional, Union, NamedTuple, Callable
  File "/usr/lib/python3.12/typing.py", line 27, in <module>
    import contextlib
  File "/usr/lib/python3.12/contextlib.py", line 7, in <module>
    from functools import wraps
  File "/usr/lib/python3.12/functools.py", line 22, in <module>
    from types import GenericAlias
ImportError: cannot import name 'GenericAlias' from partially initialized module 'types' (most likely due to a circular import) (/home/emilio/Documents/ai/pizza/src/utils/types.py)

[2025-05-14 01:51:29,135] [WARNING] Validation passed with warnings for /home/emilio/Documents/ai/pizza/src/utils/validation.py
[2025-05-14 01:51:29,135] [INFO] Validating script: memory.py
[2025-05-14 01:51:29,137] [WARNING] Missing dependencies in /home/emilio/Documents/ai/pizza/src/utils/memory.py: constants, exceptions
[2025-05-14 01:51:29,150] [WARNING] Execution test issue in /home/emilio/Documents/ai/pizza/src/utils/memory.py: Execution failed with error: Traceback (most recent call last):
  File "/home/emilio/Documents/ai/pizza/src/utils/memory.py", line 5, in <module>
    import torch
  File "/home/emilio/Documents/ai/pizza/.venv/lib/python3.12/site-packages/torch/__init__.py", line 14, in <module>
    import ctypes
  File "/usr/lib/python3.12/ctypes/__init__.py", line 4, in <module>
    import types as _types
  File "/home/emilio/Documents/ai/pizza/src/utils/types.py", line 5, in <module>
    from typing import Dict, List, Tuple, Optional, Union, NamedTuple, Callable
  File "/usr/lib/python3.12/typing.py", line 27, in <module>
    import contextlib
  File "/usr/lib/python3.12/contextlib.py", line 7, in <module>
    from functools import wraps
  File "/usr/lib/python3.12/functools.py", line 22, in <module>
    from types import GenericAlias
ImportError: cannot import name 'GenericAlias' from partially initialized module 'types' (most likely due to a circular import) (/home/emilio/Documents/ai/pizza/src/utils/types.py)

[2025-05-14 01:51:29,151] [WARNING] Validation passed with warnings for /home/emilio/Documents/ai/pizza/src/utils/memory.py
[2025-05-14 01:51:29,151] [INFO] Validating script: temporal_smoother.py
[2025-05-14 01:51:29,167] [WARNING] Execution test issue in /home/emilio/Documents/ai/pizza/src/utils/temporal_smoother.py: Execution failed with error: Traceback (most recent call last):
  File "/home/emilio/Documents/ai/pizza/src/utils/temporal_smoother.py", line 9, in <module>
    import numpy as np
  File "/home/emilio/Documents/ai/pizza/.venv/lib/python3.12/site-packages/numpy/__init__.py", line 92, in <module>
    from ._globals import _NoValue, _CopyMode
  File "/home/emilio/Documents/ai/pizza/.venv/lib/python3.12/site-packages/numpy/_globals.py", line 18, in <module>
    import enum
  File "/usr/lib/python3.12/enum.py", line 3, in <module>
    from types import MappingProxyType, DynamicClassAttribute
  File "/home/emilio/Documents/ai/pizza/src/utils/types.py", line 5, in <module>
    from typing import Dict, List, Tuple, Optional, Union, NamedTuple, Callable
  File "/usr/lib/python3.12/typing.py", line 27, in <module>
    import contextlib
  File "/usr/lib/python3.12/contextlib.py", line 7, in <module>
    from functools import wraps
  File "/usr/lib/python3.12/functools.py", line 22, in <module>
    from types import GenericAlias
ImportError: cannot import name 'GenericAlias' from partially initialized module 'types' (most likely due to a circular import) (/home/emilio/Documents/ai/pizza/src/utils/types.py)

[2025-05-14 01:51:29,169] [WARNING] Validation passed with warnings for /home/emilio/Documents/ai/pizza/src/utils/temporal_smoother.py
[2025-05-14 01:51:29,169] [INFO] Validating script: utils.py
[2025-05-14 01:51:29,182] [WARNING] Execution test issue in /home/emilio/Documents/ai/pizza/src/utils/utils.py: Execution failed with error: Traceback (most recent call last):
  File "/home/emilio/Documents/ai/pizza/src/utils/utils.py", line 6, in <module>
    import logging
  File "/usr/lib/python3.12/logging/__init__.py", line 26, in <module>
    import sys, os, time, io, re, traceback, warnings, weakref, collections.abc
  File "/usr/lib/python3.12/re/__init__.py", line 124, in <module>
    import enum
  File "/usr/lib/python3.12/enum.py", line 3, in <module>
    from types import MappingProxyType, DynamicClassAttribute
  File "/home/emilio/Documents/ai/pizza/src/utils/types.py", line 5, in <module>
    from typing import Dict, List, Tuple, Optional, Union, NamedTuple, Callable
  File "/usr/lib/python3.12/typing.py", line 27, in <module>
    import contextlib
  File "/usr/lib/python3.12/contextlib.py", line 7, in <module>
    from functools import wraps
  File "/usr/lib/python3.12/functools.py", line 22, in <module>
    from types import GenericAlias
ImportError: cannot import name 'GenericAlias' from partially initialized module 'types' (most likely due to a circular import) (/home/emilio/Documents/ai/pizza/src/utils/types.py)

[2025-05-14 01:51:29,183] [WARNING] Validation passed with warnings for /home/emilio/Documents/ai/pizza/src/utils/utils.py
[2025-05-14 01:51:29,183] [INFO] Validating script: constants.py
[2025-05-14 01:51:29,197] [WARNING] Execution test issue in /home/emilio/Documents/ai/pizza/src/utils/constants.py: Execution failed with error: Traceback (most recent call last):
  File "/home/emilio/Documents/ai/pizza/src/utils/constants.py", line 5, in <module>
    from pathlib import Path
  File "/usr/lib/python3.12/pathlib.py", line 8, in <module>
    import fnmatch
  File "/usr/lib/python3.12/fnmatch.py", line 14, in <module>
    import re
  File "/usr/lib/python3.12/re/__init__.py", line 124, in <module>
    import enum
  File "/usr/lib/python3.12/enum.py", line 3, in <module>
    from types import MappingProxyType, DynamicClassAttribute
  File "/home/emilio/Documents/ai/pizza/src/utils/types.py", line 5, in <module>
    from typing import Dict, List, Tuple, Optional, Union, NamedTuple, Callable
  File "/usr/lib/python3.12/typing.py", line 27, in <module>
    import contextlib
  File "/usr/lib/python3.12/contextlib.py", line 7, in <module>
    from functools import wraps
  File "/usr/lib/python3.12/functools.py", line 22, in <module>
    from types import GenericAlias
ImportError: cannot import name 'GenericAlias' from partially initialized module 'types' (most likely due to a circular import) (/home/emilio/Documents/ai/pizza/src/utils/types.py)

[2025-05-14 01:51:29,197] [WARNING] Validation passed with warnings for /home/emilio/Documents/ai/pizza/src/utils/constants.py
[2025-05-14 01:51:29,197] [INFO] Validating script: enhanced_pizza_augmentation.py
[2025-05-14 01:51:31,192] [WARNING] Execution test issue in /home/emilio/Documents/ai/pizza/src/augmentation/enhanced_pizza_augmentation.py: Execution failed with error: 
[2025-05-14 01:51:31,201] [WARNING] Missing or incomplete docstring in /home/emilio/Documents/ai/pizza/src/augmentation/enhanced_pizza_augmentation.py
[2025-05-14 01:51:31,201] [WARNING] Validation passed with warnings for /home/emilio/Documents/ai/pizza/src/augmentation/enhanced_pizza_augmentation.py
[2025-05-14 01:51:31,201] [INFO] Validating script: augmentation_optimized.py
[2025-05-14 01:51:33,358] [WARNING] Execution test issue in /home/emilio/Documents/ai/pizza/src/augmentation/augmentation_optimized.py: Execution failed with error: Traceback (most recent call last):
  File "/home/emilio/Documents/ai/pizza/src/augmentation/augmentation_optimized.py", line 698, in <module>
    main()
  File "/home/emilio/Documents/ai/pizza/src/augmentation/augmentation_optimized.py", line 688, in main
    augment_pizza_dataset(input_dir, output_dir, img_per_original=img_per_original, batch_size=batch_size)
  File "/home/emilio/Documents/ai/pizza/src/augmentation/augmentation_optimized.py", line 512, in augment_pizza_dataset
    image_files = [os.path.join(input_dir, f) for f in os.listdir(input_dir) 
                                                       ^^^^^^^^^^^^^^^^^^^^^
FileNotFoundError: [Errno 2] No such file or directory: '/home/emilio/Documents/ai/pizza/img-pizza/'

[2025-05-14 01:51:33,361] [WARNING] Missing or incomplete docstring in /home/emilio/Documents/ai/pizza/src/augmentation/augmentation_optimized.py
[2025-05-14 01:51:33,361] [WARNING] Validation passed with warnings for /home/emilio/Documents/ai/pizza/src/augmentation/augmentation_optimized.py
[2025-05-14 01:51:33,361] [INFO] Validating script: diffusion_pizza_generator.py
[2025-05-14 01:51:37,646] [INFO] Validation passed for /home/emilio/Documents/ai/pizza/src/augmentation/diffusion_pizza_generator.py
[2025-05-14 01:51:37,646] [INFO] Validating script: augmentation.py
[2025-05-14 01:51:39,717] [WARNING] Execution test issue in /home/emilio/Documents/ai/pizza/src/augmentation/augmentation.py: Execution failed with error: 
[2025-05-14 01:51:39,726] [WARNING] Missing or incomplete docstring in /home/emilio/Documents/ai/pizza/src/augmentation/augmentation.py
[2025-05-14 01:51:39,726] [WARNING] Validation passed with warnings for /home/emilio/Documents/ai/pizza/src/augmentation/augmentation.py
[2025-05-14 01:51:39,726] [INFO] Validating script: advanced_pizza_diffusion_control.py
[2025-05-14 01:51:41,391] [WARNING] Execution test issue in /home/emilio/Documents/ai/pizza/src/augmentation/advanced_pizza_diffusion_control.py: Execution failed with error: Traceback (most recent call last):
  File "/home/emilio/Documents/ai/pizza/src/augmentation/advanced_pizza_diffusion_control.py", line 36, in <module>
    from src.augmentation.diffusion_pizza_generator import PizzaDiffusionGenerator, PIZZA_STAGES
ModuleNotFoundError: No module named 'src'

[2025-05-14 01:51:41,395] [WARNING] Validation passed with warnings for /home/emilio/Documents/ai/pizza/src/augmentation/advanced_pizza_diffusion_control.py
[2025-05-14 01:51:41,395] [INFO] Validating script: optimized-pizza-augmentation.py
[2025-05-14 01:51:43,522] [WARNING] Execution test issue in /home/emilio/Documents/ai/pizza/src/augmentation/optimized-pizza-augmentation.py: Execution failed with error: Traceback (most recent call last):
  File "/home/emilio/Documents/ai/pizza/src/augmentation/optimized-pizza-augmentation.py", line 698, in <module>
    main()
  File "/home/emilio/Documents/ai/pizza/src/augmentation/optimized-pizza-augmentation.py", line 688, in main
    augment_pizza_dataset(input_dir, output_dir, img_per_original=img_per_original, batch_size=batch_size)
  File "/home/emilio/Documents/ai/pizza/src/augmentation/optimized-pizza-augmentation.py", line 512, in augment_pizza_dataset
    image_files = [os.path.join(input_dir, f) for f in os.listdir(input_dir) 
                                                       ^^^^^^^^^^^^^^^^^^^^^
FileNotFoundError: [Errno 2] No such file or directory: '/home/emilio/Documents/ai/pizza/img-pizza/'

[2025-05-14 01:51:43,525] [WARNING] Missing or incomplete docstring in /home/emilio/Documents/ai/pizza/src/augmentation/optimized-pizza-augmentation.py
[2025-05-14 01:51:43,525] [WARNING] Validation passed with warnings for /home/emilio/Documents/ai/pizza/src/augmentation/optimized-pizza-augmentation.py
[2025-05-14 01:51:43,525] [INFO] Validating script: augment_legacy.py
[2025-05-14 01:51:45,389] [WARNING] Execution test issue in /home/emilio/Documents/ai/pizza/src/legacy/augment_legacy.py: Execution failed with error: Traceback (most recent call last):
  File "/home/emilio/Documents/ai/pizza/src/legacy/augment_legacy.py", line 176, in <module>
    augment_pizza(input_dir, output_dir, num_images, batch_size) 
    ^^^^^^^^^^^^^^^^^^^^^^^^^^^^^^^^^^^^^^^^^^^^^^^^^^^^^^^^^^^^
  File "/home/emilio/Documents/ai/pizza/src/legacy/augment_legacy.py", line 131, in augment_pizza
    image_files = [os.path.join(input_dir, f) for f in os.listdir(input_dir) 
                                                       ^^^^^^^^^^^^^^^^^^^^^
FileNotFoundError: [Errno 2] No such file or directory: 'img-pizza'

[2025-05-14 01:51:45,391] [WARNING] Missing or incomplete docstring in /home/emilio/Documents/ai/pizza/src/legacy/augment_legacy.py
[2025-05-14 01:51:45,391] [WARNING] Validation passed with warnings for /home/emilio/Documents/ai/pizza/src/legacy/augment_legacy.py
[2025-05-14 01:51:45,391] [INFO] Validating script: diffusion_data_agent.py
[2025-05-14 01:51:45,400] [WARNING] Missing dependencies in /home/emilio/Documents/ai/pizza/src/integration/diffusion_data_agent.py: cleanfid
[2025-05-14 01:51:47,044] [WARNING] Validation passed with warnings for /home/emilio/Documents/ai/pizza/src/integration/diffusion_data_agent.py
[2025-05-14 01:51:47,044] [INFO] Validating script: pizza_diffusion_integration.py
[2025-05-14 01:51:47,050] [WARNING] Missing dependencies in /home/emilio/Documents/ai/pizza/src/integration/pizza_diffusion_integration.py: enhanced_pizza_augmentation, diffusion_data_agent, optimized_pizza_augmentation
[2025-05-14 01:51:48,682] [WARNING] Execution test issue in /home/emilio/Documents/ai/pizza/src/integration/pizza_diffusion_integration.py: Execution failed with error: Traceback (most recent call last):
  File "/home/emilio/Documents/ai/pizza/src/integration/pizza_diffusion_integration.py", line 29, in <module>
    from enhanced_pizza_augmentation import (
ModuleNotFoundError: No module named 'enhanced_pizza_augmentation'

During handling of the above exception, another exception occurred:

Traceback (most recent call last):
  File "/home/emilio/Documents/ai/pizza/src/integration/pizza_diffusion_integration.py", line 40, in <module>
    from optimized_pizza_augmentation import (
ModuleNotFoundError: No module named 'optimized_pizza_augmentation'

During handling of the above exception, another exception occurred:

Traceback (most recent call last):
  File "/home/emilio/Documents/ai/pizza/src/integration/pizza_diffusion_integration.py", line 49, in <module>
    from test import (
ImportError: cannot import name 'PizzaBurningEffect' from 'test' (/usr/lib/python3.12/test/__init__.py)

[2025-05-14 01:51:48,684] [WARNING] Validation passed with warnings for /home/emilio/Documents/ai/pizza/src/integration/pizza_diffusion_integration.py
[2025-05-14 01:51:48,684] [INFO] Validating script: diffusion_training_integration.py
[2025-05-14 01:51:53,043] [INFO] Validation passed for /home/emilio/Documents/ai/pizza/src/integration/diffusion_training_integration.py
[2025-05-14 01:51:53,044] [INFO] Validation complete. Summary: 28 passed, 47 with warnings, 0 failed
[2025-05-14 01:51:53,044] [INFO] Report written to /home/emilio/Documents/ai/pizza/output/pipeline_runs/20250514_015022/reports/validation_report.json
